File: data/Rock_mag_data/MPMS3/DA2-R-FC-ZFC-RT-SIRM-AC_sweep.dat
[Header]
; MPMS3 Data File (default extension .dat)
; Copyright (c) 2007, Quantum Design, Inc. All rights reserved.
TITLE,
FILEOPENTIME,3863236258.03999,06/01/2022,10:09 am
BYAPP,MPMS3 w/ AC,1.0,1.1
INFO,MPMS3 Measurement Release 1.1.16 Build 424, MultiVu Release 2.3.4.19,APPNAME
INFO,Linear Motor Servo Controller,MOTOR_MODULE_NAME
INFO,3101-100 N2,MOTOR_HW_VERSION
INFO,,MOTOR_SERIAL_NUMBER
INFO,01.04.28,MOTOR_SOFTWARE_VERSION
INFO,Quantum Design Squid Module,SQUID_MODULE_NAME
INFO,3101-501 B0,SQUID_HW_VERSION
INFO,SQM327,SQUID_SERIAL_NUMBER
INFO,01.03.04,SQUID_SOFTWARE_VERSION
INFO,Quantum Design VSM Oven,OVEN_MODULE_NAME
INFO,3101-201 A3,OVEN_HW_VERSION
INFO,OVB365,OVEN_SERIAL_NUMBER
INFO,01.07.07,OVEN_SOFTWARE_VERSION
INFO,SQUID AC,AC_MODULE_NAME
INFO,3101-401 G0,AC_HW_VERSION
INFO,SAC220,AC_SERIAL_NUMBER
INFO,SQUID AC 00.95.07,AC_SOFTWARE_VERSION
INFO,TCI344,COIL_SERIAL_NUMBER
INFO,0,MOMENT_UNITS
INFO,DA2-R,SAMPLE_MATERIAL
INFO,DA2-R,SAMPLE_COMMENT
INFO,,SAMPLE_MASS
INFO,,SAMPLE_VOLUME
INFO,,SAMPLE_MOLECULAR_WEIGHT
INFO,,SAMPLE_SIZE
INFO,,SAMPLE_SHAPE
INFO,Straw,SAMPLE_HOLDER
INFO,Standard,SAMPLE_HOLDER_DETAIL
INFO,63.74,SAMPLE_OFFSET
DATATYPE,COMMENT,1
DATATYPE,TIME,2
STARTUPAXIS,X,2
STARTUPAXIS,Y1,5
FIELDGROUP, VSM,2,3,4,5,6,8,9,10,11,14,15
FIELDGROUP, DC, 2,3,4,14,56,57,58,59,60,61,62,63,64,65,66,67,68,69
FIELDGROUP, AC, 2,3,4,11,16,17,18,19,20,21,22,23,24,25,26,27,28,29,30
STARTUPGROUP, All
[Data]
Comment,Time Stamp (sec),Temperature (K),Magnetic Field (Oe),Moment (emu),M. Std. Err. (emu),Transport Action,Averaging Time (sec),Frequency (Hz),Peak Amplitude (mm),Center Position (mm),Lockin Signal' (V),Lockin Signal (V),Range,M. Quad. Signal (emu),AC Moment (emu),AC M. Std Err. (emu),AC Phase (deg),AC Phase Std. Err. (deg),AC Susceptibility (emu/Oe),AC Suscept. Std Err. (emu/Oe),AC X' (emu/Oe),AC X' Std Err. (emu/Oe),AC X'' (emu/Oe),AC X'' Std Err. (emu/Oe),AC Drive (Oe),AC Frequency (Hz),AC Averaging Time (sec),AC Cycles,AC Range,AC Measure Type,AC Signal' (V),AC Signal'' (V),AC Trim Coil Ratio,AC Trim Coil Phase,Min. Temperature (K),Max. Temperature (K),Min. Field (Oe),Max. Field (Oe),Mass (grams),Motor Lag (deg),Pressure (Torr),Measure Count,Measurement Number,SQUID Status (code),Motor Status (code),Measure Status (code),Motor Current (amps),Motor Temp. (C),Temp. Status (code),Field Status (code),Chamber Status (code),Chamber Temp (K),Redirection State,Average Temp (K),Rotation Angle (deg),Rotator state,DC Moment Fixed Ctr (emu),DC Moment Err Fixed Ctr (emu),DC Moment Free Ctr (emu),DC Moment Err Free Ctr (emu),DC Fixed Fit,DC Free Fit,DC Calculated Center (mm),DC Calculated Center Err (mm),DC Scan Length (mm),DC Scan Time (s),DC Number of Points,DC Squid Drift,DC Min V (V),DC Max V (V),DC Scans per Measure,Map 01,Map 02,Map 03,Map 04,Map 05,Map 06,Map 07,Map 08,Map 09,Map 10,Map 11,Map 12,Map 13,Map 14,Map 15,Map 16
,3863237752.30276,10.0001192092896,25.2842388153076,0.000613166172716881,1.67035181926542E-7,1,5,12.9061126708984,4.97610709474866,36.8800014257431,0.795185244633051,0.117290929044287,1,3.54357984457714E-7,,,,,,,,,,,,,,,,,,,,,10.0001192092896,10.0001192092896,25.2842388153076,25.2842388153076,49.9527062212649,5.36624061874165,5.08714866638184,65,1,0,0,1,0.287017822265625,29.3255138397217,1,1,1,10.0001192092896,0,10.0001192092896,,,,,,,,,,,,,,,,,,,,,,,,,,,,,,,,,
,3863237846.76004,24.0073299407959,25.2842388153076,0.00061817898864891,1.64142337350805E-7,1,5,12.9061126708984,4.9760971061277,36.8900001049042,0.801708303509318,0.118083075451356,1,2.28948643210044E-7,,,,,,,,,,,,,,,,,,,,,24.0073299407959,24.0073299407959,25.2842388153076,25.2842388153076,50.015627317063,5.36536840259362,5.92922067642212,65,1,0,0,1,0.2667236328125,30.3030319213867,2,1,1,24.0073299407959,0,24.0073299407959,,,,,,,,,,,,,,,,,,,,,,,,,,,,,,,,,
,3863237944.17335,39.1224670410156,25.2842388153076,0.000580617456643682,1.28238493827499E-7,1,5,12.9061126708984,4.97606165130801,36.8900001049042,0.753043121670223,0.1105297440689,1,-7.58812175668119E-8,,,,,,,,,,,,,,,,,,,,,39.1224670410156,39.1224670410156,25.2842388153076,25.2842388153076,50.0304782589284,5.36554288507922,6.33102369308472,65,1,0,0,1,0.276412963867187,30.3030319213867,2,1,1,39.1224670410156,0,39.1224670410156,,,,,,,,,,,,,,,,,,,,,,,,,,,,,,,,,
,3863238039.3479,54.0953483581543,25.2842388153076,0.000559786937278221,1.04234718752328E-7,1,5,12.9061126708984,4.97606841383532,36.9100011885166,0.726009315648697,0.106691451398642,1,2.47043297491846E-8,,,,,,,,,,,,,,,,,,,,,54.0953483581543,54.0953483581543,25.2842388153076,25.2842388153076,50.015627317063,5.365608640224,6.54560327529907,64,1,64,0,0,0.267105102539062,30.7917900085449,2,1,1,54.0953483581543,0,54.0953483581543,,,,,,,,,,,,,,,,,,,,,,,,,,,,,,,,,
,3863238134.50514,69.1397323608398,25.2842388153076,0.000538992111486196,1.23831143631227E-7,1,5,12.9061126708984,4.97598865180558,36.9299985468388,0.699058351119196,0.10249153000675,1,-1.56839312829094E-7,,,,,,,,,,,,,,,,,,,,,69.1397323608398,69.1397323608398,25.2842388153076,25.2842388153076,50.0504097861688,5.36545949195673,6.72277688980103,64,1,64,0,0,0.267257690429687,30.3030319213867,2,1,1,69.1397323608398,0,69.1397323608398,,,,,,,,,,,,,,,,,,,,,,,,,,,,,,,,,
,3863238227.04143,84.0730285644531,25.2842388153076,0.000506183160037084,1.42175326947473E-7,1,5,12.9061126708984,4.97589124825738,36.9499996304512,0.65647451662614,0.0963414701942725,1,-7.68571796870738E-8,,,,,,,,,,,,,,,,,,,,,84.0730285644531,84.0730285644531,25.2842388153076,25.2842388153076,50.0539271145053,5.36637688276402,6.82733535766602,65,1,0,0,1,0.277938842773438,31.2805480957031,2,1,1,84.0730285644531,0,84.0730285644531,,,,,,,,,,,,,,,,,,,,,,,,,,,,,,,,,
,3863238318.45111,99.0275497436523,25.2842388153076,0.000423712141186007,2.73518645523588E-7,1,5,12.9061126708984,4.9865898773042,36.9799993932247,0.551198870944859,0.0807499991178018,1,-1.7093490916611E-7,,,,,,,,,,,,,,,,,,,,,99.0275497436523,99.0275497436523,25.2842388153076,25.2842388153076,50.0402486154188,5.36621940503932,6.91669845581055,65,1,0,0,1,0.276718139648438,30.7917900085449,2,1,1,99.0275497436523,0,99.0275497436523,,,,,,,,,,,,,,,,,,,,,,,,,,,,,,,,,
,3863238409.68435,114.058753967285,25.2842388153076,0.000258107118276365,2.45130796422551E-7,1,5,12.9061126708984,4.98663636169413,37.0099991559982,0.335787293214091,0.0490785871155782,1,-1.89814558504614E-7,,,,,,,,,,,,,,,,,,,,,114.058753967285,114.058753967285,25.2842388153076,25.2842388153076,50.0277425591111,5.36645710662733,6.96145439147949,65,1,0,0,1,0.26763916015625,31.2805480957031,2,1,1,114.058753967285,0,114.058753967285,,,,,,,,,,,,,,,,,,,,,,,,,,,,,,,,,
,3863238500.46014,129.03401184082,25.2842388153076,0.000189599742476361,5.02098421728297E-8,1,5,12.9061126708984,4.98649922769255,37.0600000023842,0.246685795613576,0.0358229454636329,1,-3.14483441591798E-7,,,,,,,,,,,,,,,,,,,,,129.03401184082,129.03401184082,25.2842388153076,25.2842388153076,50.0988707543611,5.36673066170869,7.01469278335571,64,1,64,0,0,0.275039672851562,31.7693061828613,2,1,1,129.03401184082,0,129.03401184082,,,,,,,,,,,,,,,,,,,,,,,,,,,,,,,,,
,3863238590.97861,144.015350341797,25.2842388153076,0.000178666868182412,3.51216120471391E-8,1,5,12.9061126708984,4.98647759877202,37.0999984443188,0.232473351656538,0.0336645476864775,1,-3.67489703527815E-7,,,,,,,,,,,,,,,,,,,,,144.015350341797,144.015350341797,25.2842388153076,25.2842388153076,50.0644790995149,5.36713131419213,7.05565309524536,63,1,64,0,0,0.267181396484375,31.2805480957031,2,1,1,144.015350341797,0,144.015350341797,,,,,,,,,,,,,,,,,,,,,,,,,,,,,,,,,
,3863238682.02778,159.091339111328,25.2842388153076,0.000174191106992202,2.54903080962113E-8,1,5,12.9061126708984,4.98650888296205,37.1499992907047,0.226648866859071,0.0328407126379858,1,-3.43521682538731E-7,,,,,,,,,,,,,,,,,,,,,159.091339111328,159.091339111328,25.2842388153076,25.2842388153076,50.0527546717264,5.36720863628514,7.08196449279785,64,1,64,0,0,0.267486572265625,31.2805480957031,2,1,1,159.091339111328,0,159.091339111328,,,,,,,,,,,,,,,,,,,,,,,,,,,,,,,,,
,3863238772.15955,174.039199829102,25.2842388153076,0.000171883432277819,2.8118642318817E-8,1,5,12.9061126708984,4.98645203552133,37.2000001370907,0.223668147622573,0.0322315912458489,1,-4.72378499768318E-7,,,,,,,,,,,,,,,,,,,,,174.039199829102,174.039199829102,25.2842388153076,25.2842388153076,50.0046845177938,5.36751936452251,7.12381458282471,65,1,0,0,1,0.267715454101562,31.7693061828613,2,1,1,174.039199829102,0,174.039199829102,,,,,,,,,,,,,,,,,,,,,,,,,,,,,,,,,
,3863238862.5029,189.048568725586,25.2842388153076,0.000170527710717452,1.61330051676695E-8,1,5,12.9061126708984,4.98642121713332,37.2599996626377,0.221872079302339,0.0321811007196767,1,-3.11809812460314E-7,,,,,,,,,,,,,,,,,,,,,189.048568725586,189.048568725586,25.2842388153076,25.2842388153076,50.0855830695341,5.36708899445049,7.16383361816406,64,1,64,0,0,0.268325805664062,31.7693061828613,2,1,1,189.048568725586,0,189.048568725586,,,,,,,,,,,,,,,,,,,,,,,,,,,,,,,,,
,3863238953.45287,204.078887939453,25.2842388153076,0.000169426747559461,1.34282279127997E-8,1,5,12.9061126708984,4.98630271348974,37.3199991881847,0.220409121238999,0.0321298293184839,1,-1.88658919484576E-7,,,,,,,,,,,,,,,,,,,,,204.078887939453,204.078887939453,25.2842388153076,25.2842388153076,50.1168482103034,5.36770809100283,7.21025896072388,63,1,64,0,0,0.268325805664062,31.2805480957031,2,1,1,204.078887939453,0,204.078887939453,,,,,,,,,,,,,,,,,,,,,,,,,,,,,,,,,
,3863239043.33725,219.02897644043,25.2842388153076,0.000168333882804653,1.50494062883815E-8,1,5,12.9061126708984,4.98601937466423,37.3900011181831,0.218970000418214,0.0319195274666384,1,-1.8783045388971E-7,,,,,,,,,,,,,,,,,,,,,219.02897644043,219.02897644043,25.2842388153076,25.2842388153076,50.0117191744668,5.36861012552986,7.27624940872192,63,1,64,0,0,0.268020629882813,31.7693061828613,2,1,1,219.02897644043,0,219.02897644043,,,,,,,,,,,,,,,,,,,,,,,,,,,,,,,,,
,3863239134.14592,234.031158447266,25.2842388153076,0.000167023985457629,2.93098773330666E-8,1,5,12.9061126708984,4.98577745058238,37.4599993228912,0.217251606760191,0.0316666984201343,1,-1.8812791902124E-7,,,,,,,,,,,,,,,,,,,,,234.031158447266,234.031158447266,25.2842388153076,25.2842388153076,50.0066385890918,5.36930550988438,7.34746980667114,63,1,64,0,0,0.2691650390625,31.7693061828613,2,1,1,234.031158447266,0,234.031158447266,,,,,,,,,,,,,,,,,,,,,,,,,,,,,,,,,
,3863239224.06457,249.050155639648,25.2842388153076,0.000165520261649297,1.23663091369682E-8,1,5,12.9061126708984,4.98553526936633,37.5300012528896,0.215280056316305,0.0313858410409354,1,-1.81527972601216E-7,,,,,,,,,,,,,,,,,,,,,249.050155639648,249.050155639648,25.2842388153076,25.2842388153076,50.0793300413803,5.37037930753488,7.47101354598999,64,1,64,0,0,0.269241333007813,28.8367557525635,2,1,1,249.050155639648,0,249.050155639648,,,,,,,,,,,,,,,,,,,,,,,,,,,,,,,,,
,3863239314.98954,264.084991455078,25.2842388153076,0.000163861816759299,1.27519626138608E-8,1,5,12.9061126708984,4.98517291895516,37.6200005412102,0.213099130578658,0.0310828419644718,1,-1.6844542233158E-7,,,,,,,,,,,,,,,,,,,,,264.084991455078,264.084991455078,25.2842388153076,25.2842388153076,50.0730770132265,5.3715170177861,7.68344879150391,64,1,64,0,0,0.273056030273438,31.7693061828613,2,1,1,264.084991455078,0,264.084991455078,,,,,,,,,,,,,,,,,,,,,,,,,,,,,,,,,
,3863239405.22634,279.170745849609,25.2842388153076,0.000162223920148306,1.0648071371677E-8,1,5,12.9061126708984,4.98533188867093,37.7099998295307,0.210976448851665,0.0307876759266442,1,-1.5588212698544E-7,,,,,,,,,,,,,,,,,,,,,279.170745849609,279.170745849609,25.2842388153076,25.2842388153076,50.0887095836111,5.37162939467722,7.55935430526733,64,1,64,0,0,0.271453857421875,30.7917900085449,2,1,1,279.170745849609,0,279.170745849609,,,,,,,,,,,,,,,,,,,,,,,,,,,,,,,,,
,3863239495.58767,294.029296875,25.2842388153076,0.000160508278832361,7.94796245117277E-9,1,5,12.9061126708984,4.98507242938697,37.7900004386902,0.208731815370379,0.0304471670468392,1,-1.63984732313433E-7,,,,,,,,,,,,,,,,,,,,,294.029296875,294.029296875,25.2842388153076,25.2842388153076,50.1231012384572,5.3729326363666,7.52665948867798,63,1,64,0,0,0.27069091796875,31.7693061828613,2,1,1,294.029296875,0,294.029296875,,,,,,,,,,,,,,,,,,,,,,,,,,,,,,,,,
,3863241042.76873,17.0040893554687,25.4221286773682,0.00058814432683189,1.58086400972415E-7,1,5,12.9061126708984,4.98667473698058,36.8800014257431,0.765062477822489,0.112507039500194,1,8.3513992863028E-8,,,,,,,,,,,,,,,,,,,,,17.0040893554687,17.0040893554687,25.4221286773682,25.4221286773682,49.9812356622168,5.36529275876348,5.58741092681885,65,1,0,0,1,0.27740478515625,30.7917900085449,2,1,1,17.0040893554687,0,17.0040893554687,,,,,,,,,,,,,,,,,,,,,,,,,,,,,,,,,
,3863241139.55645,32.0325164794922,25.4221286773682,0.000557754204295729,1.13770924876004E-7,1,5,12.9061126708984,4.98659187108446,36.8900001049042,0.725566984367699,0.10632951317399,1,-1.98831610315798E-7,,,,,,,,,,,,,,,,,,,,,32.0325164794922,32.0325164794922,25.4221286773682,25.4221286773682,50.0289150018899,5.36605319616042,6.15590715408325,65,1,0,0,1,0.267562866210938,30.7917900085449,2,1,1,32.0325164794922,0,32.0325164794922,,,,,,,,,,,,,,,,,,,,,,,,,,,,,,,,,
,3863241235.21633,47.0186462402344,25.4221286773682,0.000540332064233916,1.32306014731819E-7,1,5,12.9061126708984,4.98650838243161,36.8999987840652,0.70290526739275,0.102877870268482,1,-2.90937486645998E-7,,,,,,,,,,,,,,,,,,,,,47.0186462402344,47.0186462402344,25.4221286773682,25.4221286773682,50.0300874446688,5.36615155768973,6.43097543716431,65,1,0,0,1,0.275955200195313,31.2805480957031,2,1,1,47.0186462402344,0,47.0186462402344,,,,,,,,,,,,,,,,,,,,,,,,,,,,,,,,,
,3863241330.70299,62.0073547363281,25.4221286773682,0.000523140845793142,1.12497227364102E-7,1,5,12.9061126708984,4.98652926687223,36.9199998676777,0.680547820981955,0.099590298449994,1,-2.93206965260254E-7,,,,,,,,,,,,,,,,,,,,,62.0073547363281,62.0073547363281,25.4221286773682,25.4221286773682,50.0570536285822,5.36677287220623,6.65479326248169,64,1,64,0,0,0.267562866210938,30.7917900085449,2,1,1,62.0073547363281,0,62.0073547363281,,,,,,,,,,,,,,,,,,,,,,,,,,,,,,,,,
,3863241424.6455,77.038215637207,25.4221286773682,0.000502231606461689,1.08979871380635E-7,1,5,12.9061126708984,4.98649978327464,36.9400009512901,0.653361015731408,0.0954782888760047,1,-3.81985862718339E-7,,,,,,,,,,,,,,,,,,,,,77.038215637207,77.038215637207,25.4221286773682,25.4221286773682,50.0547087430245,5.36674003631782,6.77852439880371,65,1,0,0,1,0.266952514648438,30.7917900085449,2,1,1,77.038215637207,0,77.038215637207,,,,,,,,,,,,,,,,,,,,,,,,,,,,,,,,,
,3863241517.23814,92.0595932006836,25.4221286773682,0.000450693029940912,1.85117388957481E-7,1,5,12.9061126708984,4.986374134916,36.9700007140636,0.586270715395987,0.0858285156915614,1,-2.26575644265243E-7,,,,,,,,,,,,,,,,,,,,,92.0595932006836,92.0595932006836,25.4221286773682,25.4221286773682,50.0437659437553,5.36595800696892,6.86475706100464,64,1,64,0,0,0.277252197265625,30.7917900085449,2,1,1,92.0595932006836,0,92.0595932006836,,,,,,,,,,,,,,,,,,,,,,,,,,,,,,,,,
,3863241607.55708,107.006637573242,25.4221286773682,0.000298458639331139,3.14726448341289E-7,1,5,12.9061126708984,4.98634751835232,37.0000004768372,0.388261160648146,0.0566807422216566,1,-2.70227121022167E-7,,,,,,,,,,,,,,,,,,,,,107.006637573242,107.006637573242,25.4221286773682,25.4221286773682,50.0679964278515,5.36633446927486,6.92706060409546,64,1,64,0,0,0.266952514648438,30.7917900085449,2,1,1,107.006637573242,0,107.006637573242,,,,,,,,,,,,,,,,,,,,,,,,,,,,,,,,,
,3863241698.73572,122.029190063477,25.4221286773682,0.000193287817818549,8.63795857402168E-8,1,5,12.9061126708984,4.98636197511024,37.0399989187717,0.251460157767586,0.0366165457843779,1,-2.45113669156488E-7,,,,,,,,,,,,,,,,,,,,,122.029190063477,122.029190063477,25.4221286773682,25.4221286773682,50.0840198124957,5.36769260709404,6.98480892181396,65,1,0,0,1,0.276641845703125,31.7693061828613,2,1,1,122.029190063477,0,122.029190063477,,,,,,,,,,,,,,,,,,,,,,,,,,,,,,,,,
,3863241790.16458,137.192947387695,25.4221286773682,0.00017687117273051,2.86122851125412E-8,1,5,12.9061126708984,4.9863643074808,37.0800010859966,0.23010437493261,0.0334963671457301,1,-2.32154579604625E-7,,,,,,,,,,,,,,,,,,,,,137.192947387695,137.192947387695,25.4221286773682,25.4221286773682,50.0285241876303,5.36745069870579,7.01893758773804,65,1,0,0,1,0.277252197265625,31.2805480957031,2,1,1,137.192947387695,0,137.192947387695,,,,,,,,,,,,,,,,,,,,,,,,,,,,,,,,,
,3863241880.11316,152.123001098633,25.4221286773682,0.000174477143828648,2.39246495058191E-8,1,5,12.9061126708984,4.98623689351005,37.1199995279312,0.226987512733035,0.0330019954885978,1,-2.59610184034339E-7,,,,,,,,,,,,,,,,,,,,,152.123001098633,152.123001098633,25.4221286773682,25.4221286773682,50.0527546717264,5.36803437327036,7.06460475921631,65,1,0,0,1,0.267715454101562,31.2805480957031,2,1,1,152.123001098633,0,152.123001098633,,,,,,,,,,,,,,,,,,,,,,,,,,,,,,,,,
,3863241970.34745,167.017578125,25.4221286773682,0.000173305677578399,1.98301606951517E-8,1,5,12.9061126708984,4.98618949343919,37.1700003743172,0.225474154414819,0.0326868561490673,1,-3.29462697989817E-7,,,,,,,,,,,,,,,,,,,,,167.017578125,167.017578125,25.4221286773682,25.4221286773682,50.0195354596591,5.36815331399317,7.09554672241211,65,1,0,0,1,0.2685546875,31.2805480957031,2,1,1,167.017578125,0,167.017578125,,,,,,,,,,,,,,,,,,,,,,,,,,,,,,,,,
,3863242061.30337,182.029586791992,25.4221286773682,0.000172433517175983,1.2425598661857E-8,1,5,12.9061126708984,4.98616075180462,37.2299998998642,0.224323277207546,0.0326198631860919,1,-2.52636787007563E-7,,,,,,,,,,,,,,,,,,,,,182.029586791992,182.029586791992,25.4221286773682,25.4221286773682,50.0496281576495,5.36885542632123,7.13290166854858,64,1,64,0,0,0.26763916015625,31.2805480957031,2,1,1,182.029586791992,0,182.029586791992,,,,,,,,,,,,,,,,,,,,,,,,,,,,,,,,,
,3863242151.52167,197.011779785156,25.4221286773682,0.000171665910563634,8.04732842469887E-9,1,5,12.9061126708984,4.98616196691521,37.2899994254112,0.223309175338885,0.0325807056147598,1,-1.69981784838919E-7,,,,,,,,,,,,,,,,,,,,,197.011779785156,197.011779785156,25.4221286773682,25.4221286773682,49.9999947466784,5.36982375569156,7.16614723205566,64,1,64,0,0,0.278244018554687,31.2805480957031,2,1,1,197.011779785156,0,197.011779785156,,,,,,,,,,,,,,,,,,,,,,,,,,,,,,,,,
,3863242241.83217,212.015716552734,25.4221286773682,0.000170856584452267,9.3668378531716E-9,1,5,12.9061126708984,4.98606702002623,37.3499989509583,0.222256683321022,0.0323836785032957,1,-2.01901026999609E-7,,,,,,,,,,,,,,,,,,,,,212.015716552734,212.015716552734,25.4221286773682,25.4221286773682,50.0281333733707,5.36852118102462,7.22352886199951,63,1,64,0,0,0.268402099609375,31.2805480957031,2,1,1,212.015716552734,0,212.015716552734,,,,,,,,,,,,,,,,,,,,,,,,,,,,,,,,,
,3863242332.34983,227.015853881836,25.4221286773682,0.000169808735680764,5.90936086333982E-9,1,5,12.9061126708984,4.98586617407669,37.4299995601177,0.220882267644414,0.0321753430830417,1,-2.06743601200872E-7,,,,,,,,,,,,,,,,,,,,,227.015853881836,227.015853881836,25.4221286773682,25.4221286773682,50.168044878313,5.36978861254056,7.31431293487549,64,1,64,0,0,0.267562866210938,30.7917900085449,2,1,1,227.015853881836,0,227.015853881836,,,,,,,,,,,,,,,,,,,,,,,,,,,,,,,,,
,3863242423.25505,242.087509155273,25.4221286773682,0.000168568042599848,1.24253116257259E-8,1,5,12.9061126708984,4.98556058570825,37.5000014901161,0.219248520707251,0.0319444127067835,1,-1.99922869052385E-7,,,,,,,,,,,,,,,,,,,,,242.087509155273,242.087509155273,25.4221286773682,25.4221286773682,50.0199262739188,5.37113216890361,7.38217306137085,64,1,64,0,0,0.269317626953125,31.2805480957031,2,1,1,242.087509155273,0,242.087509155273,,,,,,,,,,,,,,,,,,,,,,,,,,,,,,,,,
,3863242513.59424,257.047393798828,25.4221286773682,0.000167116934610439,1.75447473249247E-8,1,5,12.9061126708984,4.98516994441769,37.5799983739853,0.217337544038378,0.0316636717061279,1,-1.99943066314019E-7,,,,,,,,,,,,,,,,,,,,,257.047393798828,257.047393798828,25.4221286773682,25.4221286773682,49.9702928629476,5.37279247941664,7.55044937133789,64,1,64,0,0,0.279159545898438,31.2805480957031,2,1,1,257.047393798828,0,257.047393798828,,,,,,,,,,,,,,,,,,,,,,,,,,,,,,,,,
,3863242604.46751,272.197204589844,25.4221286773682,0.000165398947725112,1.85098529432398E-8,1,5,12.9061126708984,4.98499833257261,37.6700013875961,0.215090121147261,0.0313554327509346,1,-1.83441129747399E-7,,,,,,,,,,,,,,,,,,,,,272.197204589844,272.197204589844,25.4221286773682,25.4221286773682,50.1770336062842,5.37371046586662,7.58957386016846,64,1,64,0,0,0.270233154296875,32.2580642700195,2,1,1,272.197204589844,0,272.197204589844,,,,,,,,,,,,,,,,,,,,,,,,,,,,,,,,,
,3863242694.26113,287.034545898438,25.4221286773682,0.000163769535986823,9.20736720809197E-9,1,5,12.9061126708984,4.98487402919288,37.7499982714653,0.212963180507715,0.0310491357886691,1,-1.78799352343217E-7,,,,,,,,,,,,,,,,,,,,,287.034545898438,287.034545898438,25.4221286773682,25.4221286773682,50.0132824315053,5.37438124615713,7.52770233154297,64,1,64,0,0,0.278472900390625,31.2805480957031,2,1,1,287.034545898438,0,287.034545898438,,,,,,,,,,,,,,,,,,,,,,,,,,,,,,,,,
,3863243270.56594,299.999176025391,25.3469161987305,0.00047201890914929,2.83577883219166E-8,1,5,12.9061126708984,4.97409708502698,37.8200002014637,0.611867357391714,0.0897154697298359,1,-1.31812544293112E-7,,,,,,,,,,,,,,,,,,,,,299.999176025391,299.999176025391,25.3469161987305,25.3469161987305,50.0367312870822,5.37528805676756,7.89810419082642,65,1,0,0,1,0.268630981445313,30.7917900085449,2,1,1,299.999176025391,0,299.999176025391,,,,,,,,,,,,,,,,,,,,,,,,,,,,,,,,,
,3863243388.42227,284.779052734375,25.3469161987305,0.000471639809160046,3.37172373167128E-8,1,5,12.9061126708984,4.97363908590436,37.7399995923042,0.611296321033322,0.0896343711696022,1,-1.29720208724525E-7,,,,,,,,,,,,,,,,,,,,,284.779052734375,284.779052734375,25.3469161987305,25.3469161987305,50.0117191744668,5.37679659452835,8.14890289306641,63,1,64,0,0,0.272903442382813,31.2805480957031,2,1,1,284.779052734375,0,284.779052734375,,,,,,,,,,,,,,,,,,,,,,,,,,,,,,,,,
,3863243468.67821,269.982238769531,25.3469161987305,0.000470190650381817,2.00877441405427E-8,1,5,12.9061126708984,4.97336275182577,37.6599989831448,0.609375778294596,0.0893152951111431,1,-1.57622641835738E-7,,,,,,,,,,,,,,,,,,,,,269.982238769531,269.982238769531,25.3469161987305,25.3469161987305,50.0167997598418,5.37744349488945,8.05657386779785,65,1,0,0,1,0.273895263671875,31.2805480957031,2,1,1,269.982238769531,0,269.982238769531,,,,,,,,,,,,,,,,,,,,,,,,,,,,,,,,,
,3863243562.4185,254.987655639648,25.3469161987305,0.000467083743936324,2.02695853106359E-8,1,5,12.9061126708984,4.98416990054277,37.5999994575977,0.607216014791695,0.0888868630917852,1,-2.40833011669681E-7,,,,,,,,,,,,,,,,,,,,,254.987655639648,254.987655639648,25.3469161987305,25.3469161987305,49.9933509042649,5.37717951054846,7.94566965103149,63,1,64,0,0,0.271759033203125,31.2805480957031,2,1,1,254.987655639648,0,254.987655639648,,,,,,,,,,,,,,,,,,,,,,,,,,,,,,,,,
,3863243651.40552,239.998016357422,25.3469161987305,0.000462887900307874,2.2366831753666E-8,1,5,12.9061126708984,4.98401869316915,37.5300012528896,0.601735225100468,0.0880879043335382,1,-2.36152263155895E-7,,,,,,,,,,,,,,,,,,,,,239.998016357422,239.998016357422,25.3469161987305,25.3469161987305,50.1035605254765,5.37661153003808,7.8759617805481,64,1,64,0,0,0.2679443359375,30.7917900085449,2,1,1,239.998016357422,0,239.998016357422,,,,,,,,,,,,,,,,,,,,,,,,,,,,,,,,,
,3863243742.53476,224.980194091797,25.3469161987305,0.000456795814051543,1.5171277448093E-8,1,5,12.9061126708984,4.98404328246291,37.4700017273426,0.59383908121406,0.0867984762455119,1,-3.33594414014698E-7,,,,,,,,,,,,,,,,,,,,,224.980194091797,224.980194091797,25.3469161987305,25.3469161987305,50.0730770132265,5.37581238406441,7.82145547866821,65,1,0,0,1,0.269317626953125,30.7917900085449,2,1,1,224.980194091797,0,224.980194091797,,,,,,,,,,,,,,,,,,,,,,,,,,,,,,,,,
,3863243830.15065,209.972778320313,25.3469161987305,0.000448452864674863,2.88829140337249E-8,1,5,12.9061126708984,4.98427899848524,37.4200008809567,0.583036016015254,0.0851908351166797,1,-3.49048399805315E-7,,,,,,,,,,,,,,,,,,,,,209.972778320313,209.972778320313,25.3469161987305,25.3469161987305,50.1266185667938,5.37611415707403,7.77174520492554,65,1,0,0,1,0.272674560546875,31.7693061828613,2,1,1,209.972778320313,0,209.972778320313,,,,,,,,,,,,,,,,,,,,,,,,,,,,,,,,,
,3863243920.35913,194.996307373047,25.3469161987305,0.000437320227603709,2.78940464713455E-8,1,5,12.9061126708984,4.98438411024412,37.3700000345707,0.568573340275043,0.083118757135335,1,-3.09395451970708E-7,,,,,,,,,,,,,,,,,,,,,194.996307373047,194.996307373047,25.3469161987305,25.3469161987305,50.1285726380918,5.37508826079507,7.71173191070557,65,1,0,0,1,0.271377563476562,29.3255138397217,2,1,1,194.996307373047,0,194.996307373047,,,,,,,,,,,,,,,,,,,,,,,,,,,,,,,,,
,3863244011.48643,179.870697021484,25.3469161987305,0.000422478563800488,4.22611157141167E-8,1,5,12.9061126708984,4.98466842770045,37.3199991881847,0.549332236164478,0.0802295938296942,1,-3.56378865240207E-7,,,,,,,,,,,,,,,,,,,,,179.870697021484,179.870697021484,25.3469161987305,25.3469161987305,50.0734678274861,5.37448177285833,7.6702618598938,65,1,0,0,1,0.27374267578125,31.2805480957031,2,1,1,179.870697021484,0,179.870697021484,,,,,,,,,,,,,,,,,,,,,,,,,,,,,,,,,
,3863244100.16152,164.985427856445,25.3469161987305,0.000403767047551924,5.219307166977E-8,1,5,12.9061126708984,4.98500570659696,37.2699983417988,0.525053532065884,0.0766750687127703,1,-3.47098177554719E-7,,,,,,,,,,,,,,,,,,,,,164.985427856445,164.985427856445,25.3469161987305,25.3469161987305,50.1133308819668,5.37162650682327,7.62252759933472,64,1,64,0,0,0.267791748046875,32.7468223571777,2,1,1,164.985427856445,0,164.985427856445,,,,,,,,,,,,,,,,,,,,,,,,,,,,,,,,,
,3863244192.35958,149.791717529297,25.3469161987305,0.000374951447273229,6.74363302512672E-8,1,5,12.9061126708984,4.98549357338317,37.2099988162518,0.487649186796489,0.0712123334246387,1,-3.22682040433535E-7,,,,,,,,,,,,,,,,,,,,,149.791717529297,149.791717529297,25.3469161987305,25.3469161987305,50.0855830695341,5.37066860393924,7.57324409484863,65,1,0,0,1,0.270462036132813,30.3030319213867,2,1,1,149.791717529297,0,149.791717529297,,,,,,,,,,,,,,,,,,,,,,,,,,,,,,,,,
,3863244280.28753,134.977584838867,25.3469161987305,0.000335053352152421,1.11924912764179E-7,1,5,12.9061126708984,4.98573405145246,37.1799990534782,0.435793889343318,0.063602988056902,1,-3.1606224319997E-7,,,,,,,,,,,,,,,,,,,,,134.977584838867,134.977584838867,25.3469161987305,25.3469161987305,50.132480780688,5.36926948213592,7.53284502029419,64,1,64,0,0,0.26763916015625,30.7917900085449,2,1,1,134.977584838867,0,134.977584838867,,,,,,,,,,,,,,,,,,,,,,,,,,,,,,,,,
,3863244371.20284,119.964805603027,25.3469161987305,0.000247499435043763,2.27857143567124E-7,1,5,12.9061126708984,4.98591592207971,37.1299982070923,0.321943270044256,0.0469057611166424,1,-2.94462916577882E-7,,,,,,,,,,,,,,,,,,,,,119.964805603027,119.964805603027,25.3469161987305,25.3469161987305,50.0203170881784,5.36849275305596,7.47861051559448,65,1,0,0,1,0.27801513671875,31.2805480957031,2,1,1,119.964805603027,0,119.964805603027,,,,,,,,,,,,,,,,,,,,,,,,,,,,,,,,,
,3863244459.74738,104.997604370117,25.3469161987305,0.000161069585969526,7.36657073997631E-8,1,5,12.9061126708984,4.98584857370347,37.0899997651577,0.209542365168653,0.0303234779776901,1,-3.46673193961065E-7,,,,,,,,,,,,,,,,,,,,,104.997604370117,104.997604370117,25.3469161987305,25.3469161987305,50.0746402702649,5.36869069465512,7.42449712753296,64,1,64,0,0,0.268478393554687,31.2805480957031,2,1,1,104.997604370117,0,104.997604370117,,,,,,,,,,,,,,,,,,,,,,,,,,,,,,,,,
,3863244549.82317,89.9977722167969,25.3469161987305,0.000144832644723733,3.00484394279387E-8,1,5,12.9061126708984,4.98591120456994,37.0500013232231,0.188416509646325,0.0273069135115668,1,-2.81144365048091E-7,,,,,,,,,,,,,,,,,,,,,89.9977722167969,89.9977722167969,25.3469161987305,25.3469161987305,50.0339955872649,5.36856010845572,7.35409164428711,63,1,64,0,0,0.2777099609375,31.2805480957031,2,1,1,89.9977722167969,0,89.9977722167969,,,,,,,,,,,,,,,,,,,,,,,,,,,,,,,,,
,3863244638.64575,74.9926605224609,25.3469161987305,0.000141344172488875,2.95026654918607E-8,1,5,12.9061126708984,4.98584189612681,37.0099991559982,0.183866725768905,0.0267027928451185,1,-2.32758701100082E-7,,,,,,,,,,,,,,,,,,,,,74.9926605224609,74.9926605224609,25.3469161987305,25.3469161987305,50.0605709569188,5.3682840884051,7.2702374458313,63,1,64,0,0,0.2691650390625,31.7693061828613,2,1,1,74.9926605224609,0,74.9926605224609,,,,,,,,,,,,,,,,,,,,,,,,,,,,,,,,,
,3863244726.50584,59.9907913208008,25.3469161987305,0.000140088256667937,3.08445209453319E-8,1,5,12.9061126708984,4.98581579539326,36.9900017976761,0.182232632886935,0.0264585398690554,1,-2.35911752687657E-7,,,,,,,,,,,,,,,,,,,,,59.9907913208008,59.9907913208008,25.3469161987305,25.3469161987305,50.1559296362649,5.36860638524341,7.15918779373169,65,1,0,0,1,0.269927978515625,31.2805480957031,2,1,1,59.9907913208008,0,59.9907913208008,,,,,,,,,,,,,,,,,,,,,,,,,,,,,,,,,
,3863244814.94524,44.7852439880371,25.3469161987305,0.000139860962514749,3.38293070100123E-8,1,5,12.9061126708984,4.98590455065916,36.9499996304512,0.18193263481044,0.0264766688349799,1,-1.89088949380214E-7,,,,,,,,,,,,,,,,,,,,,44.7852439880371,44.7852439880371,25.3469161987305,25.3469161987305,50.0277425591111,5.36827353195773,6.97681093215942,65,1,0,0,1,0.268325805664062,30.7917900085449,2,1,1,44.7653770446777,0,44.7852439880371,,,,,,,,,,,,,,,,,,,,,,,,,,,,,,,,,
,3863244902.53528,29.8894329071045,25.3469161987305,0.000139552346083131,3.43328257927721E-8,1,5,12.9061126708984,4.98588874402472,36.9299985468388,0.181520268712788,0.0264869198598154,1,-1.35777082482849E-7,,,,,,,,,,,,,,,,,,,,,29.8894329071045,29.8894329071045,25.3469161987305,25.3469161987305,50.0957442402841,5.36768759583786,6.68829393386841,65,1,0,0,1,0.268173217773438,31.2805480957031,2,1,1,29.8894329071045,0,29.8894329071045,,,,,,,,,,,,,,,,,,,,,,,,,,,,,,,,,
,3863244991.67961,14.9806184768677,25.3469161987305,0.000139279093841178,2.80404237175687E-8,1,5,12.9061126708984,4.98583700145849,36.9100011885166,0.181156546514574,0.0264731549698466,1,-1.05920576396573E-7,,,,,,,,,,,,,,,,,,,,,14.9806184768677,14.9806184768677,25.3469161987305,25.3469161987305,50.0859738837938,5.36844692068055,6.01760625839233,65,1,0,0,1,0.268096923828125,30.7917900085449,2,1,1,14.9806184768677,0,14.9806184768677,,,,,,,,,,,,,,,,,,,,,,,,,,,,,,,,,
,3863245250.77247,18.019006729126,25.3469161987305,0.000139443397516254,2.97715898576679E-8,1,5,12.9061126708984,4.98593889110724,36.8900001049042,0.181378571653645,0.0264839469304164,1,-1.22344897540058E-7,,,,,,,,,,,,,,,,,,,,,18.019006729126,18.019006729126,25.3469161987305,25.3469161987305,50.061352585438,5.36849030785692,5.65619087219238,65,1,0,0,1,0.27740478515625,31.2805480957031,2,1,1,18.019006729126,0,18.019006729126,,,,,,,,,,,,,,,,,,,,,,,,,,,,,,,,,
,3863245348.5179,33.0596179962158,25.3469161987305,0.000139897715970645,2.7708702044435E-8,1,5,12.9061126708984,4.98592290164129,36.8900001049042,0.181972269579687,0.0265458091747685,1,-1.41431654149225E-7,,,,,,,,,,,,,,,,,,,,,33.0471725463867,33.0720634460449,25.3469161987305,25.3469161987305,50.010546731688,5.36887770006259,6.20620250701904,65,1,0,0,1,0.267715454101562,31.2805480957031,2,1,1,33.0720634460449,0,33.0596179962158,,,,,,,,,,,,,,,,,,,,,,,,,,,,,,,,,
,3863245443.82748,48.0159454345703,25.3469161987305,0.000140195454348562,3.41927129370672E-8,1,5,12.9061126708984,4.98582180822697,36.8999987840652,0.182358943785293,0.0265703505848324,1,-1.65721007651039E-7,,,,,,,,,,,,,,,,,,,,,48.0159454345703,48.0159454345703,25.3469161987305,25.3469161987305,50.0781575986015,5.36928305540653,6.4740948677063,65,1,0,0,1,0.268402099609375,31.2805480957031,2,1,1,48.0159454345703,0,48.0159454345703,,,,,,,,,,,,,,,,,,,,,,,,,,,,,,,,,
,3863245538.96133,63.0463466644287,25.3469161987305,0.000140644864292677,2.7156549383607E-8,1,5,12.9061126708984,4.98575478359517,36.9199998676777,0.182950659520328,0.026582863658649,1,-2.21736749157739E-7,,,,,,,,,,,,,,,,,,,,,63.0289039611816,63.0637893676758,25.3469161987305,25.3469161987305,50.000385560938,5.36952056537278,6.63508272171021,65,1,0,0,1,0.2783203125,30.7917900085449,2,1,1,63.0637893676758,0,63.0463466644287,,,,,,,,,,,,,,,,,,,,,,,,,,,,,,,,,
,3863245632.98201,78.0135726928711,25.3469161987305,0.000141875535361772,2.78656216861275E-8,1,5,12.9061126708984,4.98567463293014,36.9400009512901,0.184550379197048,0.0267942307027699,1,-2.39542777163184E-7,,,,,,,,,,,,,,,,,,,,,78.0135726928711,78.0135726928711,25.3469161987305,25.3469161987305,50.0070294033514,5.3698513806746,6.79458475112915,63,1,64,0,0,0.27008056640625,31.2805480957031,2,1,1,78.0135726928711,0,78.0135726928711,,,,,,,,,,,,,,,,,,,,,,,,,,,,,,,,,
,3863245725.04146,93.0116348266602,25.3469161987305,0.000145219938975589,2.34032527321456E-8,1,5,12.9061126708984,4.98565503214087,36.9700007140636,0.188890270533872,0.0274899154011444,1,-1.95806139357805E-7,,,,,,,,,,,,,,,,,,,,,93.0116348266602,93.0116348266602,25.3469161987305,25.3469161987305,50.1336532234668,5.37008996310329,6.89640188217163,65,1,0,0,1,0.28045654296875,31.2805480957031,2,1,1,93.0116348266602,0,93.0116348266602,,,,,,,,,,,,,,,,,,,,,,,,,,,,,,,,,
,3863245816.69353,108.109367370605,25.3469161987305,0.000160986861261046,7.41014006573742E-8,1,5,12.9061126708984,4.98555473666298,37.0000004768372,0.209397607037345,0.0304401893151835,1,-2.42841279867471E-7,,,,,,,,,,,,,,,,,,,,,108.109367370605,108.109367370605,25.3469161987305,25.3469161987305,50.0273517448514,5.37035861998077,6.94884347915649,65,1,0,0,1,0.278167724609375,31.2805480957031,2,1,1,108.109367370605,0,108.109367370605,,,,,,,,,,,,,,,,,,,,,,,,,,,,,,,,,
,3863245907.02706,123.025512695313,25.3469161987305,0.00021583046255237,1.04289408858559E-7,1,5,12.9061126708984,4.9855575194122,37.0399989187717,0.280798234772244,0.0403702214291755,1,-6.63996833593276E-7,,,,,,,,,,,,,,,,,,,,,123.025512695313,123.025512695313,25.3469161987305,25.3469161987305,50.0394669868995,5.37081589756753,7.00633525848389,64,1,64,0,0,0.268020629882813,31.2805480957031,2,1,1,123.025512695313,0,123.025512695313,,,,,,,,,,,,,,,,,,,,,,,,,,,,,,,,,
,3863245997.48478,138.040893554688,25.3469161987305,0.000242465442821943,3.27062846511483E-8,1,5,12.9061126708984,4.98552864020845,37.0800010859966,0.315444624241624,0.0453756377889043,1,-7.27622024309975E-7,,,,,,,,,,,,,,,,,,,,,138.040893554688,138.040893554688,25.3469161987305,25.3469161987305,49.9562235496014,5.37161802929326,7.04262208938599,64,1,64,0,0,0.268478393554687,31.2805480957031,2,1,1,138.040893554688,0,138.040893554688,,,,,,,,,,,,,,,,,,,,,,,,,,,,,,,,,
,3863246087.79782,153.072082519531,25.3469161987305,0.000250229152958085,2.50841200634227E-8,1,5,12.9061126708984,4.98549302298554,37.1299982070923,0.325513106840562,0.0470237475461576,1,-6.00460737137779E-7,,,,,,,,,,,,,,,,,,,,,153.072082519531,153.072082519531,25.3469161987305,25.3469161987305,50.041030243938,5.37101114802947,7.08398818969727,64,1,64,0,0,0.27069091796875,31.7693061828613,2,1,1,153.072082519531,0,153.072082519531,,,,,,,,,,,,,,,,,,,,,,,,,,,,,,,,,
,3863246178.74967,168.005615234375,25.3469161987305,0.000255405513873978,1.66420848312809E-8,1,5,12.9061126708984,4.98548512404575,37.1799990534782,0.332202837815453,0.0482907977631455,1,-3.86489200750012E-7,,,,,,,,,,,,,,,,,,,,,168.005615234375,168.005615234375,25.3469161987305,25.3469161987305,50.046110829313,5.37086522047084,7.11945486068726,63,1,64,0,0,0.269622802734375,30.7917900085449,2,1,1,168.005615234375,0,168.005615234375,,,,,,,,,,,,,,,,,,,,,,,,,,,,,,,,,
,3863246269.47972,183.095565795898,25.3469161987305,0.000259160091870779,1.60469191662318E-8,1,5,12.9061126708984,4.98541947110478,37.2299998998642,0.337051875892989,0.0491921556610721,1,-2.44238484882733E-7,,,,,,,,,,,,,,,,,,,,,183.095565795898,183.095565795898,25.3469161987305,25.3469161987305,49.9894427616688,5.37144599307776,7.14518117904663,63,1,64,0,0,0.269775390625,31.2805480957031,2,1,1,183.095565795898,0,183.095565795898,,,,,,,,,,,,,,,,,,,,,,,,,,,,,,,,,
,3863246359.74518,198.073059082031,25.3469161987305,0.000261551322365729,2.50322461488996E-8,1,5,12.9061126708984,4.98527848531974,37.2899994254112,0.340157693589612,0.049580066046431,1,-2.95715278078858E-7,,,,,,,,,,,,,,,,,,,,,198.073059082031,198.073059082031,25.3469161987305,25.3469161987305,50.0769851558226,5.37253651356263,7.19102621078491,63,1,64,0,0,0.266036987304687,31.2805480957031,2,1,1,198.073059082031,0,198.073059082031,,,,,,,,,,,,,,,,,,,,,,,,,,,,,,,,,
,3863246449.97351,213.008529663086,25.3469161987305,0.000262898684417091,2.18575169083592E-8,1,5,12.9061126708984,4.98507551533833,37.3600013554096,0.341879130323227,0.0499095899868516,1,-2.38045405038271E-7,,,,,,,,,,,,,,,,,,,,,213.008529663086,213.008529663086,25.3469161987305,25.3469161987305,50.0242252307745,5.37342678763551,7.23662185668945,64,1,64,0,0,0.273818969726562,31.2805480957031,2,1,1,213.008529663086,0,213.008529663086,,,,,,,,,,,,,,,,,,,,,,,,,,,,,,,,,
,3863246540.76118,228.011306762695,25.3469161987305,0.000263346450386912,1.65586675028666E-8,1,5,12.9061126708984,4.98492133926258,37.4299995601177,0.342442352848225,0.050020906364617,1,-2.16544182991855E-7,,,,,,,,,,,,,,,,,,,,,228.011306762695,228.011306762695,25.3469161987305,25.3469161987305,49.9644306490534,5.37413432252113,7.30466365814209,64,1,64,0,0,0.278701782226562,31.2805480957031,2,1,1,228.011306762695,0,228.011306762695,,,,,,,,,,,,,,,,,,,,,,,,,,,,,,,,,
,3863246631.00145,243.001907348633,25.3469161987305,0.000263171354713347,1.91513419693741E-8,1,5,12.9061126708984,4.98460741795981,37.5000014901161,0.342182019453379,0.0499993927615264,1,-2.03965069196117E-7,,,,,,,,,,,,,,,,,,,,,243.001907348633,243.001907348633,25.3469161987305,25.3469161987305,50.0289150018899,5.37568801945981,7.39202880859375,64,1,64,0,0,0.272369384765625,30.7917900085449,2,1,1,243.001907348633,0,243.001907348633,,,,,,,,,,,,,,,,,,,,,,,,,,,,,,,,,
,3863246721.72207,258.036834716797,25.3469161987305,0.000262250783768228,2.16787382960766E-8,1,5,12.9061126708984,4.9843637335754,37.5900007784367,0.340962494955158,0.0498153359046874,1,-2.07665211214199E-7,,,,,,,,,,,,,,,,,,,,,258.036834716797,258.036834716797,25.3469161987305,25.3469161987305,50.0629158424764,5.37663601357676,7.56786727905273,64,1,64,0,0,0.268630981445313,31.2805480957031,2,1,1,258.036834716797,0,258.036834716797,,,,,,,,,,,,,,,,,,,,,,,,,,,,,,,,,
,3863246811.19219,273.009490966797,25.3469161987305,0.000260884477087612,2.06302864204654E-8,1,5,12.9061126708984,4.98417374652177,37.6700013875961,0.339165163282892,0.0495720709493752,1,-1.92026365114426E-7,,,,,,,,,,,,,,,,,,,,,273.009490966797,273.009490966797,25.3469161987305,25.3469161987305,50.0418118724572,5.37770768461914,7.59622383117676,63,1,64,0,0,0.268936157226562,31.7693061828613,2,1,1,273.009490966797,0,273.009490966797,,,,,,,,,,,,,,,,,,,,,,,,,,,,,,,,,
,3863246901.71674,288.016784667969,25.3469161987305,0.000259653068620331,1.29129803244962E-8,1,5,12.9061126708984,4.9842983676118,37.7600006759167,0.337575663344503,0.0493429087198928,1,-1.88742021110961E-7,,,,,,,,,,,,,,,,,,,,,288.016784667969,288.016784667969,25.3469161987305,25.3469161987305,50.0382945441207,5.37649098230426,7.54155111312866,63,1,64,0,0,0.270538330078125,30.7917900085449,2,1,1,288.016784667969,0,288.016784667969,,,,,,,,,,,,,,,,,,,,,,,,,,,,,,,,,
,3863248293.54131,9.99972057342529,25.3469161987305,,,5,,,,36.8900001049042,,,,,1.01098735140162E-5,2.61847494351079E-9,0.108759577476539,0.000189069463063882,3.37000481011835E-6,8.72837147029774E-10,3.36999873870008E-6,5.97504566869014E-10,6.39698215555939E-9,6.36264864506715E-10,2.99995818512233,28.2570171356201,10,282,1,3,0.0350160885807018,0.00591793190985462,0.00850535649806261,228.768417358398,9.99888134002686,10.0014209747314,25.3469161987305,25.3469161987305,,,5.08158779144287,,1,,,,,,1,1,1,10.0001459121704,0,9.99997858206431,,,,,,,,,,,,,,,,,,,,,,,,,,,,,,,,,
,3863249792.83709,24.9998865127563,25.3469161987305,,,5,,,,36.8900001049042,,,,,6.48240169372018E-6,7.32421483726687E-9,0.28917489288489,0.000383838597466135,2.1607509799595E-6,2.44134892201906E-9,2.16072345987881E-6,2.30214059461583E-9,1.09053805669985E-8,8.12608910648605E-10,3.00006884358404,28.2570171356201,10,282,1,3,0.0224404575728408,0.0038630763808523,0.00848483946174383,228.718490600586,24.9998321533203,25.0005512237549,25.3469161987305,25.3469161987305,,,5.94992971420288,,1,,,,,,1,1,1,24.9999408721924,0,25.0001653671265,,,,,,,,,,,,,,,,,,,,,,,,,,,,,,,,,
,3863251304.06859,39.9997806549072,25.3469161987305,,,5,,,,36.8999987840652,,,,,5.73412648436966E-6,3.55514791108346E-9,0.277304839576647,0.000370062210478026,1.91144100620376E-6,1.18508992065102E-9,1.91141861900843E-6,9.52907402167973E-10,9.25111372476771E-9,7.04560574345552E-10,2.99989718006416,28.2570171356201,10,282,1,3,0.0198515068246528,0.00340905806263299,0.00845827627927065,228.672958374023,39.9994201660156,40.0003471374512,25.3469161987305,25.3469161987305,,,6.34965229034424,,1,,,,,,1,1,1,40.0000152587891,0,39.9998776912689,,,,,,,,,,,,,,,,,,,,,,,,,,,,,,,,,
,3863252797.28766,55.0000152587891,25.3469161987305,,,5,,,,36.9199998676777,,,,,5.47601394930826E-6,3.29142496793177E-9,0.268182913723118,0.000299043130317336,1.82535066865429E-6,1.09714928078271E-9,1.8253306731452E-6,9.53956789920612E-10,8.54384175519316E-9,5.41943712286053E-10,2.99997915104464,28.2570171356201,10,282,1,3,0.0189587436081398,0.00325082848521117,0.00845256540924311,228.655334472656,54.9993896484375,55.0010643005371,25.3469161987305,25.3469161987305,,,6.57140874862671,,1,,,,,,1,1,1,55.0002975463867,0,55.0001481503856,,,,,,,,,,,,,,,,,,,,,,,,,,,,,,,,,
,3863254338.31309,69.9998283386231,25.3469161987305,,,5,,,,36.9400009512901,,,,,5.32303871064517E-6,4.08814709414929E-9,0.217598671523495,0.000282661019914753,1.77434218981614E-6,1.36271258986282E-9,1.77432939382072E-6,1.27000727602056E-9,6.73860410805554E-9,4.94031498414307E-10,3.00000684264671,28.2570171356201,10,282,1,3,0.0184320150193638,0.00314310486568476,0.00844638608396053,228.650924682617,69.998779296875,70.0010452270508,25.3469161987305,25.3469161987305,,,6.7091178894043,,1,,,,,,1,1,1,70.0000152587891,0,70.0000489807129,,,,,,,,,,,,,,,,,,,,,,,,,,,,,,,,,
,3863255910.46755,84.9994888305664,25.3469161987305,,,5,,,,36.9700007140636,,,,,5.50898286662322E-6,5.99212726576837E-9,0.308387408356879,0.000530871305241694,1.83636977744697E-6,1.99742160756035E-9,1.8363431777247E-6,1.74768019215358E-9,9.8839842466934E-9,9.67112725747623E-10,2.99993113276027,28.2570171356201,10,282,1,3,0.0190707669854451,0.00328276565876885,0.00843783840537071,228.663803100586,84.9983596801758,85.0009765625,25.3469161987305,25.3469161987305,,,6.80415487289429,,1,,,,,,1,1,1,84.9994201660156,0,84.9998530261921,,,,,,,,,,,,,,,,,,,,,,,,,,,,,,,,,
,3863257459.18817,100.000057220459,25.3469161987305,,,5,,,,37.0000004768372,,,,,7.66274389800694E-6,5.56185385008414E-9,0.362067556093393,0.000440772136372506,2.55426246468359E-6,1.85396180694762E-9,2.5542114649348E-6,1.47638667560405E-9,1.61409692117302E-8,1.12136379722163E-9,2.99998297119249,28.2570171356201,10,282,1,3,0.0265223396036795,0.00459069207477351,0.00844040606170893,228.654724121094,99.9977951049805,100.001884460449,25.3469161987305,25.3469161987305,,,6.87283325195313,,1,,,,,,1,1,1,99.9999771118164,0,99.9999858093262,,,,,,,,,,,,,,,,,,,,,,,,,,,,,,,,,
,3863258984.17308,114.999835968018,25.3469161987305,,,5,,,,37.0300002396107,,,,,1.17117058570527E-5,5.81564996372801E-9,0.163411997276061,0.000295947481507213,3.90393427851784E-6,1.93856604002624E-9,3.90391840055361E-6,1.55965742490991E-9,1.11343075916769E-8,1.15130665266315E-9,2.9999751587773,28.2570171356201,10,282,1,3,0.0405607911804232,0.00687540795525427,0.00844104401767254,228.655975341797,114.997055053711,115.001930236816,25.3469161987305,25.3469161987305,,,6.93139219284058,,1,,,,,,1,1,1,114.999847412109,0,114.999927910007,,,,,,,,,,,,,,,,,,,,,,,,,,,,,,,,,
,3863260539.89898,129.999542236328,25.3469161987305,,,5,,,,37.0699986815453,,,,,1.25324056199929E-5,5.07421182919966E-9,0.166821756666405,0.000186707676621711,4.17751171434367E-6,1.6914214238108E-9,4.17749400724166E-6,1.50398469447644E-9,1.21631796261469E-8,7.73909860194809E-10,2.99996899517058,28.2570171356201,10,282,1,3,0.0434027263480193,0.00735943128326637,0.00843932945281267,228.656982421875,129.997299194336,130.002456665039,25.3469161987305,25.3469161987305,,,6.9765682220459,,1,,,,,,1,1,1,129.999359130859,0,130.000125591572,,,,,,,,,,,,,,,,,,,,,,,,,,,,,,,,,
,3863262125.74316,144.999603271484,25.3469161987305,,,5,,,,37.1199995279312,,,,,1.22377006298268E-5,6.79633242812129E-9,0.143902896893566,0.000203691067114439,4.0793503216093E-6,2.26550899675119E-9,4.07933745528222E-6,2.11200202977117E-9,1.02456012736831E-8,8.19742911285627E-10,2.99991411990306,28.2570171356201,10,282,1,3,0.0423850247356501,0.00716911169710942,0.00843810942023993,228.66764831543,144.996231079102,145.00276184082,25.3469161987305,25.3469161987305,,,7.01790142059326,,1,,,,,,1,1,1,144.999740600586,0,144.999865837817,,,,,,,,,,,,,,,,,,,,,,,,,,,,,,,,,
,3863263701.66949,159.999168395996,25.3469161987305,,,5,,,,37.1700003743172,,,,,1.19514260195748E-5,3.04037905325952E-9,0.172097646863119,0.000155606610787917,3.98385854862319E-6,1.01347237246369E-9,3.98384057737727E-6,8.03305758041703E-10,1.19661806950429E-8,6.17920794960188E-10,2.99996244186562,28.2570171356201,10,282,1,3,0.041390124960015,0.0070215023321733,0.00844299327582121,228.658081054687,159.995315551758,160.003143310547,25.3469161987305,25.3469161987305,,,7.05416297912598,,1,,,,,,1,1,1,159.999557495117,0,159.999681507457,,,,,,,,,,,,,,,,,,,,,,,,,,,,,,,,,
,3863265288.46709,174.999397277832,25.3469161987305,,,5,,,,37.2200012207031,,,,,1.17289273662713E-5,5.64613465086687E-9,0.169751821523995,0.000162491544597106,3.90974866878784E-6,1.88209601318738E-9,3.90973150938584E-6,1.77548757220689E-9,1.15835056774007E-8,6.24443178996072E-10,2.99991850113161,28.2570171356201,10,282,1,3,0.0406199050015477,0.00688887153030906,0.00844135135412216,228.666564941406,174.994537353516,175.003540039062,25.3469161987305,25.3469161987305,,,7.09143400192261,,1,,,,,,1,1,1,174.999710083008,0,174.999802499447,,,,,,,,,,,,,,,,,,,,,,,,,,,,,,,,,
,3863266849.8471,189.999473571777,25.3469161987305,,,5,,,,37.2800007462502,,,,,1.16322217385026E-5,4.55280429857883E-9,0.155047667123597,0.000151444916642654,3.87746986934524E-6,1.51762594331677E-9,3.87745567212308E-6,1.40235414894552E-9,1.04927785073217E-8,5.80164928932638E-10,2.99995154842219,28.2570171356201,10,282,1,3,0.0402867973171109,0.00682149949547144,0.00844391342252493,228.659973144531,189.992721557617,190.004684448242,25.3469161987305,25.3469161987305,,,7.12698936462402,,1,,,,,,1,1,1,189.999465942383,0,189.999742861147,,,,,,,,,,,,,,,,,,,,,,,,,,,,,,,,,
,3863268436.03062,204.999542236328,25.3469161987305,,,5,,,,37.3400002717972,,,,,1.14636457675917E-5,5.39637073264847E-9,0.172823245858156,0.000160533117290444,3.82133268782335E-6,1.79884552387167E-9,3.82131530406906E-6,1.69470731089545E-9,1.15264007713423E-8,6.03168590984846E-10,2.99990780811118,28.2570171356201,10,282,1,3,0.0397009208841748,0.00673473731643475,0.00844269618391991,228.669326782227,204.992584228516,205.0048828125,25.3469161987305,25.3469161987305,,,7.17287540435791,,1,,,,,,1,1,1,205.000198364258,0,204.999717296254,,,,,,,,,,,,,,,,,,,,,,,,,,,,,,,,,
,3863270017.16091,219.999572753906,25.3469161987305,,,5,,,,37.3999997973442,,,,,1.13906598230732E-5,5.67698420720152E-9,0.20771427618909,0.000183174994373995,3.79696408054531E-6,1.89236668071715E-9,3.79693912922992E-6,1.76394612999992E-9,1.37650962222119E-8,6.85234051070684E-10,2.99993878831671,28.2570171356201,10,282,1,3,0.0394441287236578,0.00671566805949998,0.00844622030854225,228.662307739258,219.991180419922,220.00471496582,25.3469161987305,25.3469161987305,,,7.23210430145264,,1,,,,,,1,1,1,219.9990234375,0,219.999359418761,,,,,,,,,,,,,,,,,,,,,,,,,,,,,,,,,
,3863271646.94209,234.999557495117,25.3469161987305,,,5,,,,37.4700017273426,,,,,1.13233642833694E-5,5.42205525540055E-9,0.206140267187395,0.000228754496081278,3.77459305203592E-6,1.80741797072166E-9,3.77456862222664E-6,1.59130443561738E-9,1.35803011709821E-8,8.5703553839503E-10,2.99989008808828,28.2570171356201,10,282,1,3,0.0392113359284199,0.00667471002905946,0.00844338536262512,228.679916381836,234.989639282227,235.006271362305,25.3469161987305,25.3469161987305,,,7.33517408370972,,1,,,,,,1,1,1,234.999099731445,0,234.999794854058,,,,,,,,,,,,,,,,,,,,,,,,,,,,,,,,,
,3863273232.78439,249.99983215332,25.3469161987305,,,5,,,,37.5399999320507,,,,,1.1255878617192E-5,6.70952358547171E-9,0.190581000091717,0.000353578983749502,3.75209518088596E-6,2.23658871664071E-9,3.7520744242299E-6,1.80421682954022E-9,1.24804434023052E-8,1.32179072451292E-9,2.99989154713667,28.2570171356201,10,282,1,3,0.0389795045660817,0.00662414607537601,0.00844322890043259,228.68229675293,249.990570068359,250.006774902344,25.3469161987305,25.3469161987305,,,7.54160118103027,,1,,,,,,1,1,1,249.999404907227,0,250.000272930793,,,,,,,,,,,,,,,,,,,,,,,,,,,,,,,,,
,3863274829.55667,264.999450683594,25.3469161987305,,,5,,,,37.6200005412102,,,,,1.11679324778354E-5,4.57995843604244E-9,0.167562448636488,0.000172195885686197,3.72277411781808E-6,1.52670610788704E-9,3.72275819776497E-6,1.38853909314618E-9,1.0887298558499E-8,6.34657960372663E-10,2.99989527282438,28.2570171356201,10,282,1,3,0.0386776501120177,0.00655665875576594,0.00844594277441502,228.67399597168,264.990203857422,265.007232666016,25.3469161987305,25.3469161987305,,,7.8770866394043,,1,,,,,,1,1,1,264.998870849609,0,264.999666034051,,,,,,,,,,,,,,,,,,,,,,,,,,,,,,,,,
,3863276439.21532,279.999740600586,25.3469161987305,,,5,,,,37.7099998295307,,,,,1.1059345286476E-5,3.32084545989375E-9,0.140768300476003,0.000216323623070647,3.68657736453837E-6,1.10698720280893E-9,3.68656623806307E-6,7.68988645844144E-10,9.0574334183858E-9,7.96289601681159E-10,2.99989507689632,28.2570171356201,10,282,1,3,0.0383046933757102,0.0064748093508557,0.00844315253198147,228.684753417969,279.991394042969,280.007446289062,25.3469161987305,25.3469161987305,,,7.96353912353516,,1,,,,,,1,1,1,279.998748779297,0,280.000368514151,,,,,,,,,,,,,,,,,,,,,,,,,,,,,,,,,
,3863278057.55174,294.998992919922,25.3469161987305,,,5,,,,37.7900004386902,,,,,1.09925240267708E-5,6.95240242145508E-9,0.135534092687918,0.000327282932332718,3.66427029786971E-6,2.31752795170002E-9,3.66426004585679E-6,1.9869768630322E-9,8.6678825428288E-9,1.19283643165593E-9,2.99992171242428,28.2570171356201,10,282,1,3,0.0380739368088383,0.00643203037668193,0.00844177231192589,228.693023681641,294.991424560547,295.007934570313,25.3469161987305,25.3469161987305,,,8.47311878204346,,1,,,,,,1,1,1,294.997833251953,0,295.00027926463,,,,,,,,,,,,,,,,,,,,,,,,,,,,,,,,,
,3863278721.11088,300.001892089844,25.3469161987305,,,5,,,,37.8299988806248,,,,,1.11620117731551E-5,1.53473569373691E-8,-0.769235130204054,0.000569052364075337,3.7204701476002E-6,5.11551004339306E-9,3.72013484705477E-6,4.65311789537817E-9,-4.99483624662666E-8,2.12530864952991E-9,3.00016162751767,800.461120605469,10,8004,1,3,0.039167558126914,0.00551795192576992,0.0138401016592979,178.270843505859,299.990417480469,300.010223388672,25.3469161987305,25.3469161987305,,,8.43678188323975,,1,,,,,,1,1,1,300.001098632812,0,300.001914672852,,,,,,,,,,,,,,,,,,,,,,,,,,,,,,,,,