File: data/Rock_mag_data/MPMS3/DA4-A-FC-ZFC-RT-SIRM-AC_sweep.dat
[Header]
; MPMS3 Data File (default extension .dat)
; Copyright (c) 2007, Quantum Design, Inc. All rights reserved.
TITLE,
FILEOPENTIME,3863174429.51278,05/31/2022,4:58 pm
BYAPP,MPMS3 w/ AC,1.0,1.1
INFO,MPMS3 Measurement Release 1.1.16 Build 424, MultiVu Release 2.3.4.19,APPNAME
INFO,Linear Motor Servo Controller,MOTOR_MODULE_NAME
INFO,3101-100 N2,MOTOR_HW_VERSION
INFO,,MOTOR_SERIAL_NUMBER
INFO,01.04.28,MOTOR_SOFTWARE_VERSION
INFO,Quantum Design Squid Module,SQUID_MODULE_NAME
INFO,3101-501 B0,SQUID_HW_VERSION
INFO,SQM327,SQUID_SERIAL_NUMBER
INFO,01.03.04,SQUID_SOFTWARE_VERSION
INFO,Quantum Design VSM Oven,OVEN_MODULE_NAME
INFO,3101-201 A3,OVEN_HW_VERSION
INFO,OVB365,OVEN_SERIAL_NUMBER
INFO,01.07.07,OVEN_SOFTWARE_VERSION
INFO,SQUID AC,AC_MODULE_NAME
INFO,3101-401 G0,AC_HW_VERSION
INFO,SAC220,AC_SERIAL_NUMBER
INFO,SQUID AC 00.95.07,AC_SOFTWARE_VERSION
INFO,TCI344,COIL_SERIAL_NUMBER
INFO,0,MOMENT_UNITS
INFO,DA-4A,SAMPLE_MATERIAL
INFO,DA-4A,SAMPLE_COMMENT
INFO,,SAMPLE_MASS
INFO,,SAMPLE_VOLUME
INFO,,SAMPLE_MOLECULAR_WEIGHT
INFO,,SAMPLE_SIZE
INFO,,SAMPLE_SHAPE
INFO,Straw,SAMPLE_HOLDER
INFO,Standard,SAMPLE_HOLDER_DETAIL
INFO,63.74,SAMPLE_OFFSET
DATATYPE,COMMENT,1
DATATYPE,TIME,2
STARTUPAXIS,X,2
STARTUPAXIS,Y1,5
FIELDGROUP, VSM,2,3,4,5,6,8,9,10,11,14,15
FIELDGROUP, DC, 2,3,4,14,56,57,58,59,60,61,62,63,64,65,66,67,68,69
FIELDGROUP, AC, 2,3,4,11,16,17,18,19,20,21,22,23,24,25,26,27,28,29,30
STARTUPGROUP, All
[Data]
Comment,Time Stamp (sec),Temperature (K),Magnetic Field (Oe),Moment (emu),M. Std. Err. (emu),Transport Action,Averaging Time (sec),Frequency (Hz),Peak Amplitude (mm),Center Position (mm),Lockin Signal' (V),Lockin Signal (V),Range,M. Quad. Signal (emu),AC Moment (emu),AC M. Std Err. (emu),AC Phase (deg),AC Phase Std. Err. (deg),AC Susceptibility (emu/Oe),AC Suscept. Std Err. (emu/Oe),AC X' (emu/Oe),AC X' Std Err. (emu/Oe),AC X'' (emu/Oe),AC X'' Std Err. (emu/Oe),AC Drive (Oe),AC Frequency (Hz),AC Averaging Time (sec),AC Cycles,AC Range,AC Measure Type,AC Signal' (V),AC Signal'' (V),AC Trim Coil Ratio,AC Trim Coil Phase,Min. Temperature (K),Max. Temperature (K),Min. Field (Oe),Max. Field (Oe),Mass (grams),Motor Lag (deg),Pressure (Torr),Measure Count,Measurement Number,SQUID Status (code),Motor Status (code),Measure Status (code),Motor Current (amps),Motor Temp. (C),Temp. Status (code),Field Status (code),Chamber Status (code),Chamber Temp (K),Redirection State,Average Temp (K),Rotation Angle (deg),Rotator state,DC Moment Fixed Ctr (emu),DC Moment Err Fixed Ctr (emu),DC Moment Free Ctr (emu),DC Moment Err Free Ctr (emu),DC Fixed Fit,DC Free Fit,DC Calculated Center (mm),DC Calculated Center Err (mm),DC Scan Length (mm),DC Scan Time (s),DC Number of Points,DC Squid Drift,DC Min V (V),DC Max V (V),DC Scans per Measure,Map 01,Map 02,Map 03,Map 04,Map 05,Map 06,Map 07,Map 08,Map 09,Map 10,Map 11,Map 12,Map 13,Map 14,Map 15,Map 16
,3863175991.14409,10.0001840591431,25.3218441009521,0.00169061308372495,1.13023725927948E-7,1,5,12.9061126708984,4.98621482813881,37.1900014579296,2.19896455456446,0.322763154516059,10,-2.17365227528459E-7,,,,,,,,,,,,,,,,,,,,,10.0001840591431,10.0001840591431,25.3218441009521,25.3218441009521,50.0957442402841,5.37476136906372,5.06465196609497,65,1,0,0,1,0.26763916015625,30.3030319213867,1,1,1,10.0001840591431,0,10.0001840591431,,,,,,,,,,,,,,,,,,,,,,,,,,,,,,,,,
,3863176079.79754,23.031982421875,25.3218441009521,0.00136745863305414,5.19499450222977E-7,1,5,12.9061126708984,4.98605487744835,37.2000001370907,1.77865035631647,0.26044455599205,10,-6.46252032989032E-7,,,,,,,,,,,,,,,,,,,,,23.031982421875,23.031982421875,25.3218441009521,25.3218441009521,50.2149425894668,5.37622558810272,5.8617525100708,65,1,0,0,1,0.270538330078125,30.7917900085449,2,1,1,23.031982421875,0,23.031982421875,,,,,,,,,,,,,,,,,,,,,,,,,,,,,,,,,
,3863176169.51486,37.0093002319336,25.3218441009521,0.00118640385823075,2.42155123914394E-7,1,5,12.9061126708984,4.98644311533735,37.2000001370907,1.54337225250296,0.225640762068354,10,-8.2593716422045E-7,,,,,,,,,,,,,,,,,,,,,37.0093002319336,37.0093002319336,25.3218441009521,25.3218441009521,50.1160665817842,5.37509172820403,6.2506422996521,65,1,0,0,1,0.269317626953125,31.2805480957031,2,1,1,37.0093002319336,0,37.0093002319336,,,,,,,,,,,,,,,,,,,,,,,,,,,,,,,,,
,3863176259.1658,51.0095634460449,25.3218441009521,0.00107231293704986,2.32956121237433E-7,1,5,12.9061126708984,4.98627322445954,37.2099988162518,1.39492424032902,0.203676005988743,10,-9.43467656866459E-7,,,,,,,,,,,,,,,,,,,,,51.0095634460449,51.0095634460449,25.3218441009521,25.3218441009521,50.0851922552745,5.37575144983041,6.45416927337646,65,1,0,0,1,0.278472900390625,31.2805480957031,2,1,1,51.0095634460449,0,51.0095634460449,,,,,,,,,,,,,,,,,,,,,,,,,,,,,,,,,
,3863176347.57069,65.0144958496094,25.3218441009521,0.00095495979227462,1.94438033838135E-7,1,5,12.9061126708984,4.98579861053718,37.2299998998642,1.24211673783407,0.181238764785834,10,-9.34671159465282E-7,,,,,,,,,,,,,,,,,,,,,65.0144958496094,65.0144958496094,25.3218441009521,25.3218441009521,50.0687780563707,5.37727431931533,6.62713241577148,65,1,0,0,1,0.279312133789062,31.2805480957031,2,1,1,65.0144958496094,0,65.0144958496094,,,,,,,,,,,,,,,,,,,,,,,,,,,,,,,,,
,3863176435.35567,79.128360748291,25.3218441009521,0.000851204552879877,2.00276536842033E-7,1,5,12.9061126708984,4.98565608545734,37.2500009834766,1.10696399342516,0.162587763398295,1,-2.8129329028682E-8,,,,,,,,,,,,,,,,,,,,,79.0164260864258,79.2402954101562,25.3218441009521,25.3218441009521,50.1504582366303,5.37870200399636,6.74681806564331,63,1,64,0,0,0.26947021484375,30.7917900085449,2,1,1,79.2402954101562,0,79.128360748291,,,,,,,,,,,,,,,,,,,,,,,,,,,,,,,,,
,3863176535.07261,95.2878684997559,25.3218441009521,0.000712127763193474,3.07510886420598E-7,1,5,12.9061126708984,4.98513499269314,37.2800007462502,0.925980237694059,0.135886720993772,1,-1.12861072908802E-7,,,,,,,,,,,,,,,,,,,,,95.0375061035156,95.5382308959961,25.3218441009521,25.3218441009521,50.1594469646015,5.38016350253649,6.82183218002319,63,1,64,0,0,0.269546508789062,31.2805480957031,2,1,1,95.5382308959961,0,95.2878684997559,,,,,,,,,,,,,,,,,,,,,,,,,,,,,,,,,
,3863176618.01228,109.052742004395,25.3218441009521,0.000518623688674717,4.43007882649429E-7,1,5,12.9061126708984,4.98475696051431,37.3100005090237,0.674320209037871,0.098779992913893,1,-2.14600602689703E-7,,,,,,,,,,,,,,,,,,,,,109.052742004395,109.052742004395,25.3218441009521,25.3218441009521,50.1297450808707,5.3821915756189,6.88228559494019,65,1,0,0,1,0.274124145507813,31.2805480957031,2,1,1,109.052742004395,0,109.052742004395,,,,,,,,,,,,,,,,,,,,,,,,,,,,,,,,,
,3863176702.94382,123.04704284668,25.3218441009521,0.000377275791548064,9.86592411844373E-8,1,5,12.9061126708984,4.98486090017561,37.3400002717972,0.490577052028142,0.0716929967854415,1,-2.84698083637934E-7,,,,,,,,,,,,,,,,,,,,,123.04704284668,123.04704284668,25.3218441009521,25.3218441009521,50.2407363306015,5.38248467091746,6.9322829246521,65,1,0,0,1,0.27099609375,31.2805480957031,2,1,1,123.04704284668,0,123.04704284668,,,,,,,,,,,,,,,,,,,,,,,,,,,,,,,,,
,3863176787.85614,137.029052734375,25.3218441009521,0.000360161621093695,2.06541584968847E-8,1,5,12.9061126708984,4.98478854746811,37.3799987137318,0.468325063123442,0.0683621177977517,1,-3.31246514614811E-7,,,,,,,,,,,,,,,,,,,,,137.029052734375,137.029052734375,25.3218441009521,25.3218441009521,50.1391246231015,5.38312351495859,6.96347761154175,65,1,0,0,1,0.27099609375,31.2805480957031,2,1,1,137.029052734375,0,137.029052734375,,,,,,,,,,,,,,,,,,,,,,,,,,,,,,,,,
,3863176872.7911,151.092132568359,25.3218441009521,0.000354608694322776,3.03070268196023E-8,1,5,12.9061126708984,4.9846721023772,37.4299995601177,0.461074767990609,0.067405200676677,1,-2.49768270587281E-7,,,,,,,,,,,,,,,,,,,,,151.092132568359,151.092132568359,25.3218441009521,25.3218441009521,50.1027788969572,5.38340825906645,6.99952459335327,64,1,64,0,0,0.273361206054687,30.7917900085449,2,1,1,151.092132568359,0,151.092132568359,,,,,,,,,,,,,,,,,,,,,,,,,,,,,,,,,
,3863176957.6444,165.176651000977,25.3218441009521,0.000353536298368614,2.62513600875503E-8,1,5,12.9061126708984,4.98458184362208,37.4800004065037,0.459676974255678,0.0671433803544966,1,-2.92292483923178E-7,,,,,,,,,,,,,,,,,,,,,165.176651000977,165.176651000977,25.3218441009521,25.3218441009521,50.2235405031784,5.38344030753289,7.03093147277832,65,1,0,0,1,0.265884399414062,31.2805480957031,2,1,1,165.176651000977,0,165.176651000977,,,,,,,,,,,,,,,,,,,,,,,,,,,,,,,,,
,3863177041.41045,179.08544921875,25.3218441009521,0.000353517449383326,2.36902161088786E-8,1,5,12.9061126708984,4.98461074332458,37.5300012528896,0.459660344756467,0.0671122031844949,1,-3.13924993880501E-7,,,,,,,,,,,,,,,,,,,,,179.08544921875,179.08544921875,25.3218441009521,25.3218441009521,50.132480780688,5.38462842939719,7.05330276489258,65,1,0,0,1,0.269393920898438,31.2805480957031,2,1,1,179.08544921875,0,179.08544921875,,,,,,,,,,,,,,,,,,,,,,,,,,,,,,,,,
,3863177125.18744,193.018417358398,25.3218441009521,0.000353544439837222,2.62937731471225E-8,1,5,12.9061126708984,4.98478355072291,37.5900007784367,0.459730172060474,0.0670365622527697,1,-3.7858307732225E-7,,,,,,,,,,,,,,,,,,,,,193.018417358398,193.018417358398,25.3218441009521,25.3218441009521,50.1102043678899,5.38385766639312,7.09661054611206,64,1,64,0,0,0.274200439453125,31.7693061828613,2,1,1,193.018417358398,0,193.018417358398,,,,,,,,,,,,,,,,,,,,,,,,,,,,,,,,,
,3863177210.01373,207.02799987793,25.3218441009521,0.00035323683664834,2.49293291855E-8,1,5,12.9061126708984,4.98481894638656,37.6400016248226,0.459333537398612,0.0669872479000591,1,-3.71836704031725E-7,,,,,,,,,,,,,,,,,,,,,207.02799987793,207.02799987793,25.3218441009521,25.3218441009521,50.1148941390053,5.3823914464824,7.1425633430481,64,1,64,0,0,0.27130126953125,31.2805480957031,2,1,1,207.02799987793,0,207.02799987793,,,,,,,,,,,,,,,,,,,,,,,,,,,,,,,,,
,3863177294.80719,221.180419921875,25.3218441009521,0.00035197914062505,3.00954958537935E-8,1,5,12.9061126708984,4.98491272154781,37.7000011503696,0.457704579510747,0.0667886277951025,1,-3.41191360948031E-7,,,,,,,,,,,,,,,,,,,,,221.180419921875,221.180419921875,25.3218441009521,25.3218441009521,50.1098135536303,5.38272994807332,7.2043285369873,63,1,64,0,0,0.269775390625,30.7917900085449,2,1,1,221.180419921875,0,221.180419921875,,,,,,,,,,,,,,,,,,,,,,,,,,,,,,,,,
,3863177378.76154,235.008224487305,25.3218441009521,0.000350573369947284,1.29064542057553E-8,1,5,12.9061126708984,4.98537220907246,37.7699993550777,0.455938065287765,0.0665135551126495,1,-3.52854605545591E-7,,,,,,,,,,,,,,,,,,,,,235.008224487305,235.008224487305,25.3218441009521,25.3218441009521,50.2618403006207,5.38023873208068,7.2640061378479,65,1,0,0,1,0.269699096679687,31.2805480957031,2,1,1,235.008224487305,0,235.008224487305,,,,,,,,,,,,,,,,,,,,,,,,,,,,,,,,,
,3863177463.01249,249.012725830078,25.3218441009521,0.000348743353988209,2.21380596342248E-8,1,5,12.9061126708984,4.98576988389473,37.8400012850761,0.453609143813286,0.0661717957700333,1,-3.5252549628313E-7,,,,,,,,,,,,,,,,,,,,,249.012725830078,249.012725830078,25.3218441009521,25.3218441009521,50.147722536813,5.3789125540259,7.36695289611816,64,1,64,0,0,0.27130126953125,31.2805480957031,2,1,1,249.012725830078,0,249.012725830078,,,,,,,,,,,,,,,,,,,,,,,,,,,,,,,,,
,3863177547.54121,263.0478515625,25.3218441009521,0.000346855211482057,3.00524213079372E-8,1,5,12.9061126708984,4.98589001717901,37.9199981689453,0.451158332905837,0.0658850445408926,1,-2.97343596764209E-7,,,,,,,,,,,,,,,,,,,,,263.0478515625,263.0478515625,25.3218441009521,25.3218441009521,50.2004824618611,5.37697318104038,7.5580267906189,64,1,64,0,0,0.269241333007813,31.7693061828613,2,1,1,263.0478515625,0,263.0478515625,,,,,,,,,,,,,,,,,,,,,,,,,,,,,,,,,
,3863177632.55976,277.11865234375,25.3218441009521,0.000344524580187947,3.6703056935919E-8,1,5,12.9061126708984,4.98636609950696,37.9999987781048,0.448186686290766,0.0654529115357297,1,-2.93966547432686E-7,,,,,,,,,,,,,,,,,,,,,277.11865234375,277.11865234375,25.3218441009521,25.3218441009521,50.2282302742938,5.37679915350694,7.45725965499878,64,1,64,0,0,0.269088745117187,31.2805480957031,2,1,1,277.11865234375,0,277.11865234375,,,,,,,,,,,,,,,,,,,,,,,,,,,,,,,,,
,3863177716.15843,291.069427490234,25.3218441009521,0.000342787245898826,3.18050753820439E-8,1,5,12.9061126708984,4.98646086581159,38.0799993872642,0.445935675955153,0.0651439245053621,1,-2.77620240179734E-7,,,,,,,,,,,,,,,,,,,,,291.069427490234,291.069427490234,25.3218441009521,25.3218441009521,50.1750795349861,5.37673278267321,7.42019271850586,63,1,64,0,0,0.268783569335938,30.3030319213867,2,1,1,291.069427490234,0,291.069427490234,,,,,,,,,,,,,,,,,,,,,,,,,,,,,,,,,
,3863179331.7696,13.1397771835327,25.4471988677979,0.00148509912773378,4.81152128516077E-7,1,5,12.9061126708984,4.99488209583802,37.1900014579296,1.93647154029853,0.283511954798692,10,-7.33436288043259E-7,,,,,,,,,,,,,,,,,,,,,13.1397771835327,13.1397771835327,25.4471988677979,25.4471988677979,50.1383429945822,5.38244411783904,5.30698156356812,65,1,0,0,1,0.270233154296875,30.7917900085449,6,1,1,13.1397771835327,0,13.1397771835327,,,,,,,,,,,,,,,,,,,,,,,,,,,,,,,,,
,3863179421.81836,27.1560726165771,25.4471988677979,0.00127170908257889,1.90948864930931E-7,1,5,12.9061126708984,4.99466252223075,37.1900014579296,1.65819383674095,0.242276089525185,10,-9.99134667788318E-7,,,,,,,,,,,,,,,,,,,,,27.1560726165771,27.1560726165771,25.4471988677979,25.4471988677979,50.1125492534476,5.38375899200107,6.00984764099121,65,1,0,0,1,0.270309448242187,31.2805480957031,2,1,1,27.1560726165771,0,27.1560726165771,,,,,,,,,,,,,,,,,,,,,,,,,,,,,,,,,
,3863179511.93411,41.174129486084,25.4471988677979,0.00118740427248928,1.92207886901795E-7,1,5,12.9061126708984,4.99567930860854,37.2000001370907,1.54875932068592,0.225942965433935,10,-1.19099801348975E-6,,,,,,,,,,,,,,,,,,,,,41.174129486084,41.174129486084,25.4471988677979,25.4471988677979,50.1062962252938,5.38002433100616,6.32472658157349,65,1,0,0,1,0.289077758789063,30.3030319213867,2,1,1,41.174129486084,0,41.174129486084,,,,,,,,,,,,,,,,,,,,,,,,,,,,,,,,,
,3863179599.67447,55.0421180725098,25.4471988677979,0.00104058630971289,3.46409811086022E-7,1,5,12.9061126708984,4.99512272438653,37.2200012207031,1.35707544697251,0.197796502061663,10,-1.18067636515421E-6,,,,,,,,,,,,,,,,,,,,,55.0421180725098,55.0421180725098,25.4471988677979,25.4471988677979,50.1524123079284,5.38176826076021,6.53198719024658,65,1,0,0,1,0.27923583984375,31.2805480957031,2,1,1,55.0421180725098,0,55.0421180725098,,,,,,,,,,,,,,,,,,,,,,,,,,,,,,,,,
,3863179692.48184,69.8008422851562,25.4471988677979,0.000826375123529086,3.82428976111233E-7,1,5,12.9061126708984,4.99457438524945,37.2299998998642,1.07738620945703,0.15815005102499,1,-9.7444255918141E-8,,,,,,,,,,,,,,,,,,,,,69.425178527832,70.1765060424805,25.4471988677979,25.4471988677979,50.112158439188,5.38399094871684,6.67813110351562,65,1,0,0,1,0.270309448242187,28.8367557525635,2,1,1,70.1765060424805,0,69.8008422851562,,,,,,,,,,,,,,,,,,,,,,,,,,,,,,,,,
,3863179794.07165,86.0528793334961,25.4471988677979,0.000674253494529921,2.118708714575E-7,1,5,12.9061126708984,4.99404446457426,37.2599996626377,0.878946875211482,0.128882326870776,1,-1.83676002049859E-7,,,,,,,,,,,,,,,,,,,,,86.0528793334961,86.0528793334961,25.4471988677979,25.4471988677979,50.0593985141399,5.385365505833,6.78087091445923,65,1,0,0,1,0.270614624023438,32.2580642700195,2,1,1,86.0528793334961,0,86.0528793334961,,,,,,,,,,,,,,,,,,,,,,,,,,,,,,,,,
,3863179878.77354,100.011871337891,25.4471988677979,0.000562031568720927,2.50450908185823E-7,1,5,12.9061126708984,4.99393900966094,37.2899994254112,0.732635535397747,0.107419989663796,1,-1.59349559344335E-7,,,,,,,,,,,,,,,,,,,,,100.011871337891,100.011871337891,25.4471988677979,25.4471988677979,50.1207563528995,5.38547166330507,6.83640909194946,63,1,64,0,0,0.273361206054687,30.3030319213867,2,1,1,100.011871337891,0,100.011871337891,,,,,,,,,,,,,,,,,,,,,,,,,,,,,,,,,
,3863179963.62843,114.015449523926,25.4471988677979,0.000417429676468852,2.54995974129051E-7,1,5,12.9061126708984,4.99364944398269,37.3199991881847,0.544102266778629,0.0797311828698824,1,-1.52757153040232E-7,,,,,,,,,,,,,,,,,,,,,114.015449523926,114.015449523926,25.4471988677979,25.4471988677979,50.1547571934861,5.38683654807584,6.89863204956055,65,1,0,0,1,0.269775390625,30.7917900085449,2,1,1,114.015449523926,0,114.015449523926,,,,,,,,,,,,,,,,,,,,,,,,,,,,,,,,,
,3863180048.18274,128.017593383789,25.4471988677979,0.000356333573897322,2.32086340122535E-8,1,5,12.9061126708984,4.99375906569544,37.3600013554096,0.464483394125389,0.0680427562438528,1,-1.46400693584164E-7,,,,,,,,,,,,,,,,,,,,,128.017593383789,128.017593383789,25.4471988677979,25.4471988677979,50.1766427920245,5.38729563625656,6.93147945404053,65,1,0,0,1,0.2716064453125,31.2805480957031,2,1,1,128.017593383789,0,128.017593383789,,,,,,,,,,,,,,,,,,,,,,,,,,,,,,,,,
,3863180127.16944,141.113922119141,25.4471988677979,0.000353769934803028,2.00241755964293E-8,1,5,12.9061126708984,4.99395551723467,37.3900011181831,0.461170409962328,0.0675344975085719,1,-1.6257205058982E-7,,,,,,,,,,,,,,,,,,,,,141.008804321289,141.219039916992,25.4471988677979,25.4471988677979,50.1965743192649,5.38631481065811,6.96716737747192,65,1,0,0,1,0.271987915039062,30.7917900085449,2,1,1,141.219039916992,0,141.113922119141,,,,,,,,,,,,,,,,,,,,,,,,,,,,,,,,,
,3863180211.55316,155.048278808594,25.4471988677979,0.000352852824482745,2.35451113263179E-8,1,5,12.9061126708984,4.99417263097433,37.4399982392788,0.459999565980846,0.0673863400495554,1,-1.44651140477565E-7,,,,,,,,,,,,,,,,,,,,,155.048278808594,155.048278808594,25.4471988677979,25.4471988677979,50.1254461240149,5.38563350560671,7.0087308883667,63,1,64,0,0,0.271530151367187,30.7917900085449,2,1,1,155.048278808594,0,155.048278808594,,,,,,,,,,,,,,,,,,,,,,,,,,,,,,,,,
,3863180295.52128,169.002548217773,25.4471988677979,0.000353143307351324,2.94770745089852E-8,1,5,12.9061126708984,4.99402066348661,37.4899990856647,0.460354219178404,0.0674688442914945,1,-1.21827275544374E-7,,,,,,,,,,,,,,,,,,,,,169.002548217773,169.002548217773,25.4471988677979,25.4471988677979,50.1719530209092,5.38637415762652,7.02990674972534,63,1,64,0,0,0.271682739257813,31.2805480957031,2,1,1,169.002548217773,0,169.002548217773,,,,,,,,,,,,,,,,,,,,,,,,,,,,,,,,,
,3863180380.49977,183.019866943359,25.4471988677979,0.000353865298184377,3.00122923408518E-8,1,5,12.9061126708984,4.9941374676889,37.5399999320507,0.461316776090439,0.0675664738303416,1,-1.54698970120778E-7,,,,,,,,,,,,,,,,,,,,,183.019866943359,183.019866943359,25.4471988677979,25.4471988677979,50.1911029196303,5.38648339805147,7.0664963722229,65,1,0,0,1,0.270767211914062,30.7917900085449,2,1,1,183.019866943359,0,183.019866943359,,,,,,,,,,,,,,,,,,,,,,,,,,,,,,,,,
,3863180464.64082,197.006790161133,25.4471988677979,0.000354166849019785,3.2460160980784E-8,1,5,12.9061126708984,4.99411841848172,37.5999994575977,0.461712392249482,0.0675898689376626,1,-1.80775775407751E-7,,,,,,,,,,,,,,,,,,,,,197.006790161133,197.006790161133,25.4471988677979,25.4471988677979,50.1742979064668,5.38603041731179,7.09545660018921,64,1,64,0,0,0.270004272460938,31.2805480957031,2,1,1,197.006790161133,0,197.006790161133,,,,,,,,,,,,,,,,,,,,,,,,,,,,,,,,,
,3863180549.517,211.042434692383,25.4471988677979,0.00035385895017183,1.74723291898567E-8,1,5,12.9061126708984,4.99417862263947,37.6599989831448,0.461315063933231,0.0675576503529687,1,-1.61133941974115E-7,,,,,,,,,,,,,,,,,,,,,211.042434692383,211.042434692383,25.4471988677979,25.4471988677979,50.1496766081111,5.38671224463043,7.14606809616089,64,1,64,0,0,0.272293090820313,31.2805480957031,2,1,1,211.042434692383,0,211.042434692383,,,,,,,,,,,,,,,,,,,,,,,,,,,,,,,,,
,3863180633.89595,225.011810302734,25.4471988677979,0.00035297714969279,2.57569761659224E-8,1,5,12.9061126708984,4.9943507191277,37.7199985086918,0.460195249511345,0.0673413206978021,1,-2.00033930522524E-7,,,,,,,,,,,,,,,,,,,,,225.011810302734,225.011810302734,25.4471988677979,25.4471988677979,50.1914937338899,5.38539041605378,7.2248387336731,64,1,64,0,0,0.270843505859375,31.2805480957031,2,1,1,225.011810302734,0,225.011810302734,,,,,,,,,,,,,,,,,,,,,,,,,,,,,,,,,
,3863180718.33666,239.099517822266,25.4471988677979,0.000351730042285007,3.06621051026671E-8,1,5,12.9061126708984,4.99485245760221,37.7900004386902,0.458640967865656,0.0670648931781558,1,-2.36107589832767E-7,,,,,,,,,,,,,,,,,,,,,239.099517822266,239.099517822266,25.4471988677979,25.4471988677979,50.203608975938,5.38478295090159,7.26953792572022,64,1,64,0,0,0.270156860351562,31.2805480957031,2,1,1,239.099517822266,0,239.099517822266,,,,,,,,,,,,,,,,,,,,,,,,,,,,,,,,,
,3863180802.13773,253.012634277344,25.4471988677979,0.000350381685144313,3.33921589084973E-8,1,5,12.9061126708984,4.9951877859477,37.8700010478497,0.456928452967524,0.0667958334230335,1,-2.49201977170727E-7,,,,,,,,,,,,,,,,,,,,,253.012634277344,253.012634277344,25.4471988677979,25.4471988677979,50.1723438351688,5.38333334476859,7.39646530151367,64,1,64,0,0,0.26947021484375,31.7693061828613,2,1,1,253.012634277344,0,253.012634277344,,,,,,,,,,,,,,,,,,,,,,,,,,,,,,,,,
,3863180886.90577,267.027099609375,25.4471988677979,0.000348683385661946,2.7131767832162E-8,1,5,12.9061126708984,4.9954957421862,37.9399992525578,0.45477372435874,0.0663369018720599,1,-3.56054256616284E-7,,,,,,,,,,,,,,,,,,,,,267.027099609375,267.027099609375,25.4471988677979,25.4471988677979,50.1797693061015,5.38193308286876,7.53228092193603,64,1,64,0,0,0.279464721679687,30.7917900085449,2,1,1,267.027099609375,0,267.027099609375,,,,,,,,,,,,,,,,,,,,,,,,,,,,,,,,,
,3863180971.49388,281.129638671875,25.4471988677979,0.000347005984328981,3.35938712479977E-8,1,5,12.9061126708984,4.99602626120415,38.0199998617172,0.452633065810229,0.066165573582256,1,-2.4855826239388E-7,,,,,,,,,,,,,,,,,,,,,281.129638671875,281.129638671875,25.4471988677979,25.4471988677979,50.1852407057361,5.37923147859393,7.43360233306885,63,1,64,0,0,0.277252197265625,31.2805480957031,2,1,1,281.129638671875,0,281.129638671875,,,,,,,,,,,,,,,,,,,,,,,,,,,,,,,,,
,3863181055.70457,295.057434082031,25.4471988677979,0.000345265448104957,3.33263531124114E-8,1,5,12.9061126708984,4.99607943315587,38.1099991500378,0.450363828147317,0.065872854504785,1,-2.18041239839091E-7,,,,,,,,,,,,,,,,,,,,,295.057434082031,295.057434082031,25.4471988677979,25.4471988677979,50.1047329682553,5.37876588926175,7.400306224823,64,1,64,0,0,0.278778076171875,31.7693061828613,2,1,1,295.057434082031,0,295.057434082031,,,,,,,,,,,,,,,,,,,,,,,,,,,,,,,,,
,3863181694.08636,286.482574462891,25.3719882965088,0.00105474980353991,1.1211714748137E-7,1,5,12.9061126708984,4.99591879483005,38.0599983036518,1.37567377984748,0.201760397049212,1,-2.56046051658734E-7,,,,,,,,,,,,,,,,,,,,,286.482574462891,286.482574462891,25.3719882965088,25.3719882965088,50.1918845481495,5.37938426467913,7.99611186981201,65,1,0,0,1,0.277328491210938,30.7917900085449,2,1,1,286.427612304687,0,286.482574462891,,,,,,,,,,,,,,,,,,,,,,,,,,,,,,,,,
,3863181822.92687,263.596054077148,25.3719882965088,0.00103011175422964,9.34054703738785E-8,1,5,12.9061126708984,4.99562447403418,37.9399992525578,1.34339544537582,0.197254611473378,1,-7.87326857180866E-8,,,,,,,,,,,,,,,,,,,,,263.282440185547,263.90966796875,25.3719882965088,25.3719882965088,50.2356557452265,5.38063733621674,7.83909368515015,65,1,0,0,1,0.277481079101562,31.2805480957031,2,1,1,263.282440185547,0,263.596054077148,,,,,,,,,,,,,,,,,,,,,,,,,,,,,,,,,
,3863181999.08841,234.209594726562,25.3719882965088,0.000990413591722071,6.23444319923475E-8,1,5,12.9061126708984,4.99509901969014,37.8100015223026,1.29145561652024,0.189474964836929,1,-1.90688801206607E-7,,,,,,,,,,,,,,,,,,,,,233.878616333008,234.540573120117,25.3719882965088,25.3719882965088,50.1825050059188,5.38348869384087,7.71377754211426,65,1,0,0,1,0.279693603515625,31.2805480957031,2,1,1,233.878616333008,0,234.209594726562,,,,,,,,,,,,,,,,,,,,,,,,,,,,,,,,,
,3863182129.71299,212.15104675293,25.3719882965088,0.000951599727395986,8.97461045576797E-8,1,5,12.9061126708984,4.99461012909739,37.7399995923042,1.24065694439264,0.18213915194381,1,-9.53095797013942E-8,,,,,,,,,,,,,,,,,,,,,211.784484863281,212.517608642578,25.3719882965088,25.3719882965088,50.1692173210919,5.3846105890964,7.64630794525146,65,1,0,0,1,0.269699096679687,31.2805480957031,2,1,1,211.784484863281,0,212.15104675293,,,,,,,,,,,,,,,,,,,,,,,,,,,,,,,,,
,3863182266.16162,189.521965026855,25.3719882965088,0.00090320044948455,1.09974847829541E-7,1,5,12.9061126708984,4.99448195280517,37.6500003039837,1.17752543307044,0.172788389085327,1,-1.52416695669502E-7,,,,,,,,,,,,,,,,,,,,,189.165100097656,189.878829956055,25.3719882965088,25.3719882965088,50.168044878313,5.38632300013768,7.5798225402832,63,1,64,0,0,0.271682739257813,31.2805480957031,2,1,1,189.165100097656,0,189.521965026855,,,,,,,,,,,,,,,,,,,,,,,,,,,,,,,,,
,3863182402.30868,166.88591003418,25.3719882965088,0.000835279803653385,1.04492363067242E-7,1,5,12.9061126708984,4.9937478337615,37.5699996948242,1.08873516624519,0.159870340575884,1,-5.76611837189344E-8,,,,,,,,,,,,,,,,,,,,,166.600433349609,167.17138671875,25.3719882965088,25.3719882965088,50.1559296362649,5.38779377699307,7.51085710525513,63,1,64,0,0,0.271453857421875,30.7917900085449,2,1,1,166.600433349609,0,166.88591003418,,,,,,,,,,,,,,,,,,,,,,,,,,,,,,,,,
,3863182481.22787,153.804901123047,25.3719882965088,0.00078329706744523,1.36986858507505E-7,1,5,12.9061126708984,4.99388383641732,37.5300012528896,1.02101849824911,0.149922651733597,1,-5.71848818027802E-8,,,,,,,,,,,,,,,,,,,,,153.804901123047,153.804901123047,25.3719882965088,25.3719882965088,50.142641951438,5.38586825716572,7.48282480239868,65,1,0,0,1,0.272064208984375,31.2805480957031,2,1,1,153.804901123047,0,153.804901123047,,,,,,,,,,,,,,,,,,,,,,,,,,,,,,,,,
,3863182565.31665,139.925354003906,25.3719882965088,0.000707113513255709,2.06594584019663E-7,1,5,12.9061126708984,4.99386222697836,37.4899990856647,0.921726465487441,0.135218321984588,1,-1.45231790080736E-7,,,,,,,,,,,,,,,,,,,,,139.925354003906,139.925354003906,25.3719882965088,25.3719882965088,50.1516306794092,5.38603622234189,7.43975639343262,63,1,64,0,0,0.272293090820313,31.7693061828613,2,1,1,139.925354003906,0,139.925354003906,,,,,,,,,,,,,,,,,,,,,,,,,,,,,,,,,
,3863182648.15408,125.996315002441,25.3719882965088,0.000582806225587812,3.73584610148959E-7,1,5,12.9061126708984,4.99412144226335,37.4500006437302,0.759754072269464,0.111404196371758,1,-1.59193734687352E-7,,,,,,,,,,,,,,,,,,,,,125.996315002441,125.996315002441,25.3719882965088,25.3719882965088,50.1277910095726,5.38494122911993,7.40856075286865,64,1,64,0,0,0.270614624023438,31.2805480957031,2,1,1,125.996315002441,0,125.996315002441,,,,,,,,,,,,,,,,,,,,,,,,,,,,,,,,,
,3863182732.89304,111.912635803223,25.3719882965088,0.000390725327657298,2.93000194415605E-7,1,5,12.9061126708984,4.99408438514816,37.4099984765053,0.50935886689746,0.0746232601666673,1,-1.55544537943329E-7,,,,,,,,,,,,,,,,,,,,,111.912635803223,111.912635803223,25.3719882965088,25.3719882965088,50.1727346494284,5.38561905378671,7.35369491577148,64,1,64,0,0,0.270614624023438,31.2805480957031,2,1,1,111.912635803223,0,111.912635803223,,,,,,,,,,,,,,,,,,,,,,,,,,,,,,,,,
,3863182816.6324,97.9982681274414,25.3719882965088,0.000311350778951002,6.84498335228577E-8,1,5,12.9061126708984,4.99434418075249,37.3700000345707,0.405916133904975,0.0594530405928749,1,-1.3552176434993E-7,,,,,,,,,,,,,,,,,,,,,97.9982681274414,97.9982681274414,25.3719882965088,25.3719882965088,50.223931317438,5.38441979388992,7.31404113769531,63,1,64,0,0,0.271453857421875,31.7693061828613,2,1,1,97.9982681274414,0,97.9982681274414,,,,,,,,,,,,,,,,,,,,,,,,,,,,,,,,,
,3863182900.21118,83.8404693603516,25.3719882965088,0.000280628964272401,3.77666086000247E-8,1,5,12.9061126708984,4.9941331812005,37.3499989509583,0.365843786916868,0.0535687873573727,1,-1.33417150297075E-7,,,,,,,,,,,,,,,,,,,,,83.8404693603516,83.8404693603516,25.3719882965088,25.3719882965088,50.1653091784957,5.38485435409526,7.24668502807617,63,1,64,0,0,0.271377563476562,31.7693061828613,2,1,1,83.8404693603516,0,83.8404693603516,,,,,,,,,,,,,,,,,,,,,,,,,,,,,,,,,
,3863182982.69773,69.9141235351562,25.3719882965088,0.000270133998755414,2.60610473737312E-8,1,5,12.9061126708984,4.99394954487315,37.3100005090237,0.352153410476552,0.0514973354024982,1,-1.78621009006099E-7,,,,,,,,,,,,,,,,,,,,,69.9141235351562,69.9141235351562,25.3719882965088,25.3719882965088,50.2071263042745,5.38494682714384,7.16575336456299,65,1,0,0,1,0.270156860351562,30.7917900085449,2,1,1,69.9141235351562,0,69.9141235351562,,,,,,,,,,,,,,,,,,,,,,,,,,,,,,,,,
,3863183064.92394,55.7897663116455,25.3719882965088,0.000265572518071758,1.94695833849069E-8,1,5,12.9061126708984,4.99413488086933,37.2899994254112,0.346221853163719,0.0506515858767575,1,-1.59342215671616E-7,,,,,,,,,,,,,,,,,,,,,55.7717628479004,55.8077697753906,25.3719882965088,25.3719882965088,50.1739070922072,5.38430337789871,7.05225467681885,65,1,0,0,1,0.270614624023438,32.2580642700195,2,1,1,55.7717628479004,0,55.7897663116455,,,,,,,,,,,,,,,,,,,,,,,,,,,,,,,,,
,3863183145.89134,41.9320945739746,25.3719882965088,0.000264476821081283,1.3272492566083E-8,1,5,12.9061126708984,4.99471944970991,37.2500009834766,0.344848348814042,0.0504621518378453,1,-1.50044640805691E-7,,,,,,,,,,,,,,,,,,,,,41.9320945739746,41.9320945739746,25.3719882965088,25.3719882965088,50.1559296362649,5.38270128930084,6.89253520965576,63,1,64,0,0,0.270233154296875,30.7917900085449,2,1,1,41.9320945739746,0,41.9320945739746,,,,,,,,,,,,,,,,,,,,,,,,,,,,,,,,,
,3863183228.35033,27.9764251708984,25.3719882965088,0.000263489583562657,1.00302150485582E-8,1,5,12.9061126708984,4.99509333766099,37.2299998998642,0.343584639828508,0.0503642755696876,1,-8.41336051712743E-8,,,,,,,,,,,,,,,,,,,,,27.9764251708984,27.9764251708984,25.3719882965088,25.3719882965088,50.2102528183515,5.38133922883596,6.60053253173828,65,1,0,0,1,0.279312133789062,30.7917900085449,2,1,1,27.9764251708984,0,27.9764251708984,,,,,,,,,,,,,,,,,,,,,,,,,,,,,,,,,
,3863183312.25268,13.9864721298218,25.3719882965088,0.000262619773854423,1.23644676356965E-8,1,5,12.9061126708984,4.99434867783556,37.2099988162518,0.342370280926534,0.0502458585975132,1,-3.91095065049186E-8,,,,,,,,,,,,,,,,,,,,,13.9864721298218,13.9864721298218,25.3719882965088,25.3719882965088,50.1946202479669,5.38426760787013,5.8822226524353,65,1,0,0,1,0.271835327148438,31.2805480957031,2,1,1,13.9864721298218,0,13.9864721298218,,,,,,,,,,,,,,,,,,,,,,,,,,,,,,,,,
,3863183558.42682,18.0241451263428,25.3719882965088,0.000263095092150019,1.08128586032184E-8,1,5,12.9061126708984,4.99426838639949,37.2000001370907,0.342984353972106,0.0503210625831579,1,-5.0381319100786E-8,,,,,,,,,,,,,,,,,,,,,18.0241451263428,18.0241451263428,25.3719882965088,25.3719882965088,50.1422511371784,5.38434686976249,5.63295316696167,65,1,0,0,1,0.270843505859375,31.2805480957031,2,1,1,18.0241451263428,0,18.0241451263428,,,,,,,,,,,,,,,,,,,,,,,,,,,,,,,,,
,3863183648.7719,32.0379867553711,25.3719882965088,0.000264626593487573,1.0690057686476E-8,1,5,12.9061126708984,4.99513380086283,37.2000001370907,0.345073422984404,0.0505670142232984,1,-9.61289006817548E-8,,,,,,,,,,,,,,,,,,,,,32.0379867553711,32.0379867553711,25.3719882965088,25.3719882965088,50.0805024841591,5.38154238115202,6.14643144607544,65,1,0,0,1,0.279083251953125,30.7917900085449,2,1,1,32.0379867553711,0,32.0379867553711,,,,,,,,,,,,,,,,,,,,,,,,,,,,,,,,,
,3863183738.1626,46.0235176086426,25.3719882965088,0.000266015427733264,8.75186123234328E-9,1,5,12.9061126708984,4.99484899571419,37.2099988162518,0.346869122646943,0.0507440269214264,1,-1.61299760334536E-7,,,,,,,,,,,,,,,,,,,,,46.0235176086426,46.0235176086426,25.3719882965088,25.3719882965088,50.122319609938,5.38337060899582,6.4144287109375,65,1,0,0,1,0.280227661132813,30.3030319213867,2,1,1,46.0235176086426,0,46.0235176086426,,,,,,,,,,,,,,,,,,,,,,,,,,,,,,,,,
,3863183827.53128,60.1279182434082,25.3719882965088,0.000267899061942112,1.04051045016648E-8,1,5,12.9061126708984,4.99414695138261,37.2200012207031,0.349253891666511,0.0511105772025428,1,-1.49165502843387E-7,,,,,,,,,,,,,,,,,,,,,60.1279182434082,60.1279182434082,25.3719882965088,25.3719882965088,50.0492373433899,5.38507299200511,6.59115362167358,65,1,0,0,1,0.27099609375,31.2805480957031,2,1,1,60.1279182434082,0,60.1279182434082,,,,,,,,,,,,,,,,,,,,,,,,,,,,,,,,,
,3863183915.06202,74.0983657836914,25.3719882965088,0.000273324872075303,2.07186685817859E-8,1,5,12.9061126708984,4.9937467982745,37.2399985790253,0.356295116309526,0.0520870832212178,1,-1.9268551258295E-7,,,,,,,,,,,,,,,,,,,,,74.0983657836914,74.0983657836914,25.3719882965088,25.3719882965088,50.1442052084765,5.38696854656513,6.73951053619385,65,1,0,0,1,0.272140502929687,31.2805480957031,2,1,1,74.0983657836914,0,74.0983657836914,,,,,,,,,,,,,,,,,,,,,,,,,,,,,,,,,
,3863184001.22396,88.0081787109375,25.3719882965088,0.000286715248232333,4.10661594762337E-8,1,5,12.9061126708984,4.99340486987091,37.2699983417988,0.373704107988418,0.0547035021067178,1,-1.48505340355409E-7,,,,,,,,,,,,,,,,,,,,,88.0081787109375,88.0081787109375,25.3719882965088,25.3719882965088,50.1539755649668,5.38837238443676,6.84124231338501,65,1,0,0,1,0.272369384765625,31.7693061828613,2,1,1,88.0081787109375,0,88.0081787109375,,,,,,,,,,,,,,,,,,,,,,,,,,,,,,,,,
,3863184086.8637,102.027793884277,25.3719882965088,0.000311840158305509,6.75150561020059E-8,1,5,12.9061126708984,4.99326382408662,37.3000018298626,0.406443145362321,0.0594445982074957,1,-2.00057213344304E-7,,,,,,,,,,,,,,,,,,,,,102.027793884277,102.027793884277,25.3719882965088,25.3719882965088,50.1078594823322,5.38816918768944,6.90691375732422,64,1,64,0,0,0.2728271484375,30.7917900085449,2,1,1,102.027793884277,0,102.027793884277,,,,,,,,,,,,,,,,,,,,,,,,,,,,,,,,,
,3863184170.87868,116.012283325195,25.3719882965088,0.000365399312084362,1.47977333615964E-7,1,5,12.9061126708984,4.99332970638213,37.3300015926361,0.476250344428824,0.0697169726664578,1,-1.87335773447234E-7,,,,,,,,,,,,,,,,,,,,,116.012283325195,116.012283325195,25.3719882965088,25.3719882965088,50.0425935009765,5.38907543993005,6.94636678695679,64,1,64,0,0,0.273056030273438,31.2805480957031,2,1,1,116.012283325195,0,116.012283325195,,,,,,,,,,,,,,,,,,,,,,,,,,,,,,,,,
,3863184256.1434,130.059066772461,25.3719882965088,0.0004444664366721,1.14783140241902E-7,1,5,12.9061126708984,4.99359925175631,37.3600013554096,0.579324420469832,0.084968853150957,1,-1.05331495293481E-7,,,,,,,,,,,,,,,,,,,,,130.059066772461,130.059066772461,25.3719882965088,25.3719882965088,50.0777667843418,5.38813041623658,6.99175214767456,64,1,64,0,0,0.271987915039062,31.2805480957031,2,1,1,130.059066772461,0,130.059066772461,,,,,,,,,,,,,,,,,,,,,,,,,,,,,,,,,
,3863184340.3411,144.025833129883,25.3719882965088,0.00047716265617649,6.31735355157924E-8,1,5,12.9061126708984,4.99328083697044,37.3999997973442,0.621893396761226,0.0911579174901935,1,-1.54000517686528E-7,,,,,,,,,,,,,,,,,,,,,144.025833129883,144.025833129883,25.3719882965088,25.3719882965088,50.1098135536303,5.38866566188458,7.02853012084961,63,1,64,0,0,0.271453857421875,30.7917900085449,2,1,1,144.025833129883,0,144.025833129883,,,,,,,,,,,,,,,,,,,,,,,,,,,,,,,,,
,3863184425.24793,158.094131469727,25.3719882965088,0.000492892986164657,4.11379806484411E-8,1,5,12.9061126708984,4.99305004265477,37.4500006437302,0.642343407922952,0.0942245272821975,1,-1.072295999235E-7,,,,,,,,,,,,,,,,,,,,,158.094131469727,158.094131469727,25.3719882965088,25.3719882965088,50.1449868369957,5.38844007182201,7.05990266799927,64,1,64,0,0,0.27374267578125,30.7917900085449,2,1,1,158.094131469727,0,158.094131469727,,,,,,,,,,,,,,,,,,,,,,,,,,,,,,,,,
,3863184509.99035,172.080589294434,25.3719882965088,0.00050395057525954,2.51312419197502E-8,1,5,12.9061126708984,4.99323252909364,37.5000014901161,0.656788963953859,0.0963329356813202,1,-1.17590911946387E-7,,,,,,,,,,,,,,,,,,,,,172.072860717773,172.088317871094,25.3719882965088,25.3719882965088,50.0719045704476,5.3896058729898,7.10435247421265,63,1,64,0,0,0.272598266601562,31.2805480957031,2,1,1,172.088317871094,0,172.080589294434,,,,,,,,,,,,,,,,,,,,,,,,,,,,,,,,,
,3863184593.43636,186.021194458008,25.3719882965088,0.000511591080900771,2.36550689495024E-8,1,5,12.9061126708984,4.993403273547,37.5499986112118,0.666767629082222,0.0978732461833931,1,-6.17539746808343E-8,,,,,,,,,,,,,,,,,,,,,186.021194458008,186.021194458008,25.3719882965088,25.3719882965088,50.1547571934861,5.38858603835807,7.13368320465088,65,1,0,0,1,0.272674560546875,31.2805480957031,2,1,1,186.021194458008,0,186.021194458008,,,,,,,,,,,,,,,,,,,,,,,,,,,,,,,,,
,3863184678.48906,200.031723022461,25.3719882965088,0.000517697433678471,3.18594078673785E-8,1,5,12.9061126708984,4.99369517154792,37.6100018620491,0.674783335449097,0.0990369761372422,1,-7.21617704759504E-8,,,,,,,,,,,,,,,,,,,,,200.031723022461,200.031723022461,25.3719882965088,25.3719882965088,50.1113768106688,5.38581509078561,7.16021966934204,64,1,64,0,0,0.269622802734375,33.2355842590332,2,1,1,200.031723022461,0,200.031723022461,,,,,,,,,,,,,,,,,,,,,,,,,,,,,,,,,
,3863184762.6242,214.018203735352,25.3719882965088,0.000521011900470664,2.25654224416064E-8,1,5,12.9061126708984,4.99346723930788,37.6700013875961,0.679068185617438,0.0996092712535973,1,-1.15124257285035E-7,,,,,,,,,,,,,,,,,,,,,214.018203735352,214.018203735352,25.3719882965088,25.3719882965088,50.1227104241976,5.38867652241959,7.21049451828003,63,1,64,0,0,0.271759033203125,30.7917900085449,2,1,1,214.018203735352,0,214.018203735352,,,,,,,,,,,,,,,,,,,,,,,,,,,,,,,,,
,3863184847.50274,228.183898925781,25.3719882965088,0.000523016499958303,4.23189271350395E-8,1,5,12.9061126708984,4.99386952597747,37.7399995923042,0.681770401869515,0.0999188835467842,1,-1.80726126883782E-7,,,,,,,,,,,,,,,,,,,,,228.183898925781,228.183898925781,25.3719882965088,25.3719882965088,50.1539755649668,5.38727400334113,7.26872682571411,64,1,64,0,0,0.27069091796875,31.2805480957031,2,1,1,228.183898925781,0,228.183898925781,,,,,,,,,,,,,,,,,,,,,,,,,,,,,,,,,
,3863184932.42504,242.163223266602,25.3719882965088,0.000523225468093312,4.01138105031573E-8,1,5,12.9061126708984,4.99416139447357,37.8100015223026,0.682087732448321,0.100041632809408,1,-1.23544300791687E-7,,,,,,,,,,,,,,,,,,,,,242.163223266602,242.163223266602,25.3719882965088,25.3719882965088,50.1481133510726,5.38589807595444,7.34569692611694,63,1,64,0,0,0.2716064453125,31.7693061828613,2,1,1,242.163223266602,0,242.163223266602,,,,,,,,,,,,,,,,,,,,,,,,,,,,,,,,,
,3863185015.10616,256.002593994141,25.3719882965088,0.00052300838200197,4.07269612724111E-8,1,5,12.9061126708984,4.99467993527594,37.8799997270107,0.681922295260184,0.0998901299813355,1,-2.19027373796515E-7,,,,,,,,,,,,,,,,,,,,,256.002593994141,256.002593994141,25.3719882965088,25.3719882965088,50.1574928933034,5.38412956921397,7.49639797210693,64,1,64,0,0,0.270309448242187,31.7693061828613,2,1,1,256.002593994141,0,256.002593994141,,,,,,,,,,,,,,,,,,,,,,,,,,,,,,,,,
,3863185100.30264,270.048004150391,25.3719882965088,0.000521614331895854,4.3470133437547E-8,1,5,12.9061126708984,4.99492580933782,37.9600003361702,0.680151021086504,0.0996347591562573,1,-2.15372045416246E-7,,,,,,,,,,,,,,,,,,,,,270.048004150391,270.048004150391,25.3719882965088,25.3719882965088,50.1293542666111,5.3839756928756,7.56387090682983,63,1,64,0,0,0.270462036132813,32.7468223571777,2,1,1,270.048004150391,0,270.048004150391,,,,,,,,,,,,,,,,,,,,,,,,,,,,,,,,,
,3863185184.06021,284.0048828125,25.3719882965088,0.000520703570520927,4.56251060163237E-8,1,5,12.9061126708984,4.99523696614834,38.0400009453297,0.679025373410413,0.0994515949674899,1,-2.28711127674789E-7,,,,,,,,,,,,,,,,,,,,,284.0048828125,284.0048828125,25.3719882965088,25.3719882965088,50.1711713923899,5.38360636917232,7.51958799362183,64,1,64,0,0,0.2789306640625,33.7243423461914,2,1,1,284.0048828125,0,284.0048828125,,,,,,,,,,,,,,,,,,,,,,,,,,,,,,,,,
,3863185270.80164,298.018829345703,25.3719882965088,0.000519254086755031,2.7075805175662E-8,1,5,12.9061126708984,4.99530943136658,38.1200015544891,0.6771619500112,0.0990882121581749,1,-2.95985823699497E-7,,,,,,,,,,,,,,,,,,,,,298.018829345703,298.018829345703,25.3719882965088,25.3719882965088,50.1395154373611,5.38280770380186,7.46273946762085,65,1,0,0,1,0.279006958007813,30.7917900085449,6,1,1,298.018829345703,0,298.018829345703,,,,,,,,,,,,,,,,,,,,,,,,,,,,,,,,,
,3863187522.81631,20.0000896453857,25.3719882965088,,,5,,,,37.2000001370907,,,,,2.26118047454015E-5,1.86987568863248E-8,0.37033695903235,0.000415443861946427,7.53727195369669E-6,6.23292202613553E-9,7.53711450773529E-6,5.39083372579813E-9,4.87175663269915E-8,3.12861450560513E-9,2.99999852523716,5.31665134429932,10,53,1,3,0.0794076880034984,0.00502979863881482,0.0019767910707742,264.54931640625,19.9997138977051,20.00048828125,25.3719882965088,25.3719882965088,,,5.74099588394165,,1,,,,,,1,1,1,20.0000667572021,0,20.0001101195812,,,,,,,,,,,,,,,,,,,,,,,,,,,,,,,,,
,3863188929.21257,34.9998874664307,25.3719882965088,,,5,,,,37.2000001370907,,,,,2.16868270905854E-5,4.4388040830941E-8,0.577573406957208,0.00131166677392415,7.22894218631057E-6,1.47960132475886E-8,7.2285748953913E-6,1.13590523039462E-8,7.28705340951344E-8,9.4812414155021E-9,3.00000007354516,1.00057637691498,19.98847910208,20,1,3,0.076309975039323,0.00169656151186054,0.000344913918524981,262.479721069336,34.9997406005859,35.0005912780762,25.3719882965088,25.3719882965088,,,6.20649862289429,,1,,,,,,1,1,1,34.9998359680176,0,35.0001268046243,,,,,,,,,,,,,,,,,,,,,,,,,,,,,,,,,
,3863190259.12418,44.9999370574951,25.3719882965088,,,5,,,,37.2099988162518,,,,,2.25183623224612E-5,1.56756426416676E-8,0.202314246331403,0.000277292512060002,7.50550865126237E-6,5.22478809854564E-9,7.50546186079866E-6,4.80188169405793E-9,2.65022691646391E-8,2.05920928294708E-9,3.00024466945005,800.461120605469,10,8004,1,3,0.0782131995955033,0.0128240530528953,0.0138740101829171,178.412750244141,44.9995422363281,45.0005111694336,25.3719882965088,25.3719882965088,,,6.42373704910278,,1,,,,,,1,1,1,44.9998970031738,0,45.000046823539,,,,,,,,,,,,,,,,,,,,,,,,,,,,,,,,,
,3863191736.63454,59.999906539917,25.3719882965088,,,5,,,,37.2299998998642,,,,,2.50704163478854E-5,8.01590931249782E-9,1.3321231946215,0.000304288240772532,8.35587438084369E-6,2.67167207492812E-9,8.35361605887837E-6,8.02276453249879E-10,1.94256040547709E-7,2.54836892315683E-9,3.00033428043877,150.471878051758,10,1504,1,3,0.0873416709392072,0.0105623736682299,0.0126961013302207,191.559310913086,59.9992179870605,60.0007362365723,25.3719882965088,25.3719882965088,,,6.60410833358765,,1,,,,,,1,1,1,60.0000419616699,0,59.9999363708496,,,,,,,,,,,,,,,,,,,,,,,,,,,,,,,,,
,3863193232.09634,74.9997711181641,25.3719882965088,,,5,,,,37.2500009834766,,,,,3.2944757624564E-5,3.58596290615969E-9,1.54199836029648,6.00166056649325E-5,1.09818304949678E-5,1.19534759507004E-9,1.0977853627796E-5,1.00310243046623E-9,2.95517760702117E-7,6.50108750158364E-10,2.99993317504401,28.2570171356201,10,282,1,3,0.113597444623446,0.0220836128423692,0.00847342517226934,228.476211547852,74.9990539550781,75.0007019042969,25.3719882965088,25.3719882965088,,,6.72137832641602,,1,,,,,,1,1,1,74.9999389648438,0,75.0000054099343,,,,,,,,,,,,,,,,,,,,,,,,,,,,,,,,,
,3863194729.49735,89.9996223449707,25.3719882965088,,,5,,,,37.2899994254112,,,,,4.18471463260059E-5,1.82619056179636E-8,0.386998274778883,0.00032875489364432,1.39490473934072E-5,6.08730126958733E-9,1.39487292040156E-5,4.00280861514977E-9,9.42166469436711E-8,4.5861487042182E-9,3.00000029720914,5.31665134429932,10,53,1,3,0.146955965385541,0.00934030178685116,0.00198910874314606,264.568855285645,89.9987106323242,90.0015563964844,25.3719882965088,25.3719882965088,,,6.80380535125732,,1,,,,,,1,1,1,89.9998397827148,0,90.0000364515517,,,,,,,,,,,,,,,,,,,,,,,,,,,,,,,,,
,3863196177.76567,104.991260528564,25.3719882965088,,,5,,,,37.3199991881847,,,,,4.67384073195671E-5,4.48318054749557E-8,0.166852250362429,0.000580008067224575,1.55794696216328E-5,1.49439356524161E-8,1.55794035612269E-5,1.19026366425736E-8,4.53692386036713E-8,9.03595339399318E-9,2.99999990080975,1.00057637691498,19.98847910208,20,1,3,0.16448159460937,0.00247603592171887,2.23048264160752E-5,245.974838256836,104.956695556641,104.998908996582,25.3719882965088,25.3719882965088,,,6.86889362335205,,1,,,,,,1,1,1,104.994743347168,0,104.98918390274,,,,,,,,,,,,,,,,,,,,,,,,,,,,,,,,,
,3863197524.90764,114.999809265137,25.3719882965088,,,5,,,,37.3400002717972,,,,,5.16797202095124E-5,1.42577690548485E-8,-0.623623930886752,0.000123668243128382,1.72259159740195E-5,4.7524083087158E-9,1.72248956260107E-5,4.24676567151167E-9,-1.87488178340847E-7,2.13315870577438E-9,3.00011449536018,800.461120605469,10,8004,1,3,0.180085946959649,0.0262156239628172,0.0138657176867127,177.762741088867,114.998069763184,115.00220489502,25.3719882965088,25.3719882965088,,,6.90776300430298,,1,,,,,,1,1,1,114.999893188477,0,115.000042877197,,,,,,,,,,,,,,,,,,,,,,,,,,,,,,,,,
,3863199022.90768,129.999809265137,25.3719882965088,,,5,,,,37.3799987137318,,,,,5.186610390918E-5,4.58170619936807E-9,0.138760973225186,7.77357978475481E-5,1.72903502600346E-5,1.52738106402522E-9,1.72902995536096E-5,7.2521102220405E-10,4.18743492892151E-8,1.34423282507777E-9,2.99971389411727,150.471878051758,10,1504,1,3,0.181120203670439,0.0180170168378077,0.0126980589702725,191.513336181641,129.997665405273,130.002136230469,25.3719882965088,25.3719882965088,,,6.95094060897827,,1,,,,,,1,1,1,129.99951171875,0,129.999860839844,,,,,,,,,,,,,,,,,,,,,,,,,,,,,,,,,
,3863200523.52258,144.999641418457,25.3719882965088,,,5,,,,37.4200008809567,,,,,4.96989574435544E-5,3.55254803583851E-9,0.139074631448656,3.35481572088828E-5,1.6566750085976E-5,1.1842134826471E-9,1.65667012817216E-5,1.04778094656067E-9,4.02126023873135E-8,5.51830282340141E-10,2.99992196330801,28.2570171356201,10,282,1,3,0.172133770761556,0.0291002299333886,0.00848675891757011,228.446334838867,144.997787475586,145.00276184082,25.3719882965088,25.3719882965088,,,6.98813056945801,,1,,,,,,1,1,1,144.999450683594,0,145.000111993754,,,,,,,,,,,,,,,,,,,,,,,,,,,,,,,,,
,3863202019.70918,159.998649597168,25.3719882965088,,,5,,,,37.4700017273426,,,,,4.77299154441421E-5,3.32226512142836E-8,0.134897980140967,0.000499956218629318,1.59099748435056E-5,1.10742191796337E-8,1.59099307469238E-5,7.7051559556039E-9,3.74586314362906E-8,7.95417513878016E-9,2.99999942888818,5.31665134429932,10,53,1,3,0.167660006070091,0.00991447876239916,0.0019828996155411,264.626251220703,159.996643066406,160.001831054687,25.3719882965088,25.3719882965088,,,7.02260065078735,,1,,,,,,1,1,1,159.999282836914,0,159.99930091271,,,,,,,,,,,,,,,,,,,,,,,,,,,,,,,,,
,3863203479.20086,174.987884521484,25.3719882965088,,,5,,,,37.5199988484383,,,,,4.64421008558753E-5,4.10798200978266E-8,0.262157231808792,0.000655341792003155,1.54807005679201E-5,1.36932736159378E-8,1.54805385219342E-5,9.19669922305418E-9,7.0831804389731E-8,1.01452681443918E-8,2.99999994522956,1.00057637691498,19.98847910208,20,1,3,0.163434519188628,0.00273199698818342,0.000403268233640119,245.090637207031,174.927825927734,174.99919128418,25.3719882965088,25.3719882965088,,,7.05505466461182,,1,,,,,,1,1,1,174.993103027344,0,174.981924812749,,,,,,,,,,,,,,,,,,,,,,,,,,,,,,,,,
,3863204848.51682,184.999992370605,25.3719882965088,,,5,,,,37.5600010156631,,,,,4.68695170987131E-5,1.40952114290016E-8,-0.656530838543538,0.00012744763913683,1.56239076824236E-5,4.69862494352451E-9,1.5622881983469E-5,4.2537532093361E-9,-1.7902457791117E-7,1.99566029022315E-9,2.99985880942191,800.461120605469,10,8004,1,3,0.163511951637022,0.0235547784314004,0.0138883870095015,177.925765991211,184.995910644531,185.003707885742,25.3719882965088,25.3719882965088,,,7.08400011062622,,1,,,,,,1,1,1,184.999389648438,0,184.99981366671,,,,,,,,,,,,,,,,,,,,,,,,,,,,,,,,,
,3863206367.87034,199.999717712402,25.3719882965088,,,5,,,,37.6299992203712,,,,,4.5088637298987E-5,7.01585615357199E-9,0.199103945656393,0.00015003155131887,1.50278948132174E-5,2.33836182720281E-9,1.50278040766842E-5,6.17522851311447E-10,5.22221209946996E-8,2.25534954342502E-9,3.00032957772172,150.471878051758,10,1504,1,3,0.157444745041407,0.0158042244393764,0.0126962019130588,191.561706542969,199.99446105957,200.004425048828,25.3719882965088,25.3719882965088,,,7.12716579437256,,1,,,,,,1,1,1,199.999450683594,0,199.999669392904,,,,,,,,,,,,,,,,,,,,,,,,,,,,,,,,,
,3863207904.86511,214.999862670898,25.3719882965088,,,5,,,,37.6899987459183,,,,,4.47392040796081E-5,5.65166692918416E-9,0.194724809412728,4.19823086381372E-5,1.49130727095336E-5,1.88388956797302E-9,1.49129865835823E-5,1.78083450343333E-9,5.06833081862581E-8,6.14547293297202E-10,2.99999905794112,28.2570171356201,10,282,1,3,0.154930985832726,0.0263423482148362,0.00847897492349148,228.487380981445,214.995071411133,215.005676269531,25.3719882965088,25.3719882965088,,,7.18040370941162,,1,,,,,,1,1,1,214.999710083008,0,215.000443892045,,,,,,,,,,,,,,,,,,,,,,,,,,,,,,,,,
,3863209422.58259,229.999168395996,25.3719882965088,,,5,,,,37.7499982714653,,,,,4.43281797959929E-5,1.79199382660435E-8,0.204958079092223,0.000247730002896817,1.4776068358546E-5,5.97331616183163E-9,1.47759738190566E-5,4.72084197644782E-9,5.28567401326888E-8,3.65980286389953E-9,2.99999828914943,5.31665134429932,10,53,1,3,0.155699472995059,0.00939747988926617,0.00196237000636756,264.861640930176,229.995178222656,230.004898071289,25.3719882965088,25.3719882965088,,,7.26328945159912,,1,,,,,,1,1,1,230.000442504883,0,229.999982595444,,,,,,,,,,,,,,,,,,,,,,,,,,,,,,,,,
,3863210889.40678,244.97883605957,25.3719882965088,,,5,,,,37.8200002014637,,,,,4.40982871184475E-5,7.46419258070304E-8,0.186201387414365,0.00117908076414277,1.46994293849766E-5,2.48806425204692E-8,1.46993517619345E-5,1.78509463759761E-8,4.77705225603241E-8,1.7331765222083E-8,2.99999992948826,1.00057637691498,19.98847910208,20,1,3,0.155189703325827,0.00238824879449134,0.000143655197462067,273.930122375488,244.910461425781,245.001174926758,25.3719882965088,25.3719882965088,,,7.39851331710815,,1,,,,,,1,1,1,244.989028930664,0,244.974918712269,,,,,,,,,,,,,,,,,,,,,,,,,,,,,,,,,
,3863212258.05036,254.999656677246,25.3719882965088,,,5,,,,37.8799997270107,,,,,4.46552428479172E-5,1.77916125442729E-8,-0.765280344825673,0.000210400909050882,1.48862565945785E-5,5.93100591720823E-9,1.48849287571625E-5,5.03441941596202E-9,-1.98824781720998E-7,3.13551468408995E-9,2.99976307436354,800.461120605469,10,8004,1,3,0.156163299086418,0.0220795912404611,0.0138350818306208,178.111190795898,254.993835449219,255.005279541016,25.3719882965088,25.3719882965088,,,7.66495132446289,,1,,,,,,1,1,1,254.999267578125,0,254.999721916354,,,,,,,,,,,,,,,,,,,,,,,,,,,,,,,,,
,3863213779.83417,270.000335693359,25.3719882965088,,,5,,,,37.9600003361702,,,,,4.29319898876046E-5,4.28561726081009E-9,0.148516506382189,9.3471191169414E-5,1.43119352661155E-5,1.4286660593333E-9,1.43118871852464E-5,5.00804121375399E-10,3.7097954911986E-8,1.338014178215E-9,2.99973337562874,150.471878051758,10,1504,1,3,0.149942641885043,0.0148975571996009,0.0126924039795995,191.602355957031,269.993316650391,270.006530761719,25.3719882965088,25.3719882965088,,,7.79384422302246,,1,,,,,,1,1,1,269.999694824219,0,270.000788071576,,,,,,,,,,,,,,,,,,,,,,,,,,,,,,,,,
,3863215298.70218,284.999099731445,25.3719882965088,,,5,,,,38.0400009453297,,,,,4.25851869078883E-5,3.41747653089956E-9,0.117871923894475,5.3141797711193E-5,1.41952149354536E-5,1.1391710924721E-9,1.41951848963268E-5,8.55093036024237E-10,2.92031302916253E-8,7.52679664709313E-10,2.99996774275877,28.2570171356201,10,282,1,3,0.147506366456312,0.0248727672607212,0.00846949219703674,228.547500610352,284.993438720703,285.005096435547,25.3719882965088,25.3719882965088,,,8.15483570098877,,1,,,,,,1,1,1,284.998413085938,0,284.999752530185,,,,,,,,,,,,,,,,,,,,,,,,,,,,,,,,,
,3863216803.12873,300.003128051758,25.3719882965088,,,5,,,,38.1300002336502,,,,,4.23959283713565E-5,1.59432833412358E-8,0.0861087767315931,0.000263055137227465,1.41319696518171E-5,5.31442534658327E-9,1.41319536922101E-5,3.79791744729295E-9,2.12386701390574E-8,3.71738346528233E-9,3.00000137389945,5.31665134429932,10,53,1,3,0.14893097230948,0.00867827084701574,0.00195997976697981,265.372207641602,299.996795654297,300.012176513672,25.3719882965088,25.3719882965088,,,8.38909816741943,,1,,,,,,1,1,1,300.004760742188,0,300.005020892034,,,,,,,,,,,,,,,,,,,,,,,,,,,,,,,,,
,3863217006.35574,299.997940063477,25.3719882965088,,,5,,,,38.1300002336502,,,,,4.31276255371079E-5,1.44740935975999E-8,-0.874624235477185,0.000167140477690593,1.43768481484451E-5,4.82502440483371E-9,1.43751731168381E-5,4.18087634614645E-9,-2.19455107904792E-7,2.40855423137491E-9,2.99979697161733,800.461120605469,10,8004,1,3,0.151373958661307,0.0210417848786935,0.0138561595231295,178.251052856445,299.991333007812,300.006652832031,25.3719882965088,25.3719882965088,,,8.37574577331543,,1,,,,,,1,1,1,299.997436523438,0,299.998734107384,,,,,,,,,,,,,,,,,,,,,,,,,,,,,,,,,