File: data/Rock_mag_data/MPMS3/DX1-5r-FC-ZFC-RT-SIRM-VSM-SWEEP_AC-3freq.csv
[Header],,,,,,,,,,,,,,,,,,,,,,,,,,,,,,,,,,,,,,,,,,,,,,,,,,,,,,,,,,,,,,,,,,,,,,,,,,,,,,,,,,,,,,,
; MPMS3 Data File (default extension .dat),,,,,,,,,,,,,,,,,,,,,,,,,,,,,,,,,,,,,,,,,,,,,,,,,,,,,,,,,,,,,,,,,,,,,,,,,,,,,,,,,,,,,,,
; Copyright (c) 2007, Quantum Design, Inc. All rights reserved.,,,,,,,,,,,,,,,,,,,,,,,,,,,,,,,,,,,,,,,,,,,,,,,,,,,,,,,,,,,,,,,,,,,,,,,,,,,,,,,,,,,,,
TITLE,,,,,,,,,,,,,,,,,,,,,,,,,,,,,,,,,,,,,,,,,,,,,,,,,,,,,,,,,,,,,,,,,,,,,,,,,,,,,,,,,,,,,,,
FILEOPENTIME,3864030623,6/10/22,2:48 PM,,,,,,,,,,,,,,,,,,,,,,,,,,,,,,,,,,,,,,,,,,,,,,,,,,,,,,,,,,,,,,,,,,,,,,,,,,,,,,,,,,,,
BYAPP,MPMS3 w/ AC,1,1.1,,,,,,,,,,,,,,,,,,,,,,,,,,,,,,,,,,,,,,,,,,,,,,,,,,,,,,,,,,,,,,,,,,,,,,,,,,,,,,,,,,,,
INFO,MPMS3 Measurement Release 1.1.16 Build 424, MultiVu Release 2.3.4.19,APPNAME,,,,,,,,,,,,,,,,,,,,,,,,,,,,,,,,,,,,,,,,,,,,,,,,,,,,,,,,,,,,,,,,,,,,,,,,,,,,,,,,,,,,
INFO,Linear Motor Servo Controller,MOTOR_MODULE_NAME,,,,,,,,,,,,,,,,,,,,,,,,,,,,,,,,,,,,,,,,,,,,,,,,,,,,,,,,,,,,,,,,,,,,,,,,,,,,,,,,,,,,,
INFO,3101-100 N2,MOTOR_HW_VERSION,,,,,,,,,,,,,,,,,,,,,,,,,,,,,,,,,,,,,,,,,,,,,,,,,,,,,,,,,,,,,,,,,,,,,,,,,,,,,,,,,,,,,
INFO,,MOTOR_SERIAL_NUMBER,,,,,,,,,,,,,,,,,,,,,,,,,,,,,,,,,,,,,,,,,,,,,,,,,,,,,,,,,,,,,,,,,,,,,,,,,,,,,,,,,,,,,
INFO,01.04.28,MOTOR_SOFTWARE_VERSION,,,,,,,,,,,,,,,,,,,,,,,,,,,,,,,,,,,,,,,,,,,,,,,,,,,,,,,,,,,,,,,,,,,,,,,,,,,,,,,,,,,,,
INFO,Quantum Design Squid Module,SQUID_MODULE_NAME,,,,,,,,,,,,,,,,,,,,,,,,,,,,,,,,,,,,,,,,,,,,,,,,,,,,,,,,,,,,,,,,,,,,,,,,,,,,,,,,,,,,,
INFO,3101-501 B0,SQUID_HW_VERSION,,,,,,,,,,,,,,,,,,,,,,,,,,,,,,,,,,,,,,,,,,,,,,,,,,,,,,,,,,,,,,,,,,,,,,,,,,,,,,,,,,,,,
INFO,SQM327,SQUID_SERIAL_NUMBER,,,,,,,,,,,,,,,,,,,,,,,,,,,,,,,,,,,,,,,,,,,,,,,,,,,,,,,,,,,,,,,,,,,,,,,,,,,,,,,,,,,,,
INFO,01.03.04,SQUID_SOFTWARE_VERSION,,,,,,,,,,,,,,,,,,,,,,,,,,,,,,,,,,,,,,,,,,,,,,,,,,,,,,,,,,,,,,,,,,,,,,,,,,,,,,,,,,,,,
INFO,Quantum Design VSM Oven,OVEN_MODULE_NAME,,,,,,,,,,,,,,,,,,,,,,,,,,,,,,,,,,,,,,,,,,,,,,,,,,,,,,,,,,,,,,,,,,,,,,,,,,,,,,,,,,,,,
INFO,3101-201 A3,OVEN_HW_VERSION,,,,,,,,,,,,,,,,,,,,,,,,,,,,,,,,,,,,,,,,,,,,,,,,,,,,,,,,,,,,,,,,,,,,,,,,,,,,,,,,,,,,,
INFO,OVB365,OVEN_SERIAL_NUMBER,,,,,,,,,,,,,,,,,,,,,,,,,,,,,,,,,,,,,,,,,,,,,,,,,,,,,,,,,,,,,,,,,,,,,,,,,,,,,,,,,,,,,
INFO,01.07.07,OVEN_SOFTWARE_VERSION,,,,,,,,,,,,,,,,,,,,,,,,,,,,,,,,,,,,,,,,,,,,,,,,,,,,,,,,,,,,,,,,,,,,,,,,,,,,,,,,,,,,,
INFO,SQUID AC,AC_MODULE_NAME,,,,,,,,,,,,,,,,,,,,,,,,,,,,,,,,,,,,,,,,,,,,,,,,,,,,,,,,,,,,,,,,,,,,,,,,,,,,,,,,,,,,,
INFO,3101-401 G0,AC_HW_VERSION,,,,,,,,,,,,,,,,,,,,,,,,,,,,,,,,,,,,,,,,,,,,,,,,,,,,,,,,,,,,,,,,,,,,,,,,,,,,,,,,,,,,,
INFO,SAC220,AC_SERIAL_NUMBER,,,,,,,,,,,,,,,,,,,,,,,,,,,,,,,,,,,,,,,,,,,,,,,,,,,,,,,,,,,,,,,,,,,,,,,,,,,,,,,,,,,,,
INFO,SQUID AC 00.95.07,AC_SOFTWARE_VERSION,,,,,,,,,,,,,,,,,,,,,,,,,,,,,,,,,,,,,,,,,,,,,,,,,,,,,,,,,,,,,,,,,,,,,,,,,,,,,,,,,,,,,
INFO,TCI344,COIL_SERIAL_NUMBER,,,,,,,,,,,,,,,,,,,,,,,,,,,,,,,,,,,,,,,,,,,,,,,,,,,,,,,,,,,,,,,,,,,,,,,,,,,,,,,,,,,,,
INFO,0,MOMENT_UNITS,,,,,,,,,,,,,,,,,,,,,,,,,,,,,,,,,,,,,,,,,,,,,,,,,,,,,,,,,,,,,,,,,,,,,,,,,,,,,,,,,,,,,
INFO,DX1-5r,SAMPLE_MATERIAL,,,,,,,,,,,,,,,,,,,,,,,,,,,,,,,,,,,,,,,,,,,,,,,,,,,,,,,,,,,,,,,,,,,,,,,,,,,,,,,,,,,,,
INFO,SSRM2022C,SAMPLE_COMMENT,,,,,,,,,,,,,,,,,,,,,,,,,,,,,,,,,,,,,,,,,,,,,,,,,,,,,,,,,,,,,,,,,,,,,,,,,,,,,,,,,,,,,
INFO,,SAMPLE_MASS,,,,,,,,,,,,,,,,,,,,,,,,,,,,,,,,,,,,,,,,,,,,,,,,,,,,,,,,,,,,,,,,,,,,,,,,,,,,,,,,,,,,,
INFO,,SAMPLE_VOLUME,,,,,,,,,,,,,,,,,,,,,,,,,,,,,,,,,,,,,,,,,,,,,,,,,,,,,,,,,,,,,,,,,,,,,,,,,,,,,,,,,,,,,
INFO,,SAMPLE_MOLECULAR_WEIGHT,,,,,,,,,,,,,,,,,,,,,,,,,,,,,,,,,,,,,,,,,,,,,,,,,,,,,,,,,,,,,,,,,,,,,,,,,,,,,,,,,,,,,
INFO,,SAMPLE_SIZE,,,,,,,,,,,,,,,,,,,,,,,,,,,,,,,,,,,,,,,,,,,,,,,,,,,,,,,,,,,,,,,,,,,,,,,,,,,,,,,,,,,,,
INFO,,SAMPLE_SHAPE,,,,,,,,,,,,,,,,,,,,,,,,,,,,,,,,,,,,,,,,,,,,,,,,,,,,,,,,,,,,,,,,,,,,,,,,,,,,,,,,,,,,,
INFO,Straw,SAMPLE_HOLDER,,,,,,,,,,,,,,,,,,,,,,,,,,,,,,,,,,,,,,,,,,,,,,,,,,,,,,,,,,,,,,,,,,,,,,,,,,,,,,,,,,,,,
INFO,Standard,SAMPLE_HOLDER_DETAIL,,,,,,,,,,,,,,,,,,,,,,,,,,,,,,,,,,,,,,,,,,,,,,,,,,,,,,,,,,,,,,,,,,,,,,,,,,,,,,,,,,,,,
INFO,64.24,SAMPLE_OFFSET,,,,,,,,,,,,,,,,,,,,,,,,,,,,,,,,,,,,,,,,,,,,,,,,,,,,,,,,,,,,,,,,,,,,,,,,,,,,,,,,,,,,,
DATATYPE,COMMENT,1,,,,,,,,,,,,,,,,,,,,,,,,,,,,,,,,,,,,,,,,,,,,,,,,,,,,,,,,,,,,,,,,,,,,,,,,,,,,,,,,,,,,,
DATATYPE,TIME,2,,,,,,,,,,,,,,,,,,,,,,,,,,,,,,,,,,,,,,,,,,,,,,,,,,,,,,,,,,,,,,,,,,,,,,,,,,,,,,,,,,,,,
STARTUPAXIS,X,2,,,,,,,,,,,,,,,,,,,,,,,,,,,,,,,,,,,,,,,,,,,,,,,,,,,,,,,,,,,,,,,,,,,,,,,,,,,,,,,,,,,,,
STARTUPAXIS,Y1,5,,,,,,,,,,,,,,,,,,,,,,,,,,,,,,,,,,,,,,,,,,,,,,,,,,,,,,,,,,,,,,,,,,,,,,,,,,,,,,,,,,,,,
FIELDGROUP, VSM,2,3,4,5,6,8,9,10,11,14,15,,,,,,,,,,,,,,,,,,,,,,,,,,,,,,,,,,,,,,,,,,,,,,,,,,,,,,,,,,,,,,,,,,,,,,,,,,,
FIELDGROUP, DC,2,3,4,14,56,57,58,59,60,61,62,63,64,65,66,67,68,69,,,,,,,,,,,,,,,,,,,,,,,,,,,,,,,,,,,,,,,,,,,,,,,,,,,,,,,,,,,,,,,,,,,,
FIELDGROUP, AC,2,3,4,11,16,17,18,19,20,21,22,23,24,25,26,27,28,29,30,,,,,,,,,,,,,,,,,,,,,,,,,,,,,,,,,,,,,,,,,,,,,,,,,,,,,,,,,,,,,,,,,,,
STARTUPGROUP, All,,,,,,,,,,,,,,,,,,,,,,,,,,,,,,,,,,,,,,,,,,,,,,,,,,,,,,,,,,,,,,,,,,,,,,,,,,,,,,,,,,,,,,
[Data],,,,,,,,,,,,,,,,,,,,,,,,,,,,,,,,,,,,,,,,,,,,,,,,,,,,,,,,,,,,,,,,,,,,,,,,,,,,,,,,,,,,,,,
Comment,Time Stamp (sec),Temperature (K),Magnetic Field (Oe),Moment (emu),M. Std. Err. (emu),Transport Action,Averaging Time (sec),Frequency (Hz),Peak Amplitude (mm),Center Position (mm),Lockin Signal' (V),Lockin Signal (V),Range,M. Quad. Signal (emu),AC Moment (emu),AC M. Std Err. (emu),AC Phase (deg),AC Phase Std. Err. (deg),AC Susceptibility (emu/Oe),AC Suscept. Std Err. (emu/Oe),AC X' (emu/Oe),AC X' Std Err. (emu/Oe),AC X'' (emu/Oe),AC X'' Std Err. (emu/Oe),AC Drive (Oe),AC Frequency (Hz),AC Averaging Time (sec),AC Cycles,AC Range,AC Measure Type,AC Signal' (V),AC Signal'' (V),AC Trim Coil Ratio,AC Trim Coil Phase,Min. Temperature (K),Max. Temperature (K),Min. Field (Oe),Max. Field (Oe),Mass (grams),Motor Lag (deg),Pressure (Torr),Measure Count,Measurement Number,SQUID Status (code),Motor Status (code),Measure Status (code),Motor Current (amps),Motor Temp. (C),Temp. Status (code),Field Status (code),Chamber Status (code),Chamber Temp (K),Redirection State,Average Temp (K),Rotation Angle (deg),Rotator state,DC Moment Fixed Ctr (emu),DC Moment Err Fixed Ctr (emu),DC Moment Free Ctr (emu),DC Moment Err Free Ctr (emu),DC Fixed Fit,DC Free Fit,DC Calculated Center (mm),DC Calculated Center Err (mm),DC Scan Length (mm),DC Scan Time (s),DC Number of Points,DC Squid Drift,DC Min V (V),DC Max V (V),DC Scans per Measure,Map 01,Map 02,Map 03,Map 04,Map 05,Map 06,Map 07,Map 08,Map 09,Map 10,Map 11,Map 12,Map 13,Map 14,Map 15,Map 16
,3864040552,9.999990463,25.43466568,3.59E-05,4.71E-08,1,5,14.00089645,5.000112627,35.95000133,0.046821272,0.006999201,10,-5.47E-08,,,,,,,,,,,,,,,,,,,,,9.999990463,9.999990463,25.43466568,25.43466568,49.65803227,5.760684767,5.161449432,70,1,0,0,1,0.317840576,31.2805481,1,1,1,9.999990463,0,9.999990463,,,,,,,,,,,,,,,,,,,,,,,,,,,,,,,,,
,3864040630,21.60084343,25.43466568,2.93E-05,5.46E-08,1,5,14.00089645,4.999670646,35.95000133,0.038243712,0.005645008,1,-9.86E-08,,,,,,,,,,,,,,,,,,,,,21.60084343,21.60084343,25.43466568,25.43466568,49.70610242,5.763720814,5.92102623,70,1,0,0,1,0.314407349,31.76930618,2,1,1,21.60084343,0,21.60084343,,,,,,,,,,,,,,,,,,,,,,,,,,,,,,,,,
,3864040717,35.01518631,25.43466568,2.38E-05,1.62E-08,1,5,14.00089645,4.999659986,35.95000133,0.031081121,0.004650894,1,-3.28E-08,,,,,,,,,,,,,,,,,,,,,35.01518631,35.01518631,25.43466568,25.43466568,49.69672288,5.76294569,6.355532646,70,1,0,0,1,0.314483643,32.25806427,2,1,1,35.01518631,0,35.01518631,,,,,,,,,,,,,,,,,,,,,,,,,,,,,,,,,
,3864040812,50.01716232,25.43466568,2.14E-05,1.13E-08,1,5,14.00089645,5.000363558,35.96999869,0.027982146,0.004198446,1,-2.11E-08,,,,,,,,,,,,,,,,,,,,,50.01716232,50.01716232,25.43466568,25.43466568,49.72212581,5.760553269,6.646923065,70,1,0,0,1,0.318450928,32.74682236,2,1,1,50.01716232,0,50.01716232,,,,,,,,,,,,,,,,,,,,,,,,,,,,,,,,,
,3864040907,65.03248596,25.43466568,2.06E-05,4.32E-08,1,5,14.00089645,5.000155012,35.98999977,0.026876321,0.00399241,1,-5.03E-08,,,,,,,,,,,,,,,,,,,,,65.03248596,65.03248596,25.43466568,25.43466568,49.74205734,5.761035292,6.827240467,70,1,0,0,1,0.317230225,32.74682236,2,1,1,65.03248596,0,65.03248596,,,,,,,,,,,,,,,,,,,,,,,,,,,,,,,,,
,3864041001,80.06163025,25.43466568,1.94E-05,8.64E-09,1,5,14.00089645,4.999783824,36.01000085,0.025330332,0.003776742,1,-3.69E-08,,,,,,,,,,,,,,,,,,,,,80.06163025,80.06163025,25.43466568,25.43466568,49.65412413,5.762967229,6.935516357,70,1,0,0,1,0.315322876,33.23558426,2,1,1,80.06163025,0,80.06163025,,,,,,,,,,,,,,,,,,,,,,,,,,,,,,,,,
,3864041093,95.02999878,25.43466568,1.73E-05,1.02E-08,1,5,14.00089645,4.999146413,36.04000062,0.022517119,0.003367347,1,-2.53E-08,,,,,,,,,,,,,,,,,,,,,95.02999878,95.02999878,25.43466568,25.43466568,49.83468031,5.764273717,7.022447109,68,1,64,0,0,0.314941406,32.74682236,2,1,1,95.02999878,0,95.02999878,,,,,,,,,,,,,,,,,,,,,,,,,,,,,,,,,
,3864041184,110.030899,25.43466568,1.35E-05,7.25E-09,1,5,14.00089645,4.998696344,36.07000038,0.017639896,0.002627815,1,-2.75E-08,,,,,,,,,,,,,,,,,,,,,110.030899,110.030899,25.43466568,25.43466568,49.63614667,5.766499479,7.093688965,70,1,0,0,1,0.318374634,32.74682236,2,1,1,110.030899,0,110.030899,,,,,,,,,,,,,,,,,,,,,,,,,,,,,,,,,
,3864041275,125.057518,25.43466568,1.28E-05,6.89E-09,1,5,14.00089645,4.998513011,36.10999882,0.016666589,0.002490799,1,-2.00E-08,,,,,,,,,,,,,,,,,,,,,125.057518,125.057518,25.43466568,25.43466568,49.73150535,5.767232212,7.1451931,69,1,64,0,0,0.316925049,32.74682236,2,1,1,125.057518,0,125.057518,,,,,,,,,,,,,,,,,,,,,,,,,,,,,,,,,
,3864041366,140.0095978,25.43466568,1.25E-05,5.70E-09,1,5,14.00089645,4.99835531,36.15000099,0.016315151,0.00243999,1,-1.83E-08,,,,,,,,,,,,,,,,,,,,,140.0095978,140.0095978,25.43466568,25.43466568,49.69359637,5.768534831,7.194082737,70,1,0,0,1,0.318603516,32.74682236,2,1,1,140.0095978,0,140.0095978,,,,,,,,,,,,,,,,,,,,,,,,,,,,,,,,,
,3864041456,155.0528259,25.43466568,1.24E-05,5.81E-09,1,5,14.00089645,4.998370464,36.20000184,0.016169018,0.002415061,1,-2.04E-08,,,,,,,,,,,,,,,,,,,,,155.0528259,155.0528259,25.43466568,25.43466568,49.67913624,5.768405347,7.230769634,70,1,0,0,1,0.317459106,32.25806427,2,1,1,155.0528259,0,155.0528259,,,,,,,,,,,,,,,,,,,,,,,,,,,,,,,,,
,3864041547,170.0196686,25.43466568,1.23E-05,5.66E-09,1,5,14.00089645,4.998473775,36.24999896,0.01604521,0.002398867,1,-1.85E-08,,,,,,,,,,,,,,,,,,,,,170.0196686,170.0196686,25.43466568,25.43466568,49.81357634,5.767946486,7.268570423,70,1,0,0,1,0.317459106,32.74682236,2,1,1,170.0196686,0,170.0196686,,,,,,,,,,,,,,,,,,,,,,,,,,,,,,,,,
,3864041637,185.0128632,25.43466568,1.22E-05,5.88E-09,1,5,14.00089645,4.998476138,36.30999848,0.015927901,0.002379284,1,-1.99E-08,,,,,,,,,,,,,,,,,,,,,185.0128632,185.0128632,25.43466568,25.43466568,49.76277049,5.768105813,7.309714317,70,1,0,0,1,0.317382813,32.74682236,2,1,1,185.0128632,0,185.0128632,,,,,,,,,,,,,,,,,,,,,,,,,,,,,,,,,
,3864041728,200.1053619,25.43466568,1.21E-05,5.84E-09,1,5,14.00089645,4.998608983,36.37000173,0.015814381,0.002360138,1,-2.14E-08,,,,,,,,,,,,,,,,,,,,,200.1053619,200.1053619,25.43466568,25.43466568,49.69945858,5.767136902,7.35461998,69,1,64,0,0,0.318069458,32.74682236,2,1,1,200.1053619,0,200.1053619,,,,,,,,,,,,,,,,,,,,,,,,,,,,,,,,,
,3864041818,215.0196533,25.43466568,1.20E-05,6.46E-09,1,5,14.00089645,4.9986204,36.43000126,0.01570604,0.002347414,1,-1.87E-08,,,,,,,,,,,,,,,,,,,,,215.0196533,215.0196533,25.43466568,25.43466568,49.78270202,5.76707287,7.410220146,68,1,64,0,0,0.315551758,33.23558426,2,1,1,215.0196533,0,215.0196533,,,,,,,,,,,,,,,,,,,,,,,,,,,,,,,,,
,3864041908,230.0420532,25.43466568,1.19E-05,6.63E-09,1,5,14.00089645,4.998596961,36.50999814,0.015588453,0.002329723,1,-1.86E-08,,,,,,,,,,,,,,,,,,,,,230.0420532,230.0420532,25.43466568,25.43466568,49.78543772,5.767349958,7.515107632,69,1,64,0,0,0.318603516,32.25806427,2,1,1,230.0420532,0,230.0420532,,,,,,,,,,,,,,,,,,,,,,,,,,,,,,,,,
,3864041999,245.0062256,25.43466568,1.18E-05,6.56E-09,1,5,14.00089645,4.998565852,36.58000007,0.015436512,0.002297392,1,-2.57E-08,,,,,,,,,,,,,,,,,,,,,245.0062256,245.0062256,25.43466568,25.43466568,49.70336672,5.76719164,7.590344429,68,1,64,0,0,0.317153931,33.23558426,2,1,1,245.0062256,0,245.0062256,,,,,,,,,,,,,,,,,,,,,,,,,,,,,,,,,
,3864042089,260.0183411,25.43466568,1.17E-05,6.63E-09,1,5,14.00089645,4.99875071,36.66000068,0.015284356,0.002296203,1,-9.33E-09,,,,,,,,,,,,,,,,,,,,,260.0183411,260.0183411,25.43466568,25.43466568,49.76589701,5.766196904,7.775835991,68,1,64,0,0,0.318145752,32.74682236,2,1,1,260.0183411,0,260.0183411,,,,,,,,,,,,,,,,,,,,,,,,,,,,,,,,,
,3864042180,275.0236206,25.43466568,1.16E-05,6.89E-09,1,5,14.00089645,4.999389293,36.74000129,0.01513897,0.002247483,1,-2.94E-08,,,,,,,,,,,,,,,,,,,,,275.0236206,275.0236206,25.43466568,25.43466568,49.71743604,5.765404326,7.794871807,69,1,64,0,0,0.316696167,33.23558426,2,1,1,275.0236206,0,275.0236206,,,,,,,,,,,,,,,,,,,,,,,,,,,,,,,,,
,3864042270,290.0318298,25.43466568,1.14E-05,6.26E-09,1,5,14.00089645,4.999837095,36.83000058,0.014941065,0.002219628,1,-2.78E-08,,,,,,,,,,,,,,,,,,,,,290.0318298,290.0318298,25.43466568,25.43466568,49.87962395,5.764716638,7.725955963,67,1,64,0,0,0.314712524,32.25806427,2,1,1,290.0318298,0,290.0318298,,,,,,,,,,,,,,,,,,,,,,,,,,,,,,,,,
,3864044104,10.00014591,25.43466567,1.61E-05,9.26E-09,1,5,14.00089645,4.978732426,35.95000133,0.02092591,0.003150818,1,-7.51E-09,,,,,,,,,,,,,,,,,,,,,10.00014591,10.00014591,25.43466568,25.43466568,49.65099761,5.763904385,5.144463539,70,1,0,0,1,0.313415527,29.81427193,1,1,1,10.00014591,0,10.00014591,,,,,,,,,,,,,,,,,,,,,,,,,,,,,,,,,
,3864044172,20.05609512,25.43466567,1.58E-05,9.60E-09,1,5,14.00089645,4.978417186,35.95000133,0.02055415,0.003082812,1,-1.64E-08,,,,,,,,,,,,,,,,,,,,,20.05609512,20.05609512,25.43466568,25.43466568,49.6259855,5.762769633,5.855013847,70,1,0,0,1,0.315704346,31.76930618,2,1,1,20.05609512,0,20.05609512,,,,,,,,,,,,,,,,,,,,,,,,,,,,,,,,,
,3864044269,35.05437851,25.43466567,1.50E-05,8.83E-09,1,5,14.00089645,4.978919388,35.95000133,0.019524444,0.002920934,1,-2.12E-08,,,,,,,,,,,,,,,,,,,,,35.05437851,35.05437851,25.43466568,25.43466568,49.67131995,5.761068204,6.350161552,70,1,0,0,1,0.314941406,31.76930618,2,1,1,35.05437851,0,35.05437851,,,,,,,,,,,,,,,,,,,,,,,,,,,,,,,,,
,3864044365,50.00644684,25.43466567,1.46E-05,1.18E-08,1,5,14.00089645,4.978747046,35.96999869,0.018991251,0.002831117,1,-2.82E-08,,,,,,,,,,,,,,,,,,,,,50.00644684,50.00644684,25.43466568,25.43466568,49.68226275,5.761855339,6.669080734,70,1,0,0,1,0.314559937,32.25806427,2,1,1,50.00644684,0,50.00644684,,,,,,,,,,,,,,,,,,,,,,,,,,,,,,,,,
,3864044459,65.01132965,25.43466567,1.43E-05,2.01E-08,1,5,14.00089645,4.9785453,35.98999977,0.018551158,0.002764242,1,-2.85E-08,,,,,,,,,,,,,,,,,,,,,65.01132965,65.01132965,25.43466568,25.43466568,49.6697567,5.762786993,6.836237907,68,1,64,0,0,0.314483643,31.76930618,2,1,1,65.01132965,0,65.01132965,,,,,,,,,,,,,,,,,,,,,,,,,,,,,,,,,
,3864044553,80.00068665,25.43466567,1.39E-05,7.78E-08,1,5,14.00089645,4.977804834,36.01000085,0.018030014,0.002548143,1,-1.32E-07,,,,,,,,,,,,,,,,,,,,,80.00068665,80.00068665,25.43466568,25.43466568,49.65998634,5.765408935,6.955834866,70,1,0,0,1,0.315856934,31.76930618,2,1,1,80.0635376,0,80.00068665,,,,,,,,,,,,,,,,,,,,,,,,,,,,,,,,,
,3864044645,95.01056671,25.43466567,1.34E-05,7.29E-08,1,5,14.00089645,4.977711897,36.04000062,0.017376239,0.002409815,1,-1.62E-07,,,,,,,,,,,,,,,,,,,,,95.01056671,95.01056671,25.43466568,25.43466568,49.78465609,5.765905169,7.044683456,70,1,0,0,1,0.314331055,31.76930618,2,1,1,95.01056671,0,95.01056671,,,,,,,,,,,,,,,,,,,,,,,,,,,,,,,,,
,3864044736,110.0322342,25.43466567,1.25E-05,4.65E-08,1,5,14.00089645,4.977567017,36.07000038,0.016223307,0.002409693,1,-3.07E-08,,,,,,,,,,,,,,,,,,,,,110.0322342,110.0322342,25.43466568,25.43466568,49.82959973,5.765834277,7.094963551,70,1,0,0,1,0.31539917,32.74682236,2,1,1,110.0322342,0,110.0322342,,,,,,,,,,,,,,,,,,,,,,,,,,,,,,,,,
,3864044827,125.0287476,25.43466567,1.25E-05,6.71E-08,1,5,14.00089645,4.977698684,36.10999882,0.016250483,0.002423484,1,-2.34E-08,,,,,,,,,,,,,,,,,,,,,125.0287476,125.0287476,25.43466568,25.43466568,49.72994209,5.766201869,7.154619217,68,1,64,0,0,0.314941406,32.25806427,2,1,1,125.0287476,0,125.0287476,,,,,,,,,,,,,,,,,,,,,,,,,,,,,,,,,
,3864044917,140.0302429,25.43466567,1.24E-05,1.75E-08,1,5,14.00089645,4.987761332,36.15000099,0.016139406,0.002405535,1,-2.43E-08,,,,,,,,,,,,,,,,,,,,,140.0168457,140.0436401,25.43466568,25.43466568,49.66272204,5.767898525,7.199787617,68,1,64,0,0,0.315551758,32.25806427,2,1,1,140.0436401,0,140.0302429,,,,,,,,,,,,,,,,,,,,,,,,,,,,,,,,,
,3864045008,155.0062103,25.43466567,1.23E-05,1.23E-08,1,5,14.00089645,4.987617124,36.20000184,0.016035116,0.002403487,1,-1.40E-08,,,,,,,,,,,,,,,,,,,,,155.0062103,155.0062103,25.43466568,25.43466568,49.74909199,5.768449187,7.231780529,69,1,64,0,0,0.318069458,32.74682236,2,1,1,155.0062103,0,155.0062103,,,,,,,,,,,,,,,,,,,,,,,,,,,,,,,,,
,3864045098,170.0068359,25.43466567,1.23E-05,1.17E-08,1,5,14.00089645,4.988484011,36.24999896,0.015938528,0.00239404,1,-1.01E-08,,,,,,,,,,,,,,,,,,,,,170.0068359,170.0068359,25.43466568,25.43466568,49.66741181,5.764022242,7.261651993,69,1,64,0,0,0.315628052,32.25806427,2,1,1,170.0068359,0,170.0068359,,,,,,,,,,,,,,,,,,,,,,,,,,,,,,,,,
,3864045189,185.0266113,25.43466567,1.22E-05,1.18E-08,1,5,14.00089645,4.988234276,36.30999848,0.015866206,0.002365889,1,-2.30E-08,,,,,,,,,,,,,,,,,,,,,185.0266113,185.0266113,25.43466568,25.43466568,49.85109451,5.764344823,7.309290886,69,1,64,0,0,0.313644409,32.74682236,2,1,1,185.0266113,0,185.0266113,,,,,,,,,,,,,,,,,,,,,,,,,,,,,,,,,
,3864045279,200.0280151,25.43466567,1.21E-05,1.85E-08,1,5,14.00089645,4.987789263,36.37000173,0.015770457,0.002346268,1,-2.69E-08,,,,,,,,,,,,,,,,,,,,,200.0280151,200.0280151,25.43466568,25.43466568,49.74596548,5.767859234,7.35236311,69,1,64,0,0,0.316543579,32.25806427,2,1,1,200.0280151,0,200.0280151,,,,,,,,,,,,,,,,,,,,,,,,,,,,,,,,,
,3864045369,215.0368347,25.43466567,1.20E-05,1.23E-08,1,5,14.00089645,4.987916001,36.43000126,0.015648186,0.002323559,1,-3.01E-08,,,,,,,,,,,,,,,,,,,,,215.0368347,215.0368347,25.43466568,25.43466568,49.70649324,5.765920911,7.407640934,68,1,64,0,0,0.318374634,31.76930618,2,1,1,215.0368347,0,215.0368347,,,,,,,,,,,,,,,,,,,,,,,,,,,,,,,,,
,3864045460,230.0100403,25.43466567,1.19E-05,1.18E-08,1,5,14.00089645,4.987819767,36.49999946,0.015532394,0.002325177,1,-1.57E-08,,,,,,,,,,,,,,,,,,,,,230.0100403,230.0100403,25.43466568,25.43466568,49.66780263,5.766695241,7.499487877,68,1,64,0,0,0.315170288,32.25806427,2,1,1,230.0100403,0,230.0100403,,,,,,,,,,,,,,,,,,,,,,,,,,,,,,,,,
,3864045550,245.0290375,25.43466567,1.18E-05,5.79E-08,1,5,14.00089645,4.987995351,36.58000007,0.015366246,0.002237353,1,-6.29E-08,,,,,,,,,,,,,,,,,,,,,245.0290375,245.0290375,25.43466568,25.43466568,49.73932164,5.766497062,7.585025787,68,1,64,0,0,0.320968628,32.25806427,2,1,1,245.0290375,0,245.0290375,,,,,,,,,,,,,,,,,,,,,,,,,,,,,,,,,
,3864045641,260.0381165,25.43466567,1.17E-05,5.54E-08,1,5,14.00089645,4.988101272,36.66000068,0.015215514,0.002314147,1,1.20E-08,,,,,,,,,,,,,,,,,,,,,260.0381165,260.0381165,25.43466568,25.43466568,49.75026443,5.766224874,7.77519846,69,1,64,0,0,0.315093994,32.74682236,2,1,1,260.0381165,0,260.0381165,,,,,,,,,,,,,,,,,,,,,,,,,,,,,,,,,
,3864045731,275.0318909,25.43466567,1.16E-05,1.29E-08,1,5,14.00089645,4.988466514,36.74000129,0.015116302,0.002238703,1,-3.35E-08,,,,,,,,,,,,,,,,,,,,,275.0318909,275.0318909,25.43466568,25.43466568,49.67561891,5.764594365,7.796384811,68,1,64,0,0,0.313339233,32.25806427,2,1,1,275.0318909,0,275.0318909,,,,,,,,,,,,,,,,,,,,,,,,,,,,,,,,,
,3864045822,290.0712891,25.43466567,1.15E-05,9.43E-09,1,5,14.00089645,4.988890949,36.83000058,0.014904536,0.00222039,1,-2.32E-08,,,,,,,,,,,,,,,,,,,,,290.0712891,290.0712891,25.43466568,25.43466568,49.71939011,5.763536724,7.717113495,68,1,64,0,0,0.3150177,32.25806427,2,1,1,290.0712891,0,290.0712891,,,,,,,,,,,,,,,,,,,,,,,,,,,,,,,,,
,3864046477,300.0017395,25.30930901,1.79E-05,1.97E-08,1,5,14.00089645,5.010262886,36.88000143,0.023402758,0.003497964,1,-2.76E-08,,,,,,,,,,,,,,,,,,,,,300.0017395,300.0017395,25.30930901,25.30930901,49.73111454,5.76188713,8.319962502,70,1,0,0,1,0.324478149,29.81427193,1,1,1,300.0017395,0,300.0017395,,,,,,,,,,,,,,,,,,,,,,,,,,,,,,,,,
,3864046574,289.9667053,25.30930901,1.80E-05,8.64E-08,1,5,14.00089645,5.010274815,36.81999817,0.023574108,0.003580234,1,1.45E-08,,,,,,,,,,,,,,,,,,,,,289.9667053,289.9667053,25.30930901,25.30930901,49.73502268,5.762370048,8.374207497,70,1,0,0,1,0.326843262,32.74682236,2,1,1,289.9667053,0,289.9667053,,,,,,,,,,,,,,,,,,,,,,,,,,,,,,,,,
,3864046652,274.975708,25.30930901,1.81E-05,2.12E-08,1,5,14.00089645,5.010179564,36.74999997,0.023654711,0.003510582,1,-4.66E-08,,,,,,,,,,,,,,,,,,,,,274.975708,274.975708,25.30930901,25.30930901,49.72173499,5.762057952,8.254857063,69,1,64,0,0,0.327377319,32.25806427,2,1,1,274.975708,0,274.975708,,,,,,,,,,,,,,,,,,,,,,,,,,,,,,,,,
,3864046746,259.9636841,25.30930901,1.82E-05,3.15E-08,1,5,14.00089645,5.010316598,36.66999936,0.023780325,0.003550829,1,-3.07E-08,,,,,,,,,,,,,,,,,,,,,259.9636841,259.9636841,25.30930901,25.30930901,49.75690828,5.763628954,8.166045189,70,1,0,0,1,0.327377319,32.74682236,2,1,1,259.9636841,0,259.9636841,,,,,,,,,,,,,,,,,,,,,,,,,,,,,,,,,
,3864046834,244.9544678,25.30930901,1.84E-05,9.11E-08,1,5,14.00089645,5.010069039,36.60999984,0.024024832,0.00359211,1,-2.75E-08,,,,,,,,,,,,,,,,,,,,,244.9544678,244.9544678,25.30930901,25.30930901,49.71899929,5.762621911,8.10219574,69,1,64,0,0,0.327453613,32.74682236,2,1,1,244.9544678,0,244.9544678,,,,,,,,,,,,,,,,,,,,,,,,,,,,,,,,,
,3864046925,229.9877014,25.30930901,1.82E-05,3.12E-08,1,5,14.00089645,5.010241908,36.55999899,0.023817007,0.003611217,1,1.03E-08,,,,,,,,,,,,,,,,,,,,,229.9877014,229.9877014,25.30930901,25.30930901,49.76785108,5.760432927,8.047798157,69,1,64,0,0,0.323867798,32.74682236,2,1,1,229.9877014,0,229.9877014,,,,,,,,,,,,,,,,,,,,,,,,,,,,,,,,,
,3864047014,214.977066,25.30930901,1.82E-05,8.44E-08,1,5,14.00089645,5.010673807,36.49000078,0.023804954,0.00363631,1,3.04E-08,,,,,,,,,,,,,,,,,,,,,214.977066,214.977066,25.30930901,25.30930901,49.76237968,5.75908461,7.998851299,68,1,64,0,0,0.328216553,30.79179001,2,1,1,214.977066,0,214.977066,,,,,,,,,,,,,,,,,,,,,,,,,,,,,,,,,
,3864047104,199.9927063,25.30930901,1.81E-05,2.45E-08,1,5,14.00089645,5.01073035,36.44999862,0.023698406,0.00354439,1,-2.63E-08,,,,,,,,,,,,,,,,,,,,,199.9927063,199.9927063,25.30930901,25.30930901,49.66780263,5.758485778,7.947873116,70,1,0,0,1,0.329437256,32.25806427,2,1,1,199.9927063,0,199.9927063,,,,,,,,,,,,,,,,,,,,,,,,,,,,,,,,,
,3864047195,184.9631042,25.30930901,1.79E-05,2.61E-08,1,5,14.00089645,5.010839102,36.38999909,0.023430081,0.003540275,1,9.31E-10,,,,,,,,,,,,,,,,,,,,,184.9631042,184.9631042,25.30930901,25.30930901,49.71782685,5.758861795,7.890200615,70,1,0,0,1,0.329208374,32.25806427,2,1,1,184.9631042,0,184.9631042,,,,,,,,,,,,,,,,,,,,,,,,,,,,,,,,,
,3864047285,169.9743195,25.30930901,1.76E-05,4.04E-08,1,5,14.00089645,5.010717307,36.35000065,0.022977018,0.003467254,1,-2.50E-09,,,,,,,,,,,,,,,,,,,,,169.9743195,169.9743195,25.30930901,25.30930901,49.79169075,5.758637136,7.846246243,69,1,64,0,0,0.327529907,31.76930618,2,1,1,169.9743195,0,169.9743195,,,,,,,,,,,,,,,,,,,,,,,,,,,,,,,,,
,3864047374,154.9544373,25.30930901,1.72E-05,1.86E-08,1,5,14.00089645,5.010864199,36.29000112,0.022473409,0.003341608,1,-3.95E-08,,,,,,,,,,,,,,,,,,,,,154.9544373,154.9544373,25.30930901,25.30930901,49.68851578,5.757849202,7.795179844,70,1,0,0,1,0.32875061,31.76930618,2,1,1,154.9544373,0,154.9544373,,,,,,,,,,,,,,,,,,,,,,,,,,,,,,,,,
,3864047464,139.9777832,25.30930901,1.65E-05,1.33E-08,1,5,14.00089645,5.010720098,36.26000136,0.021622495,0.003245212,1,-1.55E-08,,,,,,,,,,,,,,,,,,,,,139.9777832,139.9777832,25.30930901,25.30930901,49.67327403,5.759007935,7.744871616,70,1,0,0,1,0.326385498,32.74682236,2,1,1,139.9777832,0,139.9777832,,,,,,,,,,,,,,,,,,,,,,,,,,,,,,,,,
,3864047553,124.9941635,25.30930901,1.55E-05,1.61E-08,1,5,14.00089645,5.010654513,36.21000051,0.020312097,0.00304347,1,-1.84E-08,,,,,,,,,,,,,,,,,,,,,124.9941635,124.9941635,25.30930901,25.30930901,49.66858425,5.75890752,7.702309132,70,1,0,0,1,0.328903198,32.25806427,2,1,1,124.9941635,0,124.9941635,,,,,,,,,,,,,,,,,,,,,,,,,,,,,,,,,
,3864047644,109.9944,25.30930901,1.33E-05,1.48E-08,1,5,14.00089645,5.010716805,36.18000075,0.017372689,0.002591169,1,-2.46E-08,,,,,,,,,,,,,,,,,,,,,109.9944,109.9944,25.30930901,25.30930901,49.64826191,5.757765006,7.649773598,70,1,0,0,1,0.326309204,32.74682236,2,1,1,109.9944,0,109.9944,,,,,,,,,,,,,,,,,,,,,,,,,,,,,,,,,
,3864047734,94.96463776,25.30930901,1.12E-05,1.45E-08,1,5,14.00089645,5.01060984,36.12999991,0.014653502,0.002193499,1,-1.48E-08,,,,,,,,,,,,,,,,,,,,,94.96463776,94.96463776,25.30930901,25.30930901,49.75104606,5.758732977,7.575345516,69,1,64,0,0,0.329284668,32.25806427,2,1,1,94.96463776,0,94.96463776,,,,,,,,,,,,,,,,,,,,,,,,,,,,,,,,,
,3864047823,79.97657776,25.30930901,1.08E-05,1.16E-08,1,5,14.00089645,5.010509954,36.09000146,0.014133588,0.00211845,1,-1.22E-08,,,,,,,,,,,,,,,,,,,,,79.97657776,79.97657776,25.30930901,25.30930901,49.68851578,5.758601552,7.500906944,70,1,0,0,1,0.330047607,32.74682236,2,1,1,79.97657776,0,79.97657776,,,,,,,,,,,,,,,,,,,,,,,,,,,,,,,,,
,3864047911,64.97941589,25.30930901,1.07E-05,2.63E-08,1,5,14.00089645,5.010355526,36.0499993,0.014033784,0.002094755,1,-1.87E-08,,,,,,,,,,,,,,,,,,,,,64.97941589,64.97941589,25.30930901,25.30930901,49.69046985,5.759404422,7.398816109,70,1,0,0,1,0.327224731,32.25806427,2,1,1,64.97941589,0,64.97941589,,,,,,,,,,,,,,,,,,,,,,,,,,,,,,,,,
,3864047999,49.99588776,25.30930901,1.06E-05,1.35E-08,1,5,14.00089645,5.010106735,36.02999821,0.013892928,0.002063533,1,-2.61E-08,,,,,,,,,,,,,,,,,,,,,49.99588776,49.99588776,25.30930901,25.30930901,49.71001057,5.760321681,7.24824667,70,1,0,0,1,0.329666138,32.74682236,2,1,1,49.99588776,0,49.99588776,,,,,,,,,,,,,,,,,,,,,,,,,,,,,,,,,
,3864048086,34.97075653,25.30930901,1.07E-05,8.74E-08,1,5,14.00089645,5.009931895,35.98999977,0.014035681,0.002188886,1,5.14E-08,,,,,,,,,,,,,,,,,,,,,34.97075653,34.97075653,25.30930901,25.30930901,49.67366484,5.760820733,7.008786201,70,1,0,0,1,0.326843262,32.74682236,2,1,1,34.97075653,0,34.97075653,,,,,,,,,,,,,,,,,,,,,,,,,,,,,,,,,
,3864048174,19.93945122,25.30930901,1.05E-05,5.67E-08,1,5,14.00089645,5.00965685,35.96999869,0.013763172,0.002052277,1,-1.99E-08,,,,,,,,,,,,,,,,,,,,,19.93945122,19.93945122,25.30930901,25.30930901,49.70180347,5.761967137,6.527299404,70,1,0,0,1,0.324859619,33.23558426,2,1,1,19.93945122,0,19.93945122,,,,,,,,,,,,,,,,,,,,,,,,,,,,,,,,,
,3864048401,9.998781204,25.30930901,1.04E-05,1.49E-08,1,5,14.00089645,5.008759053,35.95000133,0.013612909,0.002039105,1,-1.28E-08,,,,,,,,,,,,,,,,,,,,,9.998781204,9.998781204,25.30930901,25.30930901,49.70180347,5.766349712,5.181285858,70,1,0,0,1,0.320968628,32.74682236,1,1,1,9.998781204,0,9.998781204,,,,,,,,,,,,,,,,,,,,,,,,,,,,,,,,,
,3864048469,20.03375435,25.30930901,1.05E-05,1.47E-08,1,5,14.00089645,5.008720065,35.95000133,0.013786502,0.002058587,1,-1.78E-08,,,,,,,,,,,,,,,,,,,,,20.03375435,20.03375435,25.30930901,25.30930901,49.78739179,5.766656532,5.891755581,70,1,0,0,1,0.32081604,33.23558426,2,1,1,20.03375435,0,20.03375435,,,,,,,,,,,,,,,,,,,,,,,,,,,,,,,,,
,3864048566,35.0487709,25.30930901,1.06E-05,1.69E-08,1,5,14.00089645,5.00931805,35.96000001,0.013882804,0.002083642,1,-9.94E-09,,,,,,,,,,,,,,,,,,,,,35.0487709,35.0487709,25.30930901,25.30930901,49.89564734,5.76289468,6.418192863,70,1,0,0,1,0.327301025,32.25806427,2,1,1,35.0487709,0,35.0487709,,,,,,,,,,,,,,,,,,,,,,,,,,,,,,,,,
,3864048662,50.08143997,25.30930901,1.06E-05,1.56E-08,1,5,14.00089645,5.009021011,35.96999869,0.013921218,0.00208253,1,-1.51E-08,,,,,,,,,,,,,,,,,,,,,50.08143997,50.08143997,25.30930901,25.30930901,49.61347944,5.765187129,6.67284584,70,1,0,0,1,0.321273804,35.67937469,2,1,1,50.08143997,0,50.08143997,,,,,,,,,,,,,,,,,,,,,,,,,,,,,,,,,
,3864048757,65.06154633,25.30930901,1.07E-05,1.45E-08,1,5,14.00089645,5.008275429,35.98000109,0.013939762,0.002082814,1,-1.70E-08,,,,,,,,,,,,,,,,,,,,,65.06154633,65.06154633,25.30930901,25.30930901,49.66115878,5.769058402,6.840017796,70,1,0,0,1,0.328063965,32.25806427,2,1,1,65.06154633,0,65.06154633,,,,,,,,,,,,,,,,,,,,,,,,,,,,,,,,,
,3864048850,80.03244781,25.30930901,1.06E-05,1.26E-08,1,5,14.00089645,5.008220221,36.01000085,0.013911185,0.002080643,1,-1.54E-08,,,,,,,,,,,,,,,,,,,,,80.03244781,80.03244781,25.30930901,25.30930901,49.64318133,5.769156481,6.99212265,70,1,0,0,1,0.336303711,32.74682236,2,1,1,80.03244781,0,80.03244781,,,,,,,,,,,,,,,,,,,,,,,,,,,,,,,,,
,3864048942,95.08360291,25.30930901,1.10E-05,1.68E-08,1,5,14.00089645,5.008013359,36.04000062,0.014351152,0.002138738,1,-2.16E-08,,,,,,,,,,,,,,,,,,,,,95.08360291,95.08360291,25.30930901,25.30930901,49.73111454,5.768905532,7.082537651,70,1,0,0,1,0.328979492,32.25806427,2,1,1,95.08360291,0,95.08360291,,,,,,,,,,,,,,,,,,,,,,,,,,,,,,,,,
,3864049033,110.0389786,25.30930901,1.24E-05,3.66E-08,1,5,14.00089645,5.00788662,36.07000038,0.016278882,0.002428553,1,-2.27E-08,,,,,,,,,,,,,,,,,,,,,110.0389786,110.0389786,25.30930901,25.30930901,49.61426107,5.770400924,7.147265434,70,1,0,0,1,0.329208374,32.25806427,2,1,1,110.0389786,0,110.0389786,,,,,,,,,,,,,,,,,,,,,,,,,,,,,,,,,
,3864049124,125.0332565,25.30930901,1.35E-05,7.90E-08,1,5,14.00089645,5.007983232,36.10999882,0.017708341,0.002581325,1,-6.99E-08,,,,,,,,,,,,,,,,,,,,,125.0332565,125.0332565,25.30930901,25.30930901,49.68499845,5.77010691,7.195524216,68,1,64,0,0,0.324020386,32.74682236,2,1,1,125.0332565,0,125.0332565,,,,,,,,,,,,,,,,,,,,,,,,,,,,,,,,,
,3864049215,140.0819855,25.30930901,1.39E-05,8.88E-08,1,5,14.00089645,5.007869089,36.15000099,0.018158471,0.002897698,1,1.16E-07,,,,,,,,,,,,,,,,,,,,,140.0819855,140.0819855,25.30930901,25.30930901,49.77332248,5.771183379,7.241455555,69,1,64,0,0,0.321807861,32.74682236,2,1,1,140.0819855,0,140.0819855,,,,,,,,,,,,,,,,,,,,,,,,,,,,,,,,,
,3864049305,155.006958,25.30930901,1.39E-05,2.58E-08,1,5,14.00089645,5.007546821,36.20000184,0.018160441,0.002708458,1,-2.59E-08,,,,,,,,,,,,,,,,,,,,,155.006958,155.006958,25.30930901,25.30930901,49.70141265,5.772245632,7.276576042,68,1,64,0,0,0.328445435,32.74682236,2,1,1,155.006958,0,155.006958,,,,,,,,,,,,,,,,,,,,,,,,,,,,,,,,,
,3864049395,170.0339966,25.30930901,1.40E-05,2.57E-08,1,5,14.00089645,5.007845372,36.24999896,0.018252075,0.002727031,1,-2.23E-08,,,,,,,,,,,,,,,,,,,,,170.0170135,170.0509796,25.30930901,25.30930901,49.73345942,5.770668636,7.311429024,70,1,0,0,1,0.319671631,32.74682236,2,1,1,170.0509796,0,170.0339966,,,,,,,,,,,,,,,,,,,,,,,,,,,,,,,,,
,3864049488,185.315033,25.30930901,1.40E-05,3.38E-08,1,5,14.00089645,5.008665179,36.30999848,0.018332752,0.002775571,1,4.84E-09,,,,,,,,,,,,,,,,,,,,,185.315033,185.315033,25.30930901,25.30930901,49.72017174,5.765868105,7.350675106,68,1,64,0,0,0.32661438,32.25806427,2,1,1,185.315033,0,185.315033,,,,,,,,,,,,,,,,,,,,,,,,,,,,,,,,,
,3864049576,200.0227661,25.30930901,1.42E-05,9.16E-08,1,5,14.00089645,5.008784932,36.35999933,0.018594188,0.002781219,1,-2.05E-08,,,,,,,,,,,,,,,,,,,,,200.0227661,200.0227661,25.30930901,25.30930901,49.72916046,5.767218231,7.388588428,69,1,64,0,0,0.320968628,31.2805481,2,1,1,200.0227661,0,200.0227661,,,,,,,,,,,,,,,,,,,,,,,,,,,,,,,,,
,3864049667,215.0014343,25.30930901,1.39E-05,2.67E-08,1,5,14.00089645,5.008621414,36.43000126,0.018244978,0.002719406,1,-2.72E-08,,,,,,,,,,,,,,,,,,,,,215.0014343,215.0014343,25.30930901,25.30930901,49.7686327,5.76785946,7.442417622,68,1,64,0,0,0.321884155,32.74682236,2,1,1,215.0014343,0,215.0014343,,,,,,,,,,,,,,,,,,,,,,,,,,,,,,,,,
,3864049757,230.0294037,25.30930901,1.39E-05,1.31E-08,1,5,14.00089645,5.008554801,36.49999946,0.018186055,0.002716723,1,-2.26E-08,,,,,,,,,,,,,,,,,,,,,230.0294037,230.0294037,25.30930901,25.30930901,49.79989785,5.76829417,7.522509575,69,1,64,0,0,0.328216553,32.25806427,2,1,1,230.0294037,0,230.0294037,,,,,,,,,,,,,,,,,,,,,,,,,,,,,,,,,
,3864049848,245.0171967,25.30930901,1.38E-05,1.27E-08,1,5,14.00089645,5.008583726,36.58000007,0.018091568,0.002701052,1,-2.36E-08,,,,,,,,,,,,,,,,,,,,,245.0171967,245.0171967,25.30930901,25.30930901,49.66858425,5.768096268,7.61092329,69,1,64,0,0,0.328903198,32.25806427,2,1,1,245.0171967,0,245.0171967,,,,,,,,,,,,,,,,,,,,,,,,,,,,,,,,,
,3864049938,260.0413818,25.30930901,1.37E-05,1.21E-08,1,5,14.00089645,5.008782981,36.66000068,0.017958119,0.002691549,1,-1.57E-08,,,,,,,,,,,,,,,,,,,,,260.0413818,260.0413818,25.30930901,25.30930901,49.70571161,5.766182957,7.795081139,68,1,64,0,0,0.322113037,33.72434235,2,1,1,260.0413818,0,260.0413818,,,,,,,,,,,,,,,,,,,,,,,,,,,,,,,,,
,3864050028,275.0010376,25.30930901,1.36E-05,1.09E-08,1,5,14.00089645,5.009142143,36.74000129,0.01782749,0.002657943,1,-2.60E-08,,,,,,,,,,,,,,,,,,,,,275.0010376,275.0010376,25.30930901,25.30930901,49.75534502,5.766313563,7.803183079,69,1,64,0,0,0.322113037,32.74682236,2,1,1,275.0010376,0,275.0010376,,,,,,,,,,,,,,,,,,,,,,,,,,,,,,,,,
,3864050118,290.0490417,25.30930901,1.35E-05,1.08E-08,1,5,14.00089645,5.009357981,36.83000058,0.017648231,0.002621352,1,-3.31E-08,,,,,,,,,,,,,,,,,,,,,290.0490417,290.0490417,25.30930901,25.30930901,49.73658594,5.765898448,7.746709824,68,1,64,0,0,0.333328247,32.74682236,2,1,1,290.0490417,0,290.0490417,,,,,,,,,,,,,,,,,,,,,,,,,,,,,,,,,
,3864051361,9.998124599,25.30930901,,,5,,,,35.96000001,,,,,7.13E-06,3.64E-08,0.26632469,0.004483249,2.38E-06,1.21E-08,2.38E-06,5.84E-09,1.10E-08,1.07E-08,2.999999989,1.000576377,19.9884791,20,1,3,0.02509074,0.000421684,0.000312793,277.7528458,9.99442482,10.00049305,25.30930901,25.30930901,,,5.232172966,,1,,,,,,1,1,1,9.997039795,0,9.998485034,,,,,,,,,,,,,,,,,,,,,,,,,,,,,,,,,
,3864051742,20.00018978,25.30930901,,,5,,,,35.96000001,,,,,3.83E-06,5.10E-08,0.013109079,0.010155773,1.28E-06,1.70E-08,1.28E-06,1.10E-08,2.92E-10,1.30E-08,2.99999998,1.000576377,19.9884791,20,1,3,0.013482872,0.000166974,0.000291281,282.0829926,19.99966621,20.00050163,25.30930901,25.30930901,,,5.96999073,,1,,,,,,1,1,1,20.00027275,0,20.00006571,,,,,,,,,,,,,,,,,,,,,,,,,,,,,,,,,
,3864052122,30.00015926,25.30930901,,,5,,,,35.96000001,,,,,2.59E-06,3.97E-08,0.331589275,0.011590458,8.62E-07,1.32E-08,8.62E-07,8.67E-09,4.99E-09,9.99E-09,2.999999964,1.000576377,19.9884791,20,1,3,0.009101768,0.000163287,0.000308847,270.4961929,29.99975777,30.0034008,25.30930901,25.30930901,,,6.292892933,,1,,,,,,1,1,1,29.99994087,0,30.00054674,,,,,,,,,,,,,,,,,,,,,,,,,,,,,,,,,
,3864052507,39.99994087,25.30930901,,,5,,,,35.96999869,,,,,1.97E-06,4.89E-08,0.974848133,0.019190094,6.55E-07,1.63E-08,6.55E-07,1.04E-08,1.11E-08,1.26E-08,2.999999945,1.000576377,19.9884791,20,1,3,0.006913423,0.000201655,0.000202824,258.5311813,39.99946213,40.00052643,25.30930901,25.30930901,,,6.518979073,,1,,,,,,1,1,1,40.00000763,0,39.99999034,,,,,,,,,,,,,,,,,,,,,,,,,,,,,,,,,
,3864052900,50.00017929,25.30930901,,,5,,,,35.98000109,,,,,1.63E-06,4.88E-08,0.187633354,0.017978923,5.42E-07,1.63E-08,5.42E-07,1.30E-08,1.78E-09,9.75E-09,2.999999928,1.000576377,19.9884791,20,1,3,0.005723445,8.83E-05,0.000394987,259.237793,49.9981308,50.00067139,25.30930901,25.30930901,,,6.690667629,,1,,,,,,1,1,1,50.00040054,0,49.99985009,,,,,,,,,,,,,,,,,,,,,,,,,,,,,,,,,
,3864053293,59.99949074,25.30930901,,,5,,,,35.98999977,,,,,1.33E-06,4.58E-08,-0.602101318,0.026260916,4.45E-07,1.53E-08,4.45E-07,9.83E-09,-4.67E-09,1.17E-08,2.999999906,1.000576377,19.9884791,20,1,3,0.004693725,7.67E-06,3.72E-05,235.9284821,59.99285889,60.00058746,25.30930901,25.30930901,,,6.812585354,,1,,,,,,1,1,1,60.00007629,0,59.9989598,,,,,,,,,,,,,,,,,,,,,,,,,,,,,,,,,
,3864053696,69.9991188,25.30930901,,,5,,,,35.99999845,,,,,1.09E-06,5.58E-08,-3.326857708,0.042440472,3.63E-07,1.86E-08,3.63E-07,1.04E-08,-2.11E-08,1.54E-08,3.000000124,1.000576377,19.9884791,20,1,3,0.003830726,-0.000176043,0.000300172,250.3751297,69.98390961,70.00036621,25.30930901,25.30930901,,,6.893264771,,1,,,,,,1,1,1,70.00006104,0,69.99746119,,,,,,,,,,,,,,,,,,,,,,,,,,,,,,,,,
,3864054101,79.99776077,25.30930901,,,5,,,,36.01999953,,,,,9.07E-07,4.45E-08,0.13573509,0.027314118,3.02E-07,1.48E-08,3.02E-07,1.23E-08,7.16E-10,8.26E-09,3.000000099,1.000576377,19.9884791,20,1,3,0.003192988,4.63E-05,0.000216046,287.2700806,79.97499847,80.00039673,25.30930901,25.30930901,,,6.945604324,,1,,,,,,1,1,1,79.99919128,0,79.99550938,,,,,,,,,,,,,,,,,,,,,,,,,,,,,,,,,
,3864054514,89.99706268,25.30930901,,,5,,,,36.02999821,,,,,8.61E-07,4.00E-08,-1.309570135,0.029011094,2.87E-07,1.33E-08,2.87E-07,1.04E-08,-6.56E-09,8.33E-09,3.000000075,1.000576377,19.9884791,20,1,3,0.003030517,-3.25E-05,0.000397171,250.3904724,89.96637726,90.00035858,25.30930901,25.30930901,,,6.997634888,,1,,,,,,1,1,1,89.99863434,0,89.99362705,,,,,,,,,,,,,,,,,,,,,,,,,,,,,,,,,
,3864054917,99.9933815,25.30930901,,,5,,,,36.0499993,,,,,7.96E-07,4.59E-08,0.463814573,0.048806562,2.65E-07,1.53E-08,2.65E-07,8.13E-09,2.15E-09,1.30E-08,3.000000039,1.000576377,19.9884791,20,1,3,0.002801491,5.67E-05,0.00031638,262.173111,99.95620728,99.99963379,25.30930901,25.30930901,,,7.041715145,,1,,,,,,1,1,1,99.99671936,0,99.98995865,,,,,,,,,,,,,,,,,,,,,,,,,,,,,,,,,
,3864055317,109.9904976,25.30930901,,,5,,,,36.07999906,,,,,7.28E-07,5.12E-08,-1.709352655,0.046232375,2.43E-07,1.71E-08,2.43E-07,1.28E-08,-7.24E-09,1.12E-08,3.000000006,1.000576377,19.9884791,20,1,3,0.002561517,-4.53E-05,0.000191284,257.3822632,109.9514236,109.9990921,25.30930901,25.30930901,,,7.080485344,,1,,,,,,1,1,1,109.9947052,0,109.988173,,,,,,,,,,,,,,,,,,,,,,,,,,,,,,,,,
,3864055731,119.9931755,25.30930901,,,5,,,,36.10000014,,,,,6.44E-07,8.43E-08,-0.95235775,0.122601353,2.15E-07,2.81E-08,2.15E-07,9.87E-09,-3.57E-09,2.63E-08,2.999999991,1.000576377,19.9884791,20,1,3,0.002267032,-1.02E-05,0.000400826,254.1647491,119.9483414,119.9994812,25.30930901,25.30930901,,,7.112790108,,1,,,,,,1,1,1,119.9964752,0,119.9878894,,,,,,,,,,,,,,,,,,,,,,,,,,,,,,,,,
,3864056140,129.9903793,25.30930901,,,5,,,,36.12999991,,,,,6.32E-07,3.40E-08,-0.63832069,0.039564371,2.11E-07,1.13E-08,2.11E-07,7.65E-09,-2.35E-09,8.34E-09,2.999999957,1.000576377,19.9884791,20,1,3,0.002225078,2.22E-06,0.000250289,280.3589478,129.9411774,129.9993286,25.30930901,25.30930901,,,7.142370701,,1,,,,,,1,1,1,129.994751,0,129.9855056,,,,,,,,,,,,,,,,,,,,,,,,,,,,,,,,,
,3864056545,139.9882431,25.30930901,,,5,,,,36.15000099,,,,,6.04E-07,6.48E-08,4.30115301,0.083458556,2.01E-07,2.16E-08,2.01E-07,1.35E-08,1.51E-08,1.68E-08,2.999999923,1.000576377,19.9884791,20,1,3,0.002117711,0.000185153,0.000260618,280.5797195,139.9393921,139.9996796,25.30930901,25.30930901,,,7.179395199,,1,,,,,,1,1,1,139.9934082,0,139.9848393,,,,,,,,,,,,,,,,,,,,,,,,,,,,,,,,,
,3864056947,149.9849319,25.30930901,,,5,,,,36.18000075,,,,,4.57E-07,5.88E-08,5.619640744,0.09858809,1.52E-07,1.96E-08,1.52E-07,1.26E-08,1.49E-08,1.50E-08,3.000000124,1.000576377,19.9884791,20,1,3,0.001598451,0.000176899,0.000346502,277.3910522,149.9361115,149.9993744,25.30930901,25.30930901,,,7.201613903,,1,,,,,,1,1,1,149.9915619,0,149.9828477,,,,,,,,,,,,,,,,,,,,,,,,,,,,,,,,,
,3864057363,159.9906616,25.30930901,,,5,,,,36.21999919,,,,,4.45E-07,6.67E-08,-2.783694642,0.116632059,1.48E-07,2.22E-08,1.48E-07,1.40E-08,-7.20E-09,1.73E-08,3.000000117,1.000576377,19.9884791,20,1,3,0.001563917,-5.70E-05,0.000308495,262.2326965,159.9355774,160.0003204,25.30930901,25.30930901,,,7.231137753,,1,,,,,,1,1,1,159.9955444,0,159.9844267,,,,,,,,,,,,,,,,,,,,,,,,,,,,,,,,,
,3864057779,169.9897461,25.30930901,,,5,,,,36.24999896,,,,,4.35E-07,3.77E-08,2.907635041,0.061800052,1.45E-07,1.26E-08,1.45E-07,8.81E-09,7.36E-09,8.96E-09,3.000000086,1.000576377,19.9884791,20,1,3,0.001527998,9.62E-05,8.54E-05,261.4333954,169.931778,169.9998779,25.30930901,25.30930901,,,7.262396336,,1,,,,,,1,1,1,169.9953308,0,169.98295,,,,,,,,,,,,,,,,,,,,,,,,,,,,,,,,,
,3864058187,179.9851913,25.30930901,,,5,,,,36.29000112,,,,,3.91E-07,6.26E-08,-3.645901312,0.144090286,1.30E-07,2.09E-08,1.30E-07,9.03E-09,-8.29E-09,1.88E-08,3.000000041,1.000576377,19.9884791,20,1,3,0.001374763,-7.09E-05,0.000151072,247.4436798,179.9294281,180.0000763,25.30930901,25.30930901,,,7.286770821,,1,,,,,,1,1,1,179.9916534,0,179.981514,,,,,,,,,,,,,,,,,,,,,,,,,,,,,,,,,
,3864058596,189.9856415,25.30930901,,,5,,,,36.32999957,,,,,3.93E-07,3.62E-08,5.664002821,0.060577452,1.31E-07,1.21E-08,1.30E-07,9.12E-09,1.29E-08,7.92E-09,3.000000012,1.000576377,19.9884791,20,1,3,0.001374577,0.0001532,0.000190708,266.0453873,189.9286194,190.0004272,25.30930901,25.30930901,,,7.310596943,,1,,,,,,1,1,1,189.993103,0,189.9819842,,,,,,,,,,,,,,,,,,,,,,,,,,,,,,,,,
,3864059009,199.986496,25.30930901,,,5,,,,36.37000173,,,,,3.58E-07,3.63E-08,-6.586713102,0.056425177,1.19E-07,1.21E-08,1.18E-07,1.01E-08,-1.37E-08,6.68E-09,2.999999985,1.000576377,19.9884791,20,1,3,0.001252139,-0.000129202,8.79E-05,276.6728592,199.9264679,200.0007477,25.30930901,25.30930901,,,7.337408066,,1,,,,,,1,1,1,199.9939728,0,199.9814467,,,,,,,,,,,,,,,,,,,,,,,,,,,,,,,,,
,3864059416,209.9836502,25.30930901,,,5,,,,36.41000018,,,,,2.90E-07,6.73E-08,-2.747076028,0.134770225,9.66E-08,2.24E-08,9.65E-08,1.83E-08,-4.63E-09,1.30E-08,3.000000182,1.000576377,19.9884791,20,1,3,0.001019554,-3.65E-05,0.000456362,255.7434921,209.9239655,210.0014648,25.30930901,25.30930901,,,7.376992226,,1,,,,,,1,1,1,209.9913635,0,209.9798513,,,,,,,,,,,,,,,,,,,,,,,,,,,,,,,,,
,3864059829,219.9859238,25.30930901,,,5,,,,36.44999862,,,,,3.44E-07,5.83E-08,7.0389047,0.151987398,1.15E-07,1.94E-08,1.14E-07,8.33E-09,1.41E-08,1.76E-08,2.999999919,1.000576377,19.9884791,20,1,3,0.001200234,0.000163012,0.000339272,283.6574478,219.9203644,220.0016174,25.30930901,25.30930901,,,7.43268919,,1,,,,,,1,1,1,219.9938507,0,219.9798763,,,,,,,,,,,,,,,,,,,,,,,,,,,,,,,,,
,3864060242,229.9827805,25.30930901,,,5,,,,36.49999946,,,,,3.43E-07,4.64E-08,-3.158123137,0.11118889,1.14E-07,1.55E-08,1.14E-07,8.78E-09,-6.30E-09,1.27E-08,3.000000114,1.000576377,19.9884791,20,1,3,0.001206155,-5.19E-05,6.53E-05,284.083046,229.9250336,230.0019226,25.30930901,25.30930901,,,7.489100933,,1,,,,,,1,1,1,229.9905701,0,229.9798607,,,,,,,,,,,,,,,,,,,,,,,,,,,,,,,,,
,3864060653,239.9817581,25.30930901,,,5,,,,36.55000031,,,,,2.27E-07,6.24E-08,3.592929936,0.182946272,7.58E-08,2.08E-08,7.57E-08,1.55E-08,4.75E-09,1.39E-08,3.000000077,1.000576377,19.9884791,20,1,3,0.000798227,5.99E-05,0.000281791,285.5760727,239.9216461,240.0029602,25.30930901,25.30930901,,,7.563502312,,1,,,,,,1,1,1,239.9893188,0,239.9785146,,,,,,,,,,,,,,,,,,,,,,,,,,,,,,,,,
,3864061070,249.9824371,25.30930901,,,5,,,,36.60000116,,,,,2.66E-07,4.92E-08,-1.208057865,0.137980927,8.87E-08,1.64E-08,8.87E-08,1.09E-08,-1.87E-09,1.22E-08,3.000000044,1.000576377,19.9884791,20,1,3,0.000937008,-8.38E-06,0.000303446,250.16819,249.9161987,250.0019836,25.30930901,25.30930901,,,7.682224274,,1,,,,,,1,1,1,249.9906769,0,249.978152,,,,,,,,,,,,,,,,,,,,,,,,,,,,,,,,,
,3864061477,259.9788818,25.30930901,,,5,,,,36.64999828,,,,,2.90E-07,7.30E-08,-8.843103095,0.228229571,9.68E-08,2.43E-08,9.57E-08,9.81E-09,-1.49E-08,2.23E-08,2.999999996,1.000576377,19.9884791,20,1,3,0.001011853,-0.000144867,0.000455173,257.2784424,259.9203186,259.9997559,25.30930901,25.30930901,,,7.919474602,,1,,,,,,1,1,1,259.9874268,0,259.9775003,,,,,,,,,,,,,,,,,,,,,,,,,,,,,,,,,
,3864061897,269.9851685,25.30930901,,,5,,,,36.71000153,,,,,2.32E-07,5.06E-08,8.267319586,0.185957696,7.72E-08,1.69E-08,7.64E-08,8.69E-09,1.11E-08,1.45E-08,2.999999982,1.000576377,19.9884791,20,1,3,0.000805044,0.00012697,0.000417766,253.6176453,269.9193115,270.0016479,25.30930901,25.30930901,,,8.003177643,,1,,,,,,1,1,1,269.9927673,0,269.9787913,,,,,,,,,,,,,,,,,,,,,,,,,,,,,,,,,
,3864062318,279.9845428,25.30930901,,,5,,,,36.77000105,,,,,2.28E-07,4.80E-08,-4.115222646,0.113075458,7.58E-08,1.60E-08,7.56E-08,1.35E-08,-5.44E-09,8.55E-09,3.000000181,1.000576377,19.9884791,20,1,3,0.000799336,-4.78E-05,0.000409454,259.7251282,279.9207764,280.0016785,25.30930901,25.30930901,,,8.364383698,,1,,,,,,1,1,1,279.9909058,0,279.9790861,,,,,,,,,,,,,,,,,,,,,,,,,,,,,,,,,
,3864062724,289.9772034,25.30930901,,,5,,,,36.83000058,,,,,2.46E-07,5.10E-08,-0.755314494,0.157520006,8.20E-08,1.70E-08,8.20E-08,1.10E-08,-1.08E-09,1.29E-08,3.000000118,1.000576377,19.9884791,20,1,3,0.000866346,-9.05E-07,7.81E-05,267.8655624,289.9162292,289.9988708,25.30930901,25.30930901,,,8.576093674,,1,,,,,,1,1,1,289.984436,0,289.9759314,,,,,,,,,,,,,,,,,,,,,,,,,,,,,,,,,
,3864063128,299.9773254,25.30930901,,,5,,,,36.8900001,,,,,2.35E-07,6.02E-08,6.029627502,0.177377125,7.82E-08,2.01E-08,7.78E-08,1.45E-08,8.21E-09,1.39E-08,3.000000079,1.000576377,19.9884791,20,1,3,0.000819886,9.67E-05,0.000228332,255.3306808,299.9244385,299.997467,25.30930901,25.30930901,,,8.797883034,,1,,,,,,1,1,1,299.98526,0,299.9758002,,,,,,,,,,,,,,,,,,,,,,,,,,,,,,,,,
,3864063285,299.998764,25.30930901,,,5,,,,36.8900001,,,,,2.41E-07,4.70E-09,1.577597739,0.016142175,8.05E-08,1.57E-09,8.04E-08,8.72E-10,2.22E-09,1.30E-09,3.000288434,100.0576401,10,1000,1,3,0.000838394,0.000122086,0.012742775,197.6922607,299.9926147,300.0063782,25.30930901,25.30930901,,,8.742986679,,1,,,,,,1,1,1,299.9981995,0,299.9996387,,,,,,,,,,,,,,,,,,,,,,,,,,,,,,,,,