File: data/Rock_mag_data/MPMS3/DX1-4r-FC-ZFC-RT-SIRM-VSM-SWEEP_AC-3freq.dat
[Header]
; MPMS3 Data File (default extension .dat)
; Copyright (c) 2007, Quantum Design, Inc. All rights reserved.
TITLE,
FILEOPENTIME,3863683804.71845,06/06/2022,2:28 pm
BYAPP,MPMS3 w/ AC,1.0,1.1
INFO,MPMS3 Measurement Release 1.1.16 Build 424, MultiVu Release 2.3.4.19,APPNAME
INFO,Linear Motor Servo Controller,MOTOR_MODULE_NAME
INFO,3101-100 N2,MOTOR_HW_VERSION
INFO,,MOTOR_SERIAL_NUMBER
INFO,01.04.28,MOTOR_SOFTWARE_VERSION
INFO,Quantum Design Squid Module,SQUID_MODULE_NAME
INFO,3101-501 B0,SQUID_HW_VERSION
INFO,SQM327,SQUID_SERIAL_NUMBER
INFO,01.03.04,SQUID_SOFTWARE_VERSION
INFO,Quantum Design VSM Oven,OVEN_MODULE_NAME
INFO,3101-201 A3,OVEN_HW_VERSION
INFO,OVB365,OVEN_SERIAL_NUMBER
INFO,01.07.07,OVEN_SOFTWARE_VERSION
INFO,SQUID AC,AC_MODULE_NAME
INFO,3101-401 G0,AC_HW_VERSION
INFO,SAC220,AC_SERIAL_NUMBER
INFO,SQUID AC 00.95.07,AC_SOFTWARE_VERSION
INFO,TCI344,COIL_SERIAL_NUMBER
INFO,0,MOMENT_UNITS
INFO,DX1-4r,SAMPLE_MATERIAL
INFO,SSRM2022C,SAMPLE_COMMENT
INFO,,SAMPLE_MASS
INFO,,SAMPLE_VOLUME
INFO,,SAMPLE_MOLECULAR_WEIGHT
INFO,,SAMPLE_SIZE
INFO,,SAMPLE_SHAPE
INFO,Straw,SAMPLE_HOLDER
INFO,Standard,SAMPLE_HOLDER_DETAIL
INFO,66.04,SAMPLE_OFFSET
DATATYPE,COMMENT,1
DATATYPE,TIME,2
STARTUPAXIS,X,2
STARTUPAXIS,Y1,5
FIELDGROUP, VSM,2,3,4,5,6,8,9,10,11,14,15
FIELDGROUP, DC, 2,3,4,14,56,57,58,59,60,61,62,63,64,65,66,67,68,69
FIELDGROUP, AC, 2,3,4,11,16,17,18,19,20,21,22,23,24,25,26,27,28,29,30
STARTUPGROUP, All
[Data]
Comment,Time Stamp (sec),Temperature (K),Magnetic Field (Oe),Moment (emu),M. Std. Err. (emu),Transport Action,Averaging Time (sec),Frequency (Hz),Peak Amplitude (mm),Center Position (mm),Lockin Signal' (V),Lockin Signal (V),Range,M. Quad. Signal (emu),AC Moment (emu),AC M. Std Err. (emu),AC Phase (deg),AC Phase Std. Err. (deg),AC Susceptibility (emu/Oe),AC Suscept. Std Err. (emu/Oe),AC X' (emu/Oe),AC X' Std Err. (emu/Oe),AC X'' (emu/Oe),AC X'' Std Err. (emu/Oe),AC Drive (Oe),AC Frequency (Hz),AC Averaging Time (sec),AC Cycles,AC Range,AC Measure Type,AC Signal' (V),AC Signal'' (V),AC Trim Coil Ratio,AC Trim Coil Phase,Min. Temperature (K),Max. Temperature (K),Min. Field (Oe),Max. Field (Oe),Mass (grams),Motor Lag (deg),Pressure (Torr),Measure Count,Measurement Number,SQUID Status (code),Motor Status (code),Measure Status (code),Motor Current (amps),Motor Temp. (C),Temp. Status (code),Field Status (code),Chamber Status (code),Chamber Temp (K),Redirection State,Average Temp (K),Rotation Angle (deg),Rotator state,DC Moment Fixed Ctr (emu),DC Moment Err Fixed Ctr (emu),DC Moment Free Ctr (emu),DC Moment Err Free Ctr (emu),DC Fixed Fit,DC Free Fit,DC Calculated Center (mm),DC Calculated Center Err (mm),DC Scan Length (mm),DC Scan Time (s),DC Number of Points,DC Squid Drift,DC Min V (V),DC Max V (V),DC Scans per Measure,Map 01,Map 02,Map 03,Map 04,Map 05,Map 06,Map 07,Map 08,Map 09,Map 10,Map 11,Map 12,Map 13,Map 14,Map 15,Map 16
,3863686160.72733,10.0027704238892,25.2842388153076,4.55271283435918E-5,2.01336724179512E-8,1,5,12.9061126708984,5.00329560364866,34.8899997770786,0.0595024319245497,0.00872598146812751,1,-1.16674143414367E-8,,,,,,,,,,,,,,,,,,,,,10.0027704238892,10.0027704238892,25.2842388153076,25.2842388153076,50.2270578315149,5.43046603154853,4.95504665374756,65,1,0,0,1,0.2850341796875,30.3030319213867,1,1,1,10.0027704238892,0,10.0027704238892,,,,,,,,,,,,,,,,,,,,,,,,,,,,,,,,,
,3863686261.98762,25.0364017486572,25.2842388153076,2.79005975448195E-5,2.13147430457863E-8,1,5,12.9061126708984,4.99071384432329,34.8800010979176,0.0363386532472893,0.005315450447543,1,-1.73596827776763E-8,,,,,,,,,,,,,,,,,,,,,25.0364017486572,25.0364017486572,25.2842388153076,25.2842388153076,50.0734678274861,5.43737781292549,5.95705366134644,65,1,0,0,1,0.282974243164062,31.7693061828613,2,1,1,25.0364017486572,0,25.0364017486572,,,,,,,,,,,,,,,,,,,,,,,,,,,,,,,,,
,3863686390.31884,45.0002326965332,25.2842388153076,2.06431361304468E-5,9.08337418580936E-9,1,5,12.9061126708984,4.9971602700371,34.8899997770786,0.0269356757125622,0.00393539383043001,1,-1.6320085920858E-8,,,,,,,,,,,,,,,,,,,,,45.0002326965332,45.0002326965332,25.2842388153076,25.2842388153076,50.1363889232842,5.4119492701646,6.46270513534546,65,1,0,0,1,0.27618408203125,31.2805480957031,2,1,1,45.0002326965332,0,45.0002326965332,,,,,,,,,,,,,,,,,,,,,,,,,,,,,,,,,
,3863686516.82382,65.0009231567383,25.2842388153076,1.92928071319073E-5,3.65862892893634E-8,1,5,12.9061126708984,4.99314268356507,34.9199995398521,0.0251477102073415,0.00365784831621716,1,-2.7510636709499E-8,,,,,,,,,,,,,,,,,,,,,65.0009231567383,65.0009231567383,25.2842388153076,25.2842388153076,50.1184114673418,5.42580095281287,6.70704650878906,63,1,64,0,0,0.28045654296875,31.2805480957031,2,1,1,65.0009231567383,0,65.0009231567383,,,,,,,,,,,,,,,,,,,,,,,,,,,,,,,,,
,3863686641.65852,85.0139541625977,25.2842388153076,1.79843805536032E-5,1.56493759198344E-8,1,5,12.9061126708984,4.9915409883523,34.9499993026257,0.0234307008689758,0.00341477129742225,1,-2.0631725615098E-8,,,,,,,,,,,,,,,,,,,,,85.0139541625977,85.0139541625977,25.2842388153076,25.2842388153076,50.0425935009765,5.43320818775419,6.869469165802,65,1,0,0,1,0.278472900390625,31.7693061828613,2,1,1,85.0139541625977,0,85.0139541625977,,,,,,,,,,,,,,,,,,,,,,,,,,,,,,,,,
,3863686763.76831,105.121559143066,25.2842388153076,1.49268168676549E-5,9.30082936430951E-9,1,5,12.9061126708984,4.99189420621466,34.9900014698505,0.0194469052271549,0.00284962328592964,1,-5.51527385116677E-9,,,,,,,,,,,,,,,,,,,,,105.121559143066,105.121559143066,25.2842388153076,25.2842388153076,50.0711229419284,5.43068878796916,6.97232913970947,65,1,0,0,1,0.278778076171875,31.7693061828613,2,1,1,105.121559143066,0,105.121559143066,,,,,,,,,,,,,,,,,,,,,,,,,,,,,,,,,
,3863686884.80692,125.099838256836,25.2842388153076,1.29136745258554E-5,6.91799937141422E-9,1,5,12.9061126708984,4.99334563900611,35.0399985909462,0.0168321883741875,0.00245829758952257,1,-1.09172043974868E-8,,,,,,,,,,,,,,,,,,,,,125.099838256836,125.099838256836,25.2842388153076,25.2842388153076,50.1633551071976,5.42491679716559,7.04951620101929,63,1,64,0,0,0.276565551757813,31.7693061828613,2,1,1,125.099838256836,0,125.099838256836,,,,,,,,,,,,,,,,,,,,,,,,,,,,,,,,,
,3863687005.99348,145.123916625977,25.2842388153076,1.22708156191856E-5,6.6083359348971E-9,1,5,12.9061126708984,4.99486766659753,35.1000018417835,0.0160002149939678,0.00234292658688006,1,-5.76604697535409E-9,,,,,,,,,,,,,,,,,,,,,145.123916625977,145.123916625977,25.2842388153076,25.2842388153076,50.1043421539957,5.42159638528744,7.09329509735107,63,1,64,0,0,0.269546508789062,31.7693061828613,2,1,1,145.123916625977,0,145.123916625977,,,,,,,,,,,,,,,,,,,,,,,,,,,,,,,,,
,3863687126.30396,165.029251098633,25.2842388153076,1.19691207946128E-5,6.82120110501565E-9,1,5,12.9061126708984,4.99649818978474,35.1700000464916,0.0156161927964652,0.00227123840072735,1,-1.72231868097492E-8,,,,,,,,,,,,,,,,,,,,,165.029251098633,165.029251098633,25.2842388153076,25.2842388153076,50.0617433996976,5.41488819113801,7.15045118331909,64,1,64,0,0,0.270843505859375,32.2580642700195,2,1,1,165.029251098633,0,165.029251098633,,,,,,,,,,,,,,,,,,,,,,,,,,,,,,,,,
,3863687246.78538,185.030487060547,25.2842388153076,1.17570589642168E-5,7.79988445762326E-9,1,5,12.9061126708984,4.99757469586423,35.2399982511997,0.0153401607072983,0.0022588000753611,1,3.87285417002164E-9,,,,,,,,,,,,,,,,,,,,,185.030487060547,185.030487060547,25.2842388153076,25.2842388153076,50.1856315199957,5.40981812790493,7.20174121856689,65,1,0,0,1,0.276718139648438,32.2580642700195,2,1,1,185.030487060547,0,185.030487060547,,,,,,,,,,,,,,,,,,,,,,,,,,,,,,,,,
,3863687367.34924,205.027038574219,25.2842388153076,1.15726248979061E-5,6.69754187936125E-9,1,5,12.9061126708984,4.99658661017002,35.3300012648106,0.0150971633618883,0.00221030165172347,1,-5.73081923840435E-9,,,,,,,,,,,,,,,,,,,,,205.027038574219,205.027038574219,25.2842388153076,25.2842388153076,50.218850732063,5.41567635807252,7.27580404281616,65,1,0,0,1,0.280380249023438,31.7693061828613,2,1,1,205.027038574219,0,205.027038574219,,,,,,,,,,,,,,,,,,,,,,,,,,,,,,,,,
,3863687488.26861,225.122817993164,25.2842388153076,1.13634516344126E-5,7.13363387693087E-9,1,5,12.9061126708984,4.99837371449208,35.4099981486797,0.0148331925175913,0.00216138281496587,1,-1.3332193499275E-8,,,,,,,,,,,,,,,,,,,,,225.122817993164,225.122817993164,25.2842388153076,25.2842388153076,50.1918845481495,5.40872805574426,7.39031839370728,64,1,64,0,0,0.273056030273438,31.7693061828613,2,1,1,225.122817993164,0,225.122817993164,,,,,,,,,,,,,,,,,,,,,,,,,,,,,,,,,
,3863687608.39302,245.047897338867,25.2842388153076,1.11736891956679E-5,6.67351618136735E-9,1,5,12.9061126708984,5.00007096178866,35.5099998414516,0.0145923874246636,0.00212656279345401,1,-1.29083749234804E-8,,,,,,,,,,,,,,,,,,,,,245.047897338867,245.047897338867,25.2842388153076,25.2842388153076,50.1148941390053,5.40255312805163,7.54188585281372,64,1,64,0,0,0.2783203125,31.7693061828613,2,1,1,245.047897338867,0,245.047897338867,,,,,,,,,,,,,,,,,,,,,,,,,,,,,,,,,
,3863687728.7,265.007568359375,25.2842388153076,1.09748195275784E-5,7.12030037392788E-9,1,5,12.9061126708984,5.00163852224783,35.6200002133846,0.014339096468397,0.00208873410414772,1,-1.33654084319447E-8,,,,,,,,,,,,,,,,,,,,,265.007568359375,265.007568359375,25.2842388153076,25.2842388153076,50.1707805781303,5.39679541070663,7.85223007202148,63,1,64,0,0,0.279312133789062,31.7693061828613,2,1,1,265.007568359375,0,265.007568359375,,,,,,,,,,,,,,,,,,,,,,,,,,,,,,,,,
,3863687849.48049,285.110748291016,25.2842388153076,1.07687094441793E-5,7.30933437296114E-9,1,5,12.9061126708984,5.00238387668121,35.7399992644787,0.0140743498270572,0.00203897718161232,1,-2.15008238018671E-8,,,,,,,,,,,,,,,,,,,,,285.110748291016,285.110748291016,25.2842388153076,25.2842388153076,50.157883707563,5.39436714848057,7.72209978103638,64,1,64,0,0,0.275802612304687,32.2580642700195,2,1,1,285.110748291016,0,285.110748291016,,,,,,,,,,,,,,,,,,,,,,,,,,,,,,,,,
,3863689710.59437,10.0018329620361,25.1338119506836,2.16945760445003E-5,1.69896014303376E-8,1,5,12.9061126708984,4.98268255555663,34.8800010979176,0.0281881089297801,0.00414956739235238,1,6.34727681409523E-9,,,,,,,,,,,,,,,,,,,,,10.0018329620361,10.0018329620361,25.1338119506836,25.1338119506836,49.9202686377168,5.43199102620004,4.94202089309692,65,1,0,0,1,0.2734375,30.3030319213867,1,1,1,10.0018329620361,0,10.0018329620361,,,,,,,,,,,,,,,,,,,,,,,,,,,,,,,,,
,3863689811.9474,25.0140743255615,25.1338119506836,1.67928497093803E-5,1.35130921302991E-8,1,5,12.9061126708984,4.98267763377635,34.8800010979176,0.0218206796437369,0.0032018417513128,1,-2.90419316891679E-9,,,,,,,,,,,,,,,,,,,,,25.0140743255615,25.0140743255615,25.1338119506836,25.1338119506836,50.0871463265726,5.42878841942493,5.94364309310913,65,1,0,0,1,0.275344848632813,31.2805480957031,2,1,1,25.0140743255615,0,25.0140743255615,,,,,,,,,,,,,,,,,,,,,,,,,,,,,,,,,
,3863689940.6786,45.0286674499512,25.1338119506836,1.55135153184392E-5,1.05975132336619E-8,1,5,12.9061126708984,4.98550556273306,34.8899997770786,0.020176464141934,0.00294611520391446,1,-1.3570734661523E-8,,,,,,,,,,,,,,,,,,,,,45.0286674499512,45.0286674499512,25.1338119506836,25.1338119506836,50.1606194073803,5.4191643865788,6.45465135574341,65,1,0,0,1,0.27313232421875,32.2580642700195,2,1,1,45.0286674499512,0,45.0286674499512,,,,,,,,,,,,,,,,,,,,,,,,,,,,,,,,,
,3863690067.13333,65.0138320922852,25.1338119506836,1.48245129284096E-5,1.30442551119374E-8,1,5,12.9061126708984,4.98238954998603,34.9199995398521,0.0192627293469656,0.00281761875987523,1,-9.25720453325653E-9,,,,,,,,,,,,,,,,,,,,,65.0138320922852,65.0138320922852,25.1338119506836,25.1338119506836,50.1614010358995,5.43276035140693,6.72551679611206,64,1,64,0,0,0.277938842773438,31.2805480957031,2,1,1,65.0138320922852,0,65.0138320922852,,,,,,,,,,,,,,,,,,,,,,,,,,,,,,,,,
,3863690191.56131,85.0233535766602,25.1338119506836,1.4254079455361E-5,1.43438895302937E-8,1,5,12.9061126708984,4.98220798675124,34.9499993026257,0.0185208574351677,0.00270709647411344,1,-1.04128420039933E-8,,,,,,,,,,,,,,,,,,,,,85.0233535766602,85.0233535766602,25.1338119506836,25.1338119506836,50.1449868369957,5.43142483908299,6.87731122970581,65,1,0,0,1,0.277328491210938,31.7693061828613,2,1,1,85.0233535766602,0,85.0233535766602,,,,,,,,,,,,,,,,,,,,,,,,,,,,,,,,,
,3863690314.03717,105.082984924316,25.1338119506836,1.30843259300294E-5,6.92189404393945E-9,1,5,12.9061126708984,4.98312395332428,34.9900014698505,0.017005719684739,0.0024830355865672,1,-1.15178498008029E-8,,,,,,,,,,,,,,,,,,,,,105.082984924316,105.082984924316,25.1338119506836,25.1338119506836,49.9683387916495,5.4280814617429,6.98837900161743,65,1,0,0,1,0.274200439453125,32.7468223571777,2,1,1,105.082984924316,0,105.082984924316,,,,,,,,,,,,,,,,,,,,,,,,,,,,,,,,,
,3863690435.02005,125.090270996094,25.1338119506836,1.21938659059335E-5,6.4150538400086E-9,1,5,12.9061126708984,4.98422167700112,35.0399985909462,0.0158542924169403,0.00230796372502284,1,-1.5968066506259E-8,,,,,,,,,,,,,,,,,,,,,125.090270996094,125.090270996094,25.1338119506836,25.1338119506836,50.1074686680726,5.4229665167683,7.06365346908569,65,1,0,0,1,0.268402099609375,32.7468223571777,2,1,1,125.090270996094,0,125.090270996094,,,,,,,,,,,,,,,,,,,,,,,,,,,,,,,,,
,3863690555.00856,145.039733886719,25.1338119506836,1.18991603425467E-5,6.24660771128737E-9,1,5,12.9061126708984,4.98431048879133,35.1000018417835,0.0154709971501893,0.00225571560478492,1,-1.29088755548529E-8,,,,,,,,,,,,,,,,,,,,,145.039733886719,145.039733886719,25.1338119506836,25.1338119506836,50.1699989496111,5.42478844139159,7.12989997863769,65,1,0,0,1,0.269699096679687,32.2580642700195,2,1,1,145.039733886719,0,145.039733886719,,,,,,,,,,,,,,,,,,,,,,,,,,,,,,,,,
,3863690676.21519,165.018325805664,25.1338119506836,1.17305085536159E-5,6.55242181752096E-9,1,5,12.9061126708984,4.98634108398797,35.1600013673306,0.0152603059024211,0.00222598696685199,1,-1.19801894090245E-8,,,,,,,,,,,,,,,,,,,,,165.018325805664,165.018325805664,25.1338119506836,25.1338119506836,50.1316991521688,5.41698158017071,7.18200969696045,64,1,64,0,0,0.277481079101562,32.2580642700195,2,1,1,165.018325805664,0,165.018325805664,,,,,,,,,,,,,,,,,,,,,,,,,,,,,,,,,
,3863690796.70183,185.099670410156,25.1338119506836,1.15505465953409E-5,6.92698952119036E-9,1,5,12.9061126708984,4.98700616054797,35.2399982511997,0.0150302012712691,0.00218411505164416,1,-1.80477857191522E-8,,,,,,,,,,,,,,,,,,,,,185.099670410156,185.099670410156,25.1338119506836,25.1338119506836,50.1660908070149,5.41335557393871,7.23543214797974,63,1,64,0,0,0.27801513671875,32.2580642700195,2,1,1,185.099670410156,0,185.099670410156,,,,,,,,,,,,,,,,,,,,,,,,,,,,,,,,,
,3863690917.94312,205.147964477539,25.1338119506836,1.14031134369214E-5,7.57895527231713E-9,1,5,12.9061126708984,4.98853535142157,35.3199988603592,0.0148447110942392,0.00215737170353155,1,-1.76585600292133E-8,,,,,,,,,,,,,,,,,,,,,205.147964477539,205.147964477539,25.1338119506836,25.1338119506836,50.2321384168899,5.40909531808005,7.30478382110596,64,1,64,0,0,0.272674560546875,32.7468223571777,2,1,1,205.147964477539,0,205.147964477539,,,,,,,,,,,,,,,,,,,,,,,,,,,,,,,,,
,3863691037.54248,225.002532958984,25.1338119506836,1.12380413764938E-5,2.00282916783104E-8,1,5,12.9061126708984,4.98935749706116,35.4099981486797,0.0146271547719142,0.00216780047462435,1,1.42198993634388E-8,,,,,,,,,,,,,,,,,,,,,225.002532958984,225.002532958984,25.1338119506836,25.1338119506836,50.1668724355342,5.406508982834,7.41265487670898,65,1,0,0,1,0.282974243164062,32.2580642700195,2,1,1,225.002532958984,0,225.002532958984,,,,,,,,,,,,,,,,,,,,,,,,,,,,,,,,,
,3863691158.08534,245.015914916992,25.1338119506836,1.10565592174342E-5,6.17256350208463E-9,1,5,12.9061126708984,4.98919944311936,35.5099998414516,0.0143946143113677,0.00210334666111814,1,-8.55719703882239E-9,,,,,,,,,,,,,,,,,,,,,245.015914916992,245.015914916992,25.1338119506836,25.1338119506836,50.1449868369957,5.40761378183403,7.5591778755188,63,1,64,0,0,0.2777099609375,32.2580642700195,2,1,1,245.015914916992,0,245.015914916992,,,,,,,,,,,,,,,,,,,,,,,,,,,,,,,,,
,3863691279.34922,265.237701416016,25.1338119506836,1.08753597501566E-5,6.79972994210799E-9,1,5,12.9061126708984,4.99052338073463,35.6200002133846,0.01416512577249,0.0020618640685816,1,-1.43932356876154E-8,,,,,,,,,,,,,,,,,,,,,265.237701416016,265.237701416016,25.1338119506836,25.1338119506836,50.1434235799572,5.40378664656575,7.87759828567505,64,1,64,0,0,0.27923583984375,31.7693061828613,2,1,1,265.237701416016,0,265.237701416016,,,,,,,,,,,,,,,,,,,,,,,,,,,,,,,,,
,3863691399.31458,285.038299560547,25.1338119506836,1.0694943484523E-5,6.83901879103569E-9,1,5,12.9061126708984,4.99223170784065,35.7300005853176,0.0139362743268562,0.00203237836039937,1,-1.12795571173123E-8,,,,,,,,,,,,,,,,,,,,,285.038299560547,285.038299560547,25.1338119506836,25.1338119506836,50.173125463688,5.39679121989442,7.76082134246826,64,1,64,0,0,0.27374267578125,32.2580642700195,2,1,1,285.038299560547,0,285.038299560547,,,,,,,,,,,,,,,,,,,,,,,,,,,,,,,,,
,3863692084.25221,300.000030517578,25.4471988677979,1.61359890614767E-5,7.29565512169574E-9,1,5,12.9061126708984,5.00205002952158,35.8100011944771,0.0210821873579524,0.00308932405609199,1,-5.90424782164568E-9,,,,,,,,,,,,,,,,,,,,,300.000030517578,300.000030517578,25.4471988677979,25.4471988677979,50.0754218987841,5.3976181166638,8.44099140167236,65,1,0,0,1,0.276336669921875,30.3030319213867,1,1,1,300.000030517578,0,300.000030517578,,,,,,,,,,,,,,,,,,,,,,,,,,,,,,,,,
,3863692208.25263,284.722991943359,25.4471988677979,1.62945347507586E-5,9.82056480524938E-9,1,5,12.9061126708984,5.0025728629618,35.7300005853176,0.0212936706154191,0.00311181170708197,1,-1.23322171453103E-8,,,,,,,,,,,,,,,,,,,,,284.722991943359,284.722991943359,25.4471988677979,25.4471988677979,50.2430812161592,5.39521394234336,8.59200668334961,64,1,64,0,0,0.274658203125,31.7693061828613,2,1,1,284.722991943359,0,284.722991943359,,,,,,,,,,,,,,,,,,,,,,,,,,,,,,,,,
,3863692318.9438,264.870544433594,25.4471988677979,1.64368690835708E-5,7.50206588872111E-9,1,5,12.9061126708984,5.00191420248291,35.6400012969971,0.0214759618234165,0.00313672503580575,1,-1.3733587589264E-8,,,,,,,,,,,,,,,,,,,,,264.870544433594,264.870544433594,25.4471988677979,25.4471988677979,50.1715622066495,5.39868718114426,8.42125701904297,64,1,64,0,0,0.273895263671875,31.7693061828613,2,1,1,264.870544433594,0,264.870544433594,,,,,,,,,,,,,,,,,,,,,,,,,,,,,,,,,
,3863692439.46591,244.969619750977,25.4471988677979,1.6510160354082E-5,6.59716410841375E-9,1,5,12.9061126708984,5.00113180191001,35.5499982833862,0.0215673709082185,0.00314748044140515,1,-1.57403120327607E-8,,,,,,,,,,,,,,,,,,,,,244.969619750977,244.969619750977,25.4471988677979,25.4471988677979,50.2215864318803,5.40144248497156,8.29243659973145,64,1,64,0,0,0.279998779296875,31.2805480957031,2,1,1,244.969619750977,0,244.969619750977,,,,,,,,,,,,,,,,,,,,,,,,,,,,,,,,,
,3863692559.12645,224.904525756836,25.4471988677979,1.65288259513015E-5,7.11511876036055E-9,1,5,12.9061126708984,5.00146988512406,35.4599989950657,0.0215947451300503,0.00314488934797533,1,-2.06942006100623E-8,,,,,,,,,,,,,,,,,,,,,224.904525756836,224.904525756836,25.4471988677979,25.4471988677979,50.1997008333418,5.40149259865333,8.18741703033447,64,1,64,0,0,0.276107788085938,31.7693061828613,2,1,1,224.904525756836,0,224.904525756836,,,,,,,,,,,,,,,,,,,,,,,,,,,,,,,,,
,3863692677.79456,204.992797851562,25.4471988677979,1.64682398543258E-5,6.21951019614792E-9,1,5,12.9061126708984,5.00020821701633,35.3999994695187,0.0215092241915528,0.00312385136351121,1,-2.70539924809991E-8,,,,,,,,,,,,,,,,,,,,,204.992797851562,204.992797851562,25.4471988677979,25.4471988677979,50.2231496889188,5.40310826267021,8.11495208740234,65,1,0,0,1,0.280303955078125,32.7468223571777,2,1,1,204.992797851562,0,204.992797851562,,,,,,,,,,,,,,,,,,,,,,,,,,,,,,,,,
,3863692798.82651,184.888046264648,25.4471988677979,1.63023458176601E-5,6.29117692775591E-9,1,5,12.9061126708984,4.99934459250064,35.3199988603592,0.0212869450119612,0.00309472086075731,1,-2.44176056164252E-8,,,,,,,,,,,,,,,,,,,,,184.888046264648,184.888046264648,25.4471988677979,25.4471988677979,50.1653091784957,5.40867085319506,8.03023147583008,65,1,0,0,1,0.281906127929687,32.7468223571777,2,1,1,184.888046264648,0,184.888046264648,,,,,,,,,,,,,,,,,,,,,,,,,,,,,,,,,
,3863692918.6491,164.995727539062,25.4471988677979,1.59694326022271E-5,6.47763064871311E-9,1,5,12.9061126708984,4.99729000362857,35.2700017392635,0.0208384395291141,0.00304199487820049,1,-1.45550279176078E-8,,,,,,,,,,,,,,,,,,,,,164.995727539062,164.995727539062,25.4471988677979,25.4471988677979,50.1598377788611,5.41310025100645,7.94796085357666,65,1,0,0,1,0.27130126953125,31.7693061828613,2,1,1,164.995727539062,0,164.995727539062,,,,,,,,,,,,,,,,,,,,,,,,,,,,,,,,,
,3863693038.80665,144.848114013672,25.4471988677979,1.54359516766023E-5,6.1755179414299E-9,1,5,12.9061126708984,4.99624940891564,35.1999998092651,0.0201374794271229,0.00293233479248941,1,-1.95734706652135E-8,,,,,,,,,,,,,,,,,,,,,144.848114013672,144.848114013672,25.4471988677979,25.4471988677979,50.1711713923899,5.41949861147032,7.86150217056274,64,1,64,0,0,0.277862548828125,32.2580642700195,2,1,1,144.848114013672,0,144.848114013672,,,,,,,,,,,,,,,,,,,,,,,,,,,,,,,,,
,3863693158.28537,124.929634094238,25.4471988677979,1.45437559615794E-5,6.29262397396683E-9,1,5,12.9061126708984,4.99660711958103,35.1400002837181,0.0189750531601321,0.00276575749683437,1,-1.64229437097116E-8,,,,,,,,,,,,,,,,,,,,,124.929634094238,124.929634094238,25.4471988677979,25.4471988677979,50.1102043678899,5.41578175989617,7.7700023651123,65,1,0,0,1,0.267181396484375,32.2580642700195,2,1,1,124.929634094238,0,124.929634094238,,,,,,,,,,,,,,,,,,,,,,,,,,,,,,,,,
,3863693278.80871,104.967544555664,25.4471988677979,1.25760327804206E-5,7.09326423074353E-9,1,5,12.9061126708984,4.99752304342462,35.0800007581711,0.0164126652673895,0.00238767984194097,1,-1.76451700139594E-8,,,,,,,,,,,,,,,,,,,,,104.967544555664,104.967544555664,25.4471988677979,25.4471988677979,50.1059054110341,5.4117405734728,7.66599845886231,63,1,64,0,0,0.269317626953125,32.2580642700195,2,1,1,104.967544555664,0,104.967544555664,,,,,,,,,,,,,,,,,,,,,,,,,,,,,,,,,
,3863693398.08517,84.984489440918,25.4471988677979,1.14614194585339E-5,6.91400240263401E-9,1,5,12.9061126708984,4.99705455425345,35.0500009953976,0.0149562590913497,0.00217432579901557,1,-1.71913221381102E-8,,,,,,,,,,,,,,,,,,,,,84.984489440918,84.984489440918,25.4471988677979,25.4471988677979,50.2075171185342,5.41277736000681,7.56339359283447,64,1,64,0,0,0.267181396484375,32.7468223571777,2,1,1,84.984489440918,0,84.984489440918,,,,,,,,,,,,,,,,,,,,,,,,,,,,,,,,,
,3863693516.10683,64.9881210327148,25.4471988677979,1.12679300853799E-5,5.96975779091011E-9,1,5,12.9061126708984,4.99630252674557,34.9799990653992,0.0147000663675036,0.00214127216584978,1,-1.37549148251453E-8,,,,,,,,,,,,,,,,,,,,,64.9881210327148,64.9881210327148,25.4471988677979,25.4471988677979,50.1950110622265,5.41711842407147,7.41065692901611,65,1,0,0,1,0.278167724609375,31.2805480957031,2,1,1,64.9881210327148,0,64.9881210327148,,,,,,,,,,,,,,,,,,,,,,,,,,,,,,,,,
,3863693632.31661,44.9461250305176,25.4471988677979,1.12598124714625E-5,6.5705881740376E-9,1,5,12.9061126708984,4.9969599200056,34.9400006234646,0.0146909431037962,0.00214857861324176,1,-7.26450776742673E-9,,,,,,,,,,,,,,,,,,,,,44.9461250305176,44.9461250305176,25.4471988677979,25.4471988677979,50.1789876775822,5.41349733515289,7.17601299285889,65,1,0,0,1,0.267562866210938,32.2580642700195,2,1,1,44.9461250305176,0,44.9461250305176,,,,,,,,,,,,,,,,,,,,,,,,,,,,,,,,,
,3863693750.75189,24.8340663909912,25.4471988677979,1.14480571567751E-5,6.32552663933291E-9,1,5,12.9061126708984,4.99919729279308,34.9199995398521,0.0149477181309179,0.0021736432738468,1,-1.67519056680276E-8,,,,,,,,,,,,,,,,,,,,,24.8340663909912,24.8340663909912,25.4471988677979,25.4471988677979,50.1942294337072,5.40457979893363,6.67871475219727,65,1,0,0,1,0.283126831054687,31.7693061828613,2,1,1,24.8340663909912,0,24.8340663909912,,,,,,,,,,,,,,,,,,,,,,,,,,,,,,,,,
,3863693939.26181,9.99936103820801,25.4471988677979,1.23485095277576E-5,6.67503405516964E-9,1,5,12.9061126708984,4.99415073053316,34.8800010979176,0.0160988730239648,0.0023532606334231,1,-8.8909424300526E-9,,,,,,,,,,,,,,,,,,,,,9.99936103820801,9.99936103820801,25.4471988677979,25.4471988677979,50.2680933287745,5.4236920725367,4.98972463607788,65,1,0,0,1,0.271682739257813,31.7693061828613,1,1,1,9.99936103820801,0,9.99936103820801,,,,,,,,,,,,,,,,,,,,,,,,,,,,,,,,,
,3863694039.74377,25.1519451141357,25.4471988677979,1.15073713013027E-5,6.48678761070281E-9,1,5,12.9061126708984,4.99412385821336,34.8800010979176,0.0150014928420732,0.00219748703591389,1,-4.80331456931939E-9,,,,,,,,,,,,,,,,,,,,,25.1519451141357,25.1519451141357,25.4471988677979,25.4471988677979,50.1238828669765,5.42443846555112,6.06987476348877,65,1,0,0,1,0.270309448242187,32.7468223571777,2,1,1,25.1519451141357,0,25.1519451141357,,,,,,,,,,,,,,,,,,,,,,,,,,,,,,,,,
,3863694167.37692,45.0156402587891,25.4471988677979,1.13127916507681E-5,6.57390612894794E-9,1,5,12.9061126708984,4.99947387540452,34.8999984562397,0.0147721387028375,0.00214886314748166,1,-1.59900036964414E-8,,,,,,,,,,,,,,,,,,,,,45.0156402587891,45.0156402587891,25.4471988677979,25.4471988677979,50.1754703492457,5.40489641279801,6.56028747558594,65,1,0,0,1,0.275192260742187,31.7693061828613,2,1,1,45.0156402587891,0,45.0156402587891,,,,,,,,,,,,,,,,,,,,,,,,,,,,,,,,,
,3863694293.80978,65.010856628418,25.4471988677979,1.13006390465401E-5,7.80840138003466E-9,1,5,12.9061126708984,4.99594845333634,34.9199995398521,0.0147400336067572,0.0021557166026702,1,-7.32206631392372E-9,,,,,,,,,,,,,,,,,,,,,65.010856628418,65.010856628418,25.4471988677979,25.4471988677979,50.107077853813,5.41745268352863,6.82842206954956,65,1,0,0,1,0.272140502929687,31.2805480957031,2,1,1,65.010856628418,0,65.010856628418,,,,,,,,,,,,,,,,,,,,,,,,,,,,,,,,,
,3863694419.00567,85.0403594970703,25.4471988677979,1.14320041216967E-5,7.59780437437383E-9,1,5,12.9061126708984,4.99354578567139,34.9499993026257,0.0149016752782151,0.00217693223476561,1,-9.22812297962749E-9,,,,,,,,,,,,,,,,,,,,,85.0403594970703,85.0403594970703,25.4471988677979,25.4471988677979,50.0566628143226,5.42629730970424,7.00290489196777,64,1,64,0,0,0.275039672851562,31.7693061828613,2,1,1,85.0403594970703,0,85.0403594970703,,,,,,,,,,,,,,,,,,,,,,,,,,,,,,,,,
,3863694540.69388,105.067901611328,25.4471988677979,1.21899358864174E-5,6.59892364619665E-9,1,5,12.9061126708984,4.99464021279398,34.9900014698505,0.0158957554457028,0.00231361046846573,1,-1.62551715594558E-8,,,,,,,,,,,,,,,,,,,,,105.067901611328,105.067901611328,25.4471988677979,25.4471988677979,50.0480649006111,5.42287735075381,7.10569381713867,65,1,0,0,1,0.277252197265625,31.2805480957031,2,1,1,105.067901611328,0,105.067901611328,,,,,,,,,,,,,,,,,,,,,,,,,,,,,,,,,
,3863694661.61344,125.007888793945,25.4471988677979,1.31139313754737E-5,6.7079731569907E-9,1,5,12.9061126708984,4.99532411873723,35.0399985909462,0.0171040890154244,0.00248840798291903,1,-1.82938110090131E-8,,,,,,,,,,,,,,,,,,,,,125.007888793945,125.007888793945,25.4471988677979,25.4471988677979,50.1637459214572,5.42066823226533,7.17119455337524,65,1,0,0,1,0.267333984375,32.2580642700195,2,1,1,125.007888793945,0,125.007888793945,,,,,,,,,,,,,,,,,,,,,,,,,,,,,,,,,
,3863694783.29525,145.226303100586,25.4471988677979,1.32773190440899E-5,6.65372864885984E-9,1,5,12.9061126708984,4.99655454752745,35.1100005209446,0.0173205325253715,0.00253823311656653,1,-4.75970214839548E-9,,,,,,,,,,,,,,,,,,,,,145.226303100586,145.226303100586,25.4471988677979,25.4471988677979,50.2282302742938,5.41504251025619,7.24051380157471,65,1,0,0,1,0.269546508789062,32.2580642700195,2,1,1,145.226303100586,0,145.226303100586,,,,,,,,,,,,,,,,,,,,,,,,,,,,,,,,,
,3863694903.87098,165.118225097656,25.4471988677979,1.33405394426447E-5,6.82027102866895E-9,1,5,12.9061126708984,4.99819596682996,35.1600013673306,0.0174130513185139,0.00253764574806515,1,-1.53929690118437E-8,,,,,,,,,,,,,,,,,,,,,165.118225097656,165.118225097656,25.4471988677979,25.4471988677979,50.1313083379091,5.41179461097246,7.28615283966065,63,1,64,0,0,0.2801513671875,31.7693061828613,2,1,1,165.118225097656,0,165.118225097656,,,,,,,,,,,,,,,,,,,,,,,,,,,,,,,,,
,3863695023.77164,185.02912902832,25.4471988677979,1.33473806209265E-5,6.6910320932702E-9,1,5,12.9061126708984,4.99856050789013,35.2399982511997,0.0174242797069365,0.00253567753727219,1,-1.81046898328671E-8,,,,,,,,,,,,,,,,,,,,,185.02912902832,185.02912902832,25.4471988677979,25.4471988677979,50.1653091784957,5.40907537850554,7.33437013626099,65,1,0,0,1,0.27496337890625,31.7693061828613,2,1,1,185.02912902832,0,185.02912902832,,,,,,,,,,,,,,,,,,,,,,,,,,,,,,,,,
,3863695144.32381,205.030212402344,25.4471988677979,1.3330394197273E-5,7.04108655036019E-9,1,5,12.9061126708984,4.99955152651063,35.3199988603592,0.0174068683823487,0.00253363031337178,1,-1.77167574090087E-8,,,,,,,,,,,,,,,,,,,,,205.030212402344,205.030212402344,25.4471988677979,25.4471988677979,50.157883707563,5.40733958378803,7.37804269790649,64,1,64,0,0,0.282669067382813,32.2580642700195,2,1,1,205.030212402344,0,205.030212402344,,,,,,,,,,,,,,,,,,,,,,,,,,,,,,,,,
,3863695264.88954,225.006683349609,25.4471988677979,1.32431143055252E-5,6.37406218887109E-9,1,5,12.9061126708984,4.99916659511836,35.4099981486797,0.0172901819181759,0.00252256304910303,1,-1.31630753316577E-8,,,,,,,,,,,,,,,,,,,,,225.006683349609,225.006683349609,25.4471988677979,25.4471988677979,50.2184599178034,5.40944623614472,7.48479843139648,64,1,64,0,0,0.276947021484375,31.7693061828613,2,1,1,225.006683349609,0,225.006683349609,,,,,,,,,,,,,,,,,,,,,,,,,,,,,,,,,
,3863695386.02661,245.09992980957,25.4471988677979,1.31450306678884E-5,7.0278112672736E-9,1,5,12.9061126708984,4.99952457406785,35.5099998414516,0.0171648843216966,0.00249706126482587,1,-1.84808771546792E-8,,,,,,,,,,,,,,,,,,,,,245.09992980957,245.09992980957,25.4471988677979,25.4471988677979,50.1973559477842,5.40894728249017,7.62025308609009,64,1,64,0,0,0.281829833984375,32.2580642700195,2,1,1,245.09992980957,0,245.09992980957,,,,,,,,,,,,,,,,,,,,,,,,,,,,,,,,,
,3863695505.80456,265.051086425781,25.4471988677979,1.30053318560404E-5,6.62247347881836E-9,1,5,12.9061126708984,5.00097220168315,35.6200002133846,0.0169887537392872,0.0024755979995274,1,-1.51664894915169E-8,,,,,,,,,,,,,,,,,,,,,265.051086425781,265.051086425781,25.4471988677979,25.4471988677979,50.1965743192649,5.40050108251178,7.9239501953125,64,1,64,0,0,0.279083251953125,31.7693061828613,2,1,1,265.051086425781,0,265.051086425781,,,,,,,,,,,,,,,,,,,,,,,,,,,,,,,,,
,3863695626.17058,285.009490966797,25.4471988677979,1.28647231442332E-5,6.30283368148221E-9,1,5,12.9061126708984,5.0015447050084,35.7399992644787,0.0168089458209117,0.00244123376808346,1,-2.11203391459289E-8,,,,,,,,,,,,,,,,,,,,,285.009490966797,285.009490966797,25.4471988677979,25.4471988677979,50.1148941390053,5.40069243871284,7.8325138092041,65,1,0,0,1,0.27923583984375,31.7693061828613,2,1,1,285.009490966797,0,285.009490966797,,,,,,,,,,,,,,,,,,,,,,,,,,,,,,,,,
,3863696905.53145,9.99479150772095,25.4471988677979,,,5,,,,34.8899997770786,,,,,6.79580351399047E-6,6.40598845669081E-8,-0.0849417931401747,0.00654823044324322,2.26526785515123E-6,2.13532950173401E-8,2.26526536579487E-6,1.53600156456926E-8,-3.35828999467472E-9,1.48335136586596E-8,2.99999997728162,1.00057637691498,19.98847910208,20,1,3,0.0239171085601693,0.00025530348257912,0.000439850817201659,272.323425292969,9.98664474487305,10.0008792877197,25.4471988677979,25.4471988677979,,,5.16036558151245,,1,,,,,,1,1,1,9.99020385742188,0,9.99770862684337,,,,,,,,,,,,,,,,,,,,,,,,,,,,,,,,,
,3863697396.49273,19.9999752044678,25.4471988677979,,,5,,,,34.8899997770786,,,,,3.6145087756999E-6,1.04042191624391E-8,0.243964450904071,0.00137117464792126,1.20483216622384E-6,3.46806127450107E-9,1.20482124418458E-6,3.050914602119E-9,5.13013929063089E-9,1.64905096776027E-9,3.00001018982455,10.005763053894,10,100,1,3,0.0126469635475367,0.00129680843325487,0.00377208832651377,254.842575073242,19.9997158050537,20.0008563995361,25.4471988677979,25.4471988677979,,,5.8818507194519,,1,,,,,,1,1,1,20.0001850128174,0,20.000178607005,,,,,,,,,,,,,,,,,,,,,,,,,,,,,,,,,
,3863697856.03238,29.9999513626099,25.4471988677979,,,5,,,,34.8899997770786,,,,,2.3984875941294E-6,5.36555902439007E-9,0.227074903985915,0.00190893410114773,7.99489516646017E-7,1.78850547380145E-9,7.99483237866643E-7,9.32153419308289E-10,3.16853233382339E-9,1.52638194194297E-9,3.00002382043911,100.057640075684,10,1000,1,3,0.00835415859137931,0.00102742767570487,0.0122920023277402,197.945236206055,29.9996013641357,30.0006160736084,25.4471988677979,25.4471988677979,,,6.23985433578491,,1,,,,,,1,1,1,29.9999675750732,0,30.0000868638357,,,,,,,,,,,,,,,,,,,,,,,,,,,,,,,,,
,3863698483.92404,50,25.4471988677979,,,5,,,,34.9100008606911,,,,,1.43772187919169E-6,4.48342358654195E-8,-1.70832777165046,0.0231696331731464,4.79240599832327E-7,1.49447444600674E-8,4.79027595434172E-7,1.00023285374009E-8,-1.42868940013004E-8,1.11039997661478E-8,3.00000016629374,1.00057637691498,19.98847910208,20,1,3,0.00505940753138447,-8.94211722491813E-5,0.000389797933166847,250.951789855957,49.9972152709961,50.0006637573242,25.4471988677979,25.4471988677979,,,6.60031986236572,,1,,,,,,1,1,1,50.000129699707,0,49.9997430315205,,,,,,,,,,,,,,,,,,,,,,,,,,,,,,,,,
,3863698985.14198,59.9997577667236,25.4471988677979,,,5,,,,34.9199995398521,,,,,1.19249222139096E-6,1.12810561126175E-8,0.217044667750774,0.00878073032710255,3.97497679776223E-7,3.76035461678764E-9,3.97494827726717E-7,1.39674842374997E-9,1.5057748796004E-9,3.49132649357635E-9,2.99999794228306,10.005763053894,10,100,1,3,0.00417271722552699,0.000425358514905744,0.00379298953339458,254.754287719727,59.998950958252,60.001091003418,25.4471988677979,25.4471988677979,,,6.73194408416748,,1,,,,,,1,1,1,60.0000228881836,0,60.0000904731031,,,,,,,,,,,,,,,,,,,,,,,,,,,,,,,,,
,3863699454.86123,69.9998931884766,25.4471988677979,,,5,,,,34.9299982190132,,,,,1.0091495267603E-6,5.99088569395495E-9,0.401604998617802,0.00565374405324847,3.36384276145297E-7,1.99696843152653E-9,3.36376012781601E-7,6.04661402105468E-10,2.35780892938202E-9,1.90322555292781E-9,2.99999018480997,100.057640075684,10,1000,1,3,0.00351404819206715,0.000439706147360274,0.0122758997604251,197.671875,69.9990386962891,70.0010986328125,25.4471988677979,25.4471988677979,,,6.81675291061401,,1,,,,,,1,1,1,70.0000152587891,0,70.0001895738685,,,,,,,,,,,,,,,,,,,,,,,,,,,,,,,,,
,3863700097.93933,89.9956283569336,25.4471988677979,,,5,,,,34.960001707077,,,,,7.76828131939245E-7,5.5453794384342E-8,3.86067158159748,0.0517451319658819,2.58942704643066E-7,1.84845976995656E-8,2.58355093783519E-7,1.27304564601392E-8,1.74347298222661E-8,1.34020830631393E-8,3.00000006955225,1.00057637691498,19.98847910208,20,1,3,0.00272547941345997,0.00021719416313925,0.000327023532008752,282.375213623047,89.9651641845703,90.0000686645508,25.4471988677979,25.4471988677979,,,6.94277143478394,,1,,,,,,1,1,1,89.997932434082,0,89.9925533135732,,,,,,,,,,,,,,,,,,,,,,,,,,,,,,,,,
,3863700613.2915,99.9997444152832,25.4471988677979,,,5,,,,34.9900014698505,,,,,6.93807156922949E-7,1.13002440491149E-8,-0.312634785210389,0.00618237705917618,2.31268873908657E-7,3.76674511073406E-9,2.31265431079727E-7,3.48383067169401E-9,-1.2619138189877E-9,1.43223342378362E-9,3.00000231417643,10.005763053894,10,100,1,3,0.00242992829781979,0.000224980882362069,0.00379317556507885,254.748153686523,99.9982986450195,100.001533508301,25.4471988677979,25.4471988677979,,,6.97203016281128,,1,,,,,,1,1,1,99.9998779296875,0,99.9999935008861,,,,,,,,,,,,,,,,,,,,,,,,,,,,,,,,,
,3863701094.60453,110.000312805176,25.4471988677979,,,5,,,,35.0099988281727,,,,,6.35693991635423E-7,3.99212673553035E-9,0.793939552207433,0.00588766929106153,2.1191030906487E-7,1.33078622966999E-9,2.11889964671187E-7,4.58082699600646E-10,2.9363173554745E-9,1.24946077545709E-9,2.99982570192384,100.057640075684,10,1000,1,3,0.00221170768395789,0.000291837840878442,0.0122760813683271,197.661865234375,109.99821472168,110.002243041992,25.4471988677979,25.4471988677979,,,7.0122971534729,,1,,,,,,1,1,1,110.000198364258,0,110.000230068631,,,,,,,,,,,,,,,,,,,,,,,,,,,,,,,,,
,3863701750.73362,129.988883972168,25.4471988677979,,,5,,,,35.0599996745586,,,,,5.24664780913325E-7,3.83410232323742E-8,5.89427446238585,0.0448663772983805,1.74888249209477E-7,1.27803402666693E-8,1.73963629753748E-7,1.01183493379074E-8,1.79598227846741E-8,7.80743901723977E-9,3.00000019032093,1.00057637691498,19.98847910208,20,1,3,0.00183440688110089,0.000211918384805781,0.000305397290503606,281.872932434082,129.941741943359,129.999542236328,25.4471988677979,25.4471988677979,,,7.06376075744629,,1,,,,,,1,1,1,129.993667602539,0,129.985378901164,,,,,,,,,,,,,,,,,,,,,,,,,,,,,,,,,
,3863702259.48507,139.999801635742,25.4471988677979,,,5,,,,35.0899994373322,,,,,4.95614245461148E-7,1.50802119504238E-8,0.313401296171969,0.0173701102301946,1.65204482762276E-7,5.02672923151593E-9,1.65202011339408E-7,4.1292935829548E-9,9.03644933160585E-10,2.86652076091296E-9,3.00000482537947,10.005763053894,10,100,1,3,0.00173393710190499,0.000179654795615942,0.00379227241501212,254.743896484375,139.997436523438,140.002593994141,25.4471988677979,25.4471988677979,,,7.07818174362183,,1,,,,,,1,1,1,139.999877929688,0,140.00001638907,,,,,,,,,,,,,,,,,,,,,,,,,,,,,,,,,
,3863702733.00282,150.000289916992,25.4471988677979,,,5,,,,35.1199992001057,,,,,4.57941342184406E-7,3.68991376829179E-9,1.40657140675204,0.00743168505559612,1.5264995635007E-7,1.22999415815671E-9,1.52603960019987E-7,4.68309934539643E-10,3.74707351095771E-9,1.13735281874672E-9,2.99994414105311,100.057640075684,10,1000,1,3,0.00159095908809784,0.000227142377615402,0.0122824860736728,197.669235229492,149.996154785156,150.003036499023,25.4471988677979,25.4471988677979,,,7.08935737609863,,1,,,,,,1,1,1,149.999786376953,0,149.999997965495,,,,,,,,,,,,,,,,,,,,,,,,,,,,,,,,,
,3863703389.58515,169.987060546875,25.4471988677979,,,5,,,,35.1799987256527,,,,,3.82406481237475E-7,4.56640689098585E-8,2.76866583940041,0.0886852915345804,1.27468823840292E-7,1.52213559165255E-8,1.27320029883517E-7,1.01890503462017E-8,6.15719430323834E-9,1.13080913057912E-8,3.00000007622725,1.00057637691498,19.98847910208,20,1,3,0.00134345634964337,8.13265803367548E-5,0.000215479813050479,301.762550354004,169.932510375977,170.000946044922,25.4471988677979,25.4471988677979,,,7.12361764907837,,1,,,,,,1,1,1,169.993286132813,0,169.983137130737,,,,,,,,,,,,,,,,,,,,,,,,,,,,,,,,,
,3863703896.59117,179.999908447266,25.4471988677979,,,5,,,,35.2200008928776,,,,,3.69869290116944E-7,9.32973567599255E-9,0.915674275294171,0.0126103614805853,1.23289291483062E-7,3.10989998886818E-9,1.23273547200351E-7,2.69741190927936E-9,1.97026775800666E-9,1.54772314463544E-9,3.00001148248758,10.005763053894,10,100,1,3,0.00129253080864351,0.000147660317011944,0.00377654586918652,254.723983764648,179.996078491211,180.004318237305,25.4471988677979,25.4471988677979,,,7.13318157196045,,1,,,,,,1,1,1,179.999938964844,0,180.000376383464,,,,,,,,,,,,,,,,,,,,,,,,,,,,,,,,,
,3863704360.2344,190.000373840332,25.4471988677979,,,5,,,,35.2599993348122,,,,,3.5229911233796E-7,3.49471311446266E-9,1.45789570258244,0.0072552815994513,1.1742666006787E-7,1.16484110959969E-9,1.17388648049764E-7,7.9464812096658E-10,2.98760836519402E-9,8.51697818746599E-10,3.00016292837026,100.057640075684,10,1000,1,3,0.00122380702694734,0.000175770028831258,0.0122859440743923,197.682220458984,189.994354248047,190.005020141602,25.4471988677979,25.4471988677979,,,7.15975570678711,,1,,,,,,1,1,1,189.999771118164,0,190.000479325004,,,,,,,,,,,,,,,,,,,,,,,,,,,,,,,,,
,3863705004.364,209.97452545166,25.4471988677979,,,5,,,,25.1199994236231,,,,,3.03777177727692E-6,0,235.580658542166,0,3.03016374398297E-6,0,-1.71278644037656E-6,0,-2.49965096063652E-6,0,1.00251076639309,1.00057637691498,19.98847910208,0,1,3,-0.00593594520547681,-0.00889255422500886,0,0,209.921478271484,209.981979370117,25.4471988677979,25.4471988677979,,,7.19620656967163,,1,,,,,,1,1,1,209.981887817383,0,209.95820066664,,,,,,,,,,,,,,,,,,,,,,,,,,,,,,,,,
,3863705444.36859,220.000587463379,25.4471988677979,,,5,,,,35.3900007903576,,,,,3.20558052643641E-7,1.22015010506773E-8,180.974222995291,0.0242523537083411,1.06723332451259E-7,4.06224346041755E-9,-1.06707905134155E-7,3.1338557010492E-9,-1.81457195557923E-9,2.58471862621574E-9,3.0036360867015,10.005763053894,10,100,1,3,-0.00112007916109852,-0.000129112853325825,0.693049848079681,74.4398193359375,219.992462158203,220.007507324219,25.4471988677979,25.4471988677979,,,7.23536443710327,,1,,,,,,1,1,1,220.000930786133,0,220.000296936035,,,,,,,,,,,,,,,,,,,,,,,,,,,,,,,,,
,3863705892.78887,229.99877166748,25.4471988677979,,,5,,,,35.4400016367435,,,,,2.79132513035484E-7,3.63707999706565E-9,182.303552089888,0.0116709053297853,9.4099672550284E-8,1.22611312111663E-9,-9.40236310939457E-8,5.36241509187244E-10,-3.78221760086308E-9,1.10263249979263E-9,2.96634946191044,100.057640075684,10,1000,1,3,-0.000967504870163421,-0.00015351345268107,2.18087410926819,17.676513671875,229.992385864258,230.006195068359,25.4471988677979,25.4471988677979,,,7.28438711166382,,1,,,,,,1,1,1,229.997512817383,0,229.999689516814,,,,,,,,,,,,,,,,,,,,,,,,,,,,,,,,,
,3863706525.37859,249.970359802246,25.4471988677979,,,5,,,,35.5300009250641,,,,,2.73581660583086E-7,5.16959692548907E-8,181.634920324509,0.155225732367218,9.11934871800147E-8,1.7231914227937E-8,-9.11563633923448E-8,9.8184888412618E-9,-2.60182957441048E-9,1.41610785194136E-8,3.00001314834073,1.00057637691498,19.98847910208,20,1,3,-0.000962100107930343,-3.91530086153625E-5,0.0439997874200344,126.244415283203,249.913314819336,249.999359130859,25.4471988677979,25.4471988677979,,,7.47908449172974,,1,,,,,,1,1,1,249.981948852539,0,249.973373413086,,,,,,,,,,,,,,,,,,,,,,,,,,,,,,,,,
,3863707022.95154,259.998199462891,25.4471988677979,,,5,,,,35.5900004506111,,,,,2.73177202884897E-7,7.43040145725692E-9,182.777200065124,0.0164198381690109,9.10620334581718E-8,2.47688115612442E-9,-9.09550808486125E-8,1.9817338084547E-9,-4.41216560881067E-9,1.48582346663118E-9,2.99990229199502,10.005763053894,10,100,1,3,-0.000950589728141897,-0.000140001748311192,0.693409860134125,74.4673156738281,259.991485595703,260.006591796875,25.4471988677979,25.4471988677979,,,7.69602108001709,,1,,,,,,1,1,1,259.997100830078,0,259.999544067383,,,,,,,,,,,,,,,,,,,,,,,,,,,,,,,,,
,3863707492.71723,269.996994018555,25.4471988677979,,,5,,,,35.6499999761581,,,,,2.30677149169535E-7,3.79199503767413E-9,182.319191973859,0.00878874699668471,7.79409972910757E-8,1.28123603063049E-9,-7.78771555387302E-8,1.08793741495352E-9,-3.15399808558892E-9,6.76725902659279E-10,2.95963815176827,100.057640075684,10,1000,1,3,-0.000799546608665254,-0.000127047314814425,2.19489932060242,17.68701171875,269.990875244141,270.006286621094,25.4471988677979,25.4471988677979,,,7.86093997955322,,1,,,,,,1,1,1,269.996063232422,0,269.998777306598,,,,,,,,,,,,,,,,,,,,,,,,,,,,,,,,,
,3863708137.18247,289.987182617188,25.4471988677979,,,5,,,,35.7600003480911,,,,,2.2520283813972E-7,4.16361896458283E-8,174.202726227272,0.157943207249663,7.50675490780457E-8,1.38787181168733E-8,-7.46836173089105E-8,7.16656099576201E-9,7.58249498786491E-9,1.1885252208584E-8,3.00000254311731,1.00057637691498,19.98847910208,20,1,3,-0.000789482428639664,7.04849179079528E-5,0.0253014415502548,98.5990600585938,289.910552978516,290.013916015625,25.4471988677979,25.4471988677979,,,8.28586101531982,,1,,,,,,1,1,1,290.000823974609,0,289.988254547119,,,,,,,,,,,,,,,,,,,,,,,,,,,,,,,,,
,3863708630.3266,299.998596191406,25.4471988677979,,,5,,,,35.8199998736382,,,,,2.37194774196116E-7,1.39797960654541E-8,181.062933975589,0.0427992500488255,7.90154653019317E-8,4.65701697974448E-9,-7.900186849397E-8,3.20221262911586E-9,-1.4657869361721E-9,3.38136679873084E-9,3.00187783859468,10.005763053894,10,100,1,3,-0.000828647661714984,-9.68113320556947E-5,0.691430330276489,74.3452453613281,299.992126464844,300.005737304687,25.4471988677979,25.4471988677979,,,8.7592077255249,,1,,,,,,1,1,1,299.99755859375,0,299.999694824219,,,,,,,,,,,,,,,,,,,,,,,,,,,,,,,,,
,3863708688.4357,299.998748779297,25.4471988677979,,,5,,,,35.8199998736382,,,,,2.17942512465417E-7,5.07922867106649E-9,182.292320489418,0.0218424645460173,7.29159245775848E-8,1.69933185821448E-9,-7.28575747109619E-8,5.71874360598137E-10,-2.91648148299098E-9,1.60021513554683E-9,2.98895630451096,100.057640075684,10,1000,1,3,-0.000755497959447229,-0.000119657313454991,2.1800754070282,17.7139282226562,299.990600585937,300.00634765625,25.4471988677979,25.4471988677979,,,8.73538589477539,,1,,,,,,1,1,1,299.997283935547,0,299.999489339193,,,,,,,,,,,,,,,,,,,,,,,,,,,,,,,,,