File: data/Rock_mag_data/MPMS3/DX1-1r-FC-ZFC-RT-SIRM-VSM-SWEEP.dat
[Header]
; MPMS3 Data File (default extension .dat)
; Copyright (c) 2007, Quantum Design, Inc. All rights reserved.
TITLE,
FILEOPENTIME,3863746657.11536,06/07/2022,7:55 am
BYAPP,MPMS3 w/ AC,1.0,1.1
INFO,MPMS3 Measurement Release 1.1.16 Build 424, MultiVu Release 2.3.4.19,APPNAME
INFO,Linear Motor Servo Controller,MOTOR_MODULE_NAME
INFO,3101-100 N2,MOTOR_HW_VERSION
INFO,,MOTOR_SERIAL_NUMBER
INFO,01.04.28,MOTOR_SOFTWARE_VERSION
INFO,Quantum Design Squid Module,SQUID_MODULE_NAME
INFO,3101-501 B0,SQUID_HW_VERSION
INFO,SQM327,SQUID_SERIAL_NUMBER
INFO,01.03.04,SQUID_SOFTWARE_VERSION
INFO,Quantum Design VSM Oven,OVEN_MODULE_NAME
INFO,3101-201 A3,OVEN_HW_VERSION
INFO,OVB365,OVEN_SERIAL_NUMBER
INFO,01.07.07,OVEN_SOFTWARE_VERSION
INFO,SQUID AC,AC_MODULE_NAME
INFO,3101-401 G0,AC_HW_VERSION
INFO,SAC220,AC_SERIAL_NUMBER
INFO,SQUID AC 00.95.07,AC_SOFTWARE_VERSION
INFO,TCI344,COIL_SERIAL_NUMBER
INFO,0,MOMENT_UNITS
INFO,DX1-1r,SAMPLE_MATERIAL
INFO,SSRM2022C,SAMPLE_COMMENT
INFO,31.716,SAMPLE_MASS
INFO,,SAMPLE_VOLUME
INFO,,SAMPLE_MOLECULAR_WEIGHT
INFO,,SAMPLE_SIZE
INFO,,SAMPLE_SHAPE
INFO,Straw,SAMPLE_HOLDER
INFO,Standard,SAMPLE_HOLDER_DETAIL
INFO,68.13,SAMPLE_OFFSET
DATATYPE,COMMENT,1
DATATYPE,TIME,2
STARTUPAXIS,X,2
STARTUPAXIS,Y1,5
FIELDGROUP, VSM,2,3,4,5,6,8,9,10,11,14,15
FIELDGROUP, DC, 2,3,4,14,56,57,58,59,60,61,62,63,64,65,66,67,68,69
FIELDGROUP, AC, 2,3,4,11,16,17,18,19,20,21,22,23,24,25,26,27,28,29,30
STARTUPGROUP, All
[Data]
Comment,Time Stamp (sec),Temperature (K),Magnetic Field (Oe),Moment (emu),M. Std. Err. (emu),Transport Action,Averaging Time (sec),Frequency (Hz),Peak Amplitude (mm),Center Position (mm),Lockin Signal' (V),Lockin Signal (V),Range,M. Quad. Signal (emu),AC Moment (emu),AC M. Std Err. (emu),AC Phase (deg),AC Phase Std. Err. (deg),AC Susceptibility (emu/Oe),AC Suscept. Std Err. (emu/Oe),AC X' (emu/Oe),AC X' Std Err. (emu/Oe),AC X'' (emu/Oe),AC X'' Std Err. (emu/Oe),AC Drive (Oe),AC Frequency (Hz),AC Averaging Time (sec),AC Cycles,AC Range,AC Measure Type,AC Signal' (V),AC Signal'' (V),AC Trim Coil Ratio,AC Trim Coil Phase,Min. Temperature (K),Max. Temperature (K),Min. Field (Oe),Max. Field (Oe),Mass (grams),Motor Lag (deg),Pressure (Torr),Measure Count,Measurement Number,SQUID Status (code),Motor Status (code),Measure Status (code),Motor Current (amps),Motor Temp. (C),Temp. Status (code),Field Status (code),Chamber Status (code),Chamber Temp (K),Redirection State,Average Temp (K),Rotation Angle (deg),Rotator state,DC Moment Fixed Ctr (emu),DC Moment Err Fixed Ctr (emu),DC Moment Free Ctr (emu),DC Moment Err Free Ctr (emu),DC Fixed Fit,DC Free Fit,DC Calculated Center (mm),DC Calculated Center Err (mm),DC Scan Length (mm),DC Scan Time (s),DC Number of Points,DC Squid Drift,DC Min V (V),DC Max V (V),DC Scans per Measure,Map 01,Map 02,Map 03,Map 04,Map 05,Map 06,Map 07,Map 08,Map 09,Map 10,Map 11,Map 12,Map 13,Map 14,Map 15,Map 16
,3863748635.65899,9.99975872039795,25.3343811035156,0.000591560613179446,1.03877425157402E-7,1,5,12.9061126708984,4.9767533512041,36.9400009512901,0.767353448655989,0.112857354150808,1,9.41208649079848E-8,,,,,,,,,,,,,,,,,,,,,9.99975872039795,9.99975872039795,25.3343811035156,25.3343811035156,50.1551480077457,5.37306644808824,5.09119415283203,65,1,0,0,1,0.273895263671875,29.8142719268799,1,1,1,9.99975872039795,0,9.99975872039795,,,,,,,,,,,,,,,,,,,,,,,,,,,,,,,,,
,3863748703.78933,20.0690383911133,25.3343811035156,0.000391516218044454,9.10355822261289E-7,1,5,12.9061126708984,4.97669994929812,36.9400009512901,0.507854438538302,0.0746931229379652,1,6.31945986716969E-8,,,,,,,,,,,,,,,,,,,,,20.0690383911133,20.0690383911133,25.3343811035156,25.3343811035156,50.1668724355342,5.37168857662998,5.78834199905395,65,1,0,0,1,0.275726318359375,30.7917900085449,2,1,1,20.0690383911133,0,20.0690383911133,,,,,,,,,,,,,,,,,,,,,,,,,,,,,,,,,
,3863748800.50108,35.0513801574707,25.3343811035156,9.00078500686708E-5,2.4703616576229E-7,1,5,12.9061126708984,4.97663175458904,36.9400009512901,0.116754677731544,0.0171479053111749,1,-3.49812255620984E-9,,,,,,,,,,,,,,,,,,,,,35.0513801574707,35.0513801574707,25.3343811035156,25.3343811035156,50.1152849532649,5.37166590579554,6.27865982055664,65,1,0,0,1,0.285568237304687,30.7917900085449,2,1,1,35.0513801574707,0,35.0513801574707,,,,,,,,,,,,,,,,,,,,,,,,,,,,,,,,,
,3863748896.04302,50.0117034912109,25.3343811035156,5.11190938409696E-5,8.59357044564207E-9,1,5,12.9061126708984,4.97655806561102,36.9599983096123,0.0663153612434253,0.00969083146103008,1,-3.89559419479903E-8,,,,,,,,,,,,,,,,,,,,,50.0117034912109,50.0117034912109,25.3343811035156,25.3343811035156,50.1344348519861,5.37220197158557,6.56443309783935,65,1,0,0,1,0.27740478515625,30.7917900085449,2,1,1,50.0117034912109,0,50.0117034912109,,,,,,,,,,,,,,,,,,,,,,,,,,,,,,,,,
,3863748991.02194,65.0141220092773,25.3343811035156,4.89011204823859E-5,8.31247776262931E-9,1,5,12.9061126708984,4.97639263995202,36.9799993932247,0.0634365073457368,0.00926021280446282,1,-4.47563603452826E-8,,,,,,,,,,,,,,,,,,,,,65.0141220092773,65.0141220092773,25.3343811035156,25.3343811035156,50.1473317225534,5.37241313182284,6.72467613220215,64,1,64,0,0,0.27587890625,31.2805480957031,2,1,1,65.0141220092773,0,65.0141220092773,,,,,,,,,,,,,,,,,,,,,,,,,,,,,,,,,
,3863749085.48171,80.0893936157227,25.3343811035156,4.70881277666155E-5,7.14088437390785E-9,1,5,12.9061126708984,4.97630340165049,37.0000004768372,0.0610842056840076,0.00890899819174769,1,-4.90107892364951E-8,,,,,,,,,,,,,,,,,,,,,80.0893936157227,80.0893936157227,25.3343811035156,25.3343811035156,50.1614010358995,5.37432882078383,6.84945058822632,65,1,0,0,1,0.2667236328125,31.2805480957031,2,1,1,80.0893936157227,0,80.0893936157227,,,,,,,,,,,,,,,,,,,,,,,,,,,,,,,,,
,3863749176.69352,95.0011672973633,25.3343811035156,4.4809777941354E-5,9.08429388622978E-9,1,5,12.9061126708984,4.97591638844261,37.0300002396107,0.058122548816569,0.0084753003284953,1,-4.79579706698448E-8,,,,,,,,,,,,,,,,,,,,,95.0011672973633,95.0011672973633,25.3343811035156,25.3343811035156,50.0984799401015,5.37543913120251,6.93084383010864,65,1,0,0,1,0.266952514648438,30.7917900085449,2,1,1,95.0011672973633,0,95.0011672973633,,,,,,,,,,,,,,,,,,,,,,,,,,,,,,,,,
,3863749268.45551,110.118865966797,25.3343811035156,4.15585159104688E-5,7.73598425558916E-9,1,5,12.9061126708984,4.97546019219952,37.0699986815453,0.0538975416012299,0.00786517493460227,1,-3.99817091762529E-8,,,,,,,,,,,,,,,,,,,,,110.118865966797,110.118865966797,25.3343811035156,25.3343811035156,50.1586653360822,5.37804652907178,6.99196243286133,65,1,0,0,1,0.27862548828125,31.2805480957031,2,1,1,110.118865966797,0,110.118865966797,,,,,,,,,,,,,,,,,,,,,,,,,,,,,,,,,
,3863749358.99548,125.14762878418,25.3343811035156,4.00946553939749E-5,6.40328808529964E-9,1,5,12.9061126708984,4.97482223053287,37.0999984443188,0.0519917851538574,0.00757234727292224,1,-4.9691786409475E-8,,,,,,,,,,,,,,,,,,,,,125.14762878418,125.14762878418,25.3343811035156,25.3343811035156,50.1059054110341,5.3799790101238,7.04420328140259,65,1,0,0,1,0.278701782226562,30.7917900085449,2,1,1,125.14762878418,0,125.14762878418,,,,,,,,,,,,,,,,,,,,,,,,,,,,,,,,,
,3863749449.19351,140.09455871582,25.3343811035156,3.91548107802004E-5,6.37587469545172E-9,1,5,12.9061126708984,4.97412807011218,37.1400006115437,0.0507632948821215,0.00739202012784508,1,-4.95871166458065E-8,,,,,,,,,,,,,,,,,,,,,140.09455871582,140.09455871582,25.3343811035156,25.3343811035156,50.1606194073803,5.38247708478724,7.0867395401001,65,1,0,0,1,0.270767211914062,31.2805480957031,2,1,1,140.09455871582,0,140.09455871582,,,,,,,,,,,,,,,,,,,,,,,,,,,,,,,,,
,3863749540.23855,155.02668762207,25.3343811035156,3.84942174388816E-5,5.69377085734705E-9,1,5,12.9061126708984,4.98419963801859,37.1900014579296,0.0500514550393134,0.0072713705503204,1,-6.15492086981589E-8,,,,,,,,,,,,,,,,,,,,,155.02668762207,155.02668762207,25.3343811035156,25.3343811035156,50.1234920527168,5.3856595520111,7.12763738632202,64,1,64,0,0,0.269927978515625,31.2805480957031,2,1,1,155.02668762207,0,155.02668762207,,,,,,,,,,,,,,,,,,,,,,,,,,,,,,,,,
,3863749630.44092,170.066177368164,25.3343811035156,3.78714142023115E-5,7.356147609052E-9,1,5,12.9061126708984,4.98352507400852,37.2399985790253,0.0492295100650411,0.00717137383124981,1,-4.59282339566995E-8,,,,,,,,,,,,,,,,,,,,,170.066177368164,170.066177368164,25.3343811035156,25.3343811035156,50.1590561503418,5.38902179829454,7.16638469696045,64,1,64,0,0,0.269775390625,31.7693061828613,2,1,1,170.066177368164,0,170.066177368164,,,,,,,,,,,,,,,,,,,,,,,,,,,,,,,,,
,3863749720.79385,185.043426513672,25.3343811035156,3.73042340939113E-5,5.89599183752307E-9,1,5,12.9061126708984,4.98322310357975,37.3000018298626,0.0484872626710824,0.00706905061534226,1,-4.08696538954243E-8,,,,,,,,,,,,,,,,,,,,,185.043426513672,185.043426513672,25.3343811035156,25.3343811035156,50.1313083379091,5.3894608401138,7.20885944366455,64,1,64,0,0,0.269393920898438,31.2805480957031,2,1,1,185.043426513672,0,185.043426513672,,,,,,,,,,,,,,,,,,,,,,,,,,,,,,,,,
,3863749810.59586,200.025604248047,25.3343811035156,3.6753709065306E-5,6.18428377896324E-9,1,5,12.9061126708984,4.9827919904484,37.3600013554096,0.0477663731215681,0.00696062169864566,1,-4.27747574644018E-8,,,,,,,,,,,,,,,,,,,,,200.025604248047,200.025604248047,25.3343811035156,25.3343811035156,50.0738586417457,5.39313072013481,7.25838899612427,63,1,64,0,0,0.271072387695313,30.7917900085449,2,1,1,200.025604248047,0,200.025604248047,,,,,,,,,,,,,,,,,,,,,,,,,,,,,,,,,
,3863749901.44634,215.031967163086,25.3343811035156,3.61187210094467E-5,6.33547062409313E-9,1,5,12.9061126708984,4.9826747206873,37.4200008809567,0.046940383172633,0.00683459259894552,1,-4.63034316445575E-8,,,,,,,,,,,,,,,,,,,,,215.031967163086,215.031967163086,25.3343811035156,25.3343811035156,50.1414695086592,5.39343151369713,7.32070875167847,64,1,64,0,0,0.271682739257813,32.7468223571777,2,1,1,215.031967163086,0,215.031967163086,,,,,,,,,,,,,,,,,,,,,,,,,,,,,,,,,
,3863749991.65221,230.016830444336,25.3343811035156,3.55121314584255E-5,6.84852571889197E-9,1,5,12.9061126708984,4.98241075689446,37.5000014901161,0.0461468304617804,0.00673145799238397,1,-3.6175910988675E-8,,,,,,,,,,,,,,,,,,,,,230.016830444336,230.016830444336,25.3343811035156,25.3343811035156,50.2891972987938,5.39529093134949,7.42095136642456,65,1,0,0,1,0.27130126953125,31.7693061828613,2,1,1,230.016830444336,0,230.016830444336,,,,,,,,,,,,,,,,,,,,,,,,,,,,,,,,,
,3863750082.29648,245.025894165039,25.3343811035156,3.49125237307317E-5,7.01306143674811E-9,1,5,12.9061126708984,4.98240517016225,37.5699996948242,0.0453693079295901,0.0066060873101162,1,-4.45719639946796E-8,,,,,,,,,,,,,,,,,,,,,245.025894165039,245.025894165039,25.3343811035156,25.3343811035156,50.2274486457745,5.39431901235992,7.52082920074463,63,1,64,0,0,0.271148681640625,31.2805480957031,2,1,1,245.025894165039,0,245.025894165039,,,,,,,,,,,,,,,,,,,,,,,,,,,,,,,,,
,3863750172.70855,260.062072753906,25.3343811035156,3.4365701739307E-5,6.59013423399263E-9,1,5,12.9061126708984,4.98233040207348,37.6500003039837,0.0446587679684165,0.00649564312476511,1,-4.9137174270957E-8,,,,,,,,,,,,,,,,,,,,,260.062072753906,260.062072753906,25.3343811035156,25.3343811035156,50.1555388220053,5.39495443810204,7.73009014129639,63,1,64,0,0,0.27069091796875,31.2805480957031,2,1,1,260.062072753906,0,260.062072753906,,,,,,,,,,,,,,,,,,,,,,,,,,,,,,,,,
,3863750263.171,275.013031005859,25.3343811035156,3.38698525821061E-5,7.09959239568299E-9,1,5,12.9061126708984,4.98242471513211,37.7399995923042,0.044013110553303,0.00641886645592471,1,-3.5516329354123E-8,,,,,,,,,,,,,,,,,,,,,275.013031005859,275.013031005859,25.3343811035156,25.3343811035156,50.107077853813,5.39512430640863,7.81799125671387,64,1,64,0,0,0.272140502929687,30.3030319213867,2,1,1,275.013031005859,0,275.013031005859,,,,,,,,,,,,,,,,,,,,,,,,,,,,,,,,,
,3863750352.96344,290.059143066406,25.3343811035156,3.33850101698182E-5,7.34098914386083E-9,1,5,12.9061126708984,4.98210952206575,37.8299988806248,0.0433792905318737,0.00632588229035541,1,-3.54208307008513E-8,,,,,,,,,,,,,,,,,,,,,290.059143066406,290.059143066406,25.3343811035156,25.3343811035156,50.1942294337072,5.39441974428348,7.71952390670776,64,1,64,0,0,0.272293090820313,31.7693061828613,2,1,1,290.059143066406,0,290.059143066406,,,,,,,,,,,,,,,,,,,,,,,,,,,,,,,,,
,3863752185.05372,9.99967288970947,25.3218441009521,0.000189658734916087,4.36540519392468E-8,1,5,12.9061126708984,5.00757430271422,36.9499996304512,0.248150584028755,0.036555695862758,1,7.45535241886805E-8,,,,,,,,,,,,,,,,,,,,,9.99967288970947,9.99967288970947,25.3218441009521,25.3218441009521,50.0656515422938,5.37401109509789,5.08637094497681,65,1,0,0,1,0.27679443359375,29.8142719268799,1,1,1,9.99967288970947,0,9.99967288970947,,,,,,,,,,,,,,,,,,,,,,,,,,,,,,,,,
,3863752253.70602,20.0130920410156,25.3218441009521,8.49625731461392E-5,2.20083639783877E-7,1,5,12.9061126708984,4.97651319321186,36.9400009512901,0.110208799712267,0.0161701438932293,1,-1.56484023445793E-8,,,,,,,,,,,,,,,,,,,,,20.0130920410156,20.0130920410156,25.3218441009521,25.3218441009521,50.0633066567361,5.37333408788629,5.77122926712036,65,1,0,0,1,0.26702880859375,30.7917900085449,2,1,1,20.0130920410156,0,20.0130920410156,,,,,,,,,,,,,,,,,,,,,,,,,,,,,,,,,
,3863752351.53229,35.151050567627,25.3218441009521,4.70331431069877E-5,9.54822662904052E-9,1,5,12.9061126708984,4.97640300050182,36.9400009512901,0.0610111761793899,0.0089221238825478,1,-3.10068663424072E-8,,,,,,,,,,,,,,,,,,,,,35.151050567627,35.151050567627,25.3218441009521,25.3218441009521,50.1699989496111,5.37397452092045,6.24469327926636,65,1,0,0,1,0.26702880859375,30.3030319213867,2,1,1,35.151050567627,0,35.151050567627,,,,,,,,,,,,,,,,,,,,,,,,,,,,,,,,,
,3863752447.08447,50.1103401184082,25.3218441009521,4.49772690851681E-5,7.27107554397411E-9,1,5,12.9061126708984,4.97628670755781,36.9599983096123,0.0583451681941137,0.00851291945817738,1,-4.42443993481581E-8,,,,,,,,,,,,,,,,,,,,,50.1103401184082,50.1103401184082,25.3218441009521,25.3218441009521,50.1696081353515,5.37433725300958,6.55271673202515,65,1,0,0,1,0.266952514648438,31.2805480957031,2,1,1,50.1103401184082,0,50.1103401184082,,,,,,,,,,,,,,,,,,,,,,,,,,,,,,,,,
,3863752541.36725,65.02978515625,25.3218441009521,4.37372588884732E-5,6.54152329673509E-9,1,5,12.9061126708984,4.9761256408026,36.9799993932247,0.0567350067555701,0.00827116179791556,1,-4.81765778605838E-8,,,,,,,,,,,,,,,,,,,,,65.02978515625,65.02978515625,25.3218441009521,25.3218441009521,50.1309175236495,5.37291283066123,6.71866750717163,64,1,64,0,0,0.267105102539062,30.7917900085449,2,1,1,65.02978515625,0,65.02978515625,,,,,,,,,,,,,,,,,,,,,,,,,,,,,,,,,
,3863752635.45628,80.1657028198242,25.3218441009521,4.27064188534359E-5,6.62103138292896E-9,1,5,12.9061126708984,4.97608745989864,37.0000004768372,0.0553983477317407,0.00806849503867969,1,-5.29296763712024E-8,,,,,,,,,,,,,,,,,,,,,80.1657028198242,80.1657028198242,25.3218441009521,25.3218441009521,50.1453776512553,5.37515693525132,6.83651781082153,65,1,0,0,1,0.267333984375,31.2805480957031,2,1,1,80.1657028198242,0,80.1657028198242,,,,,,,,,,,,,,,,,,,,,,,,,,,,,,,,,
,3863752726.94406,95.0253372192383,25.3218441009521,4.17048126637624E-5,7.3551622139438E-9,1,5,12.9061126708984,4.97571605573067,37.0300002396107,0.0540916820868581,0.00789007696039703,1,-4.27107900475303E-8,,,,,,,,,,,,,,,,,,,,,95.0253372192383,95.0253372192383,25.3218441009521,25.3218441009521,50.1328715949476,5.37694637914134,6.91630840301514,64,1,64,0,0,0.27862548828125,31.2805480957031,2,1,1,95.0253372192383,0,95.0253372192383,,,,,,,,,,,,,,,,,,,,,,,,,,,,,,,,,
,3863752818.63339,110.084632873535,25.3218441009521,4.01826508504126E-5,7.84273679423281E-9,1,5,12.9061126708984,4.97529711403334,37.0699986815453,0.0521144469931658,0.00757939547975621,1,-5.79681764442353E-8,,,,,,,,,,,,,,,,,,,,,110.084632873535,110.084632873535,25.3218441009521,25.3218441009521,50.2168966607649,5.37819333707802,6.97568130493164,64,1,64,0,0,0.279006958007813,31.2805480957031,2,1,1,110.084632873535,0,110.084632873535,,,,,,,,,,,,,,,,,,,,,,,,,,,,,,,,,
,3863752908.88949,125.149200439453,25.3218441009521,3.92534761511471E-5,1.11135075569241E-8,1,5,12.9061126708984,4.97471385344798,37.0999984443188,0.0509013544517738,0.0074002591587915,1,-5.86721837555588E-8,,,,,,,,,,,,,,,,,,,,,125.149200439453,125.149200439453,25.3218441009521,25.3218441009521,50.1387338088418,5.38054820305478,7.02488470077515,64,1,64,0,0,0.279006958007813,31.2805480957031,2,1,1,125.149200439453,0,125.149200439453,,,,,,,,,,,,,,,,,,,,,,,,,,,,,,,,,
,3863752999.30737,140.007537841797,25.3218441009521,3.84885381549866E-5,7.08478026135461E-9,1,5,12.9061126708984,4.97429344683494,37.1400006115437,0.0499028192512429,0.00725979492708862,1,-5.39735462554315E-8,,,,,,,,,,,,,,,,,,,,,140.007537841797,140.007537841797,25.3218441009521,25.3218441009521,50.1117676249284,5.38179145105832,7.0689811706543,65,1,0,0,1,0.271148681640625,31.2805480957031,2,1,1,140.007537841797,0,140.007537841797,,,,,,,,,,,,,,,,,,,,,,,,,,,,,,,,,
,3863753089.96664,155.005142211914,25.3218441009521,3.79839599568106E-5,5.84782953560534E-9,1,5,12.9061126708984,4.98455523881071,37.1900014579296,0.0493929728206761,0.00717556008023398,1,-6.08444725602742E-8,,,,,,,,,,,,,,,,,,,,,155.005142211914,155.005142211914,25.3218441009521,25.3218441009521,50.1164573960438,5.38317458922607,7.1118860244751,65,1,0,0,1,0.27130126953125,30.3030319213867,2,1,1,155.005142211914,0,155.005142211914,,,,,,,,,,,,,,,,,,,,,,,,,,,,,,,,,
,3863753180.20911,170.020690917969,25.3218441009521,3.75180370038983E-5,6.04993643016107E-9,1,5,12.9061126708984,4.98425311651052,37.2399985790253,0.0487818978192243,0.00709409583501619,1,-5.45926201274034E-8,,,,,,,,,,,,,,,,,,,,,170.020690917969,170.020690917969,25.3218441009521,25.3218441009521,50.2145517752072,5.38569794593268,7.14305114746094,64,1,64,0,0,0.267486572265625,30.7917900085449,2,1,1,170.020690917969,0,170.020690917969,,,,,,,,,,,,,,,,,,,,,,,,,,,,,,,,,
,3863753270.81177,185.004623413086,25.3218441009521,3.70142721180471E-5,6.51442805548826E-9,1,5,12.9061126708984,4.98391809005549,37.3000018298626,0.0481225723576055,0.00699663444759395,1,-5.50490644492571E-8,,,,,,,,,,,,,,,,,,,,,185.004623413086,185.004623413086,25.3218441009521,25.3218441009521,50.1391246231015,5.38753737382213,7.18027687072754,64,1,64,0,0,0.267486572265625,31.7693061828613,2,1,1,185.004623413086,0,185.004623413086,,,,,,,,,,,,,,,,,,,,,,,,,,,,,,,,,
,3863753361.36504,200.057983398438,25.3218441009521,3.65059641888778E-5,6.4698564507885E-9,1,5,12.9061126708984,4.98347120673077,37.3700000345707,0.0474567949112919,0.00689248541204003,1,-5.98304101246974E-8,,,,,,,,,,,,,,,,,,,,,200.057983398438,200.057983398438,25.3218441009521,25.3218441009521,50.1848498914765,5.38940304698023,7.23337650299072,64,1,64,0,0,0.269775390625,30.7917900085449,2,1,1,200.057983398438,0,200.057983398438,,,,,,,,,,,,,,,,,,,,,,,,,,,,,,,,,
,3863753451.77756,215.033355712891,25.3218441009521,3.59544442085066E-5,6.2176053512114E-9,1,5,12.9061126708984,4.98315747368702,37.4200008809567,0.0467330604350745,0.006805715041776,1,-4.51066860715763E-8,,,,,,,,,,,,,,,,,,,,,215.033355712891,215.033355712891,25.3218441009521,25.3218441009521,50.0801116698995,5.39115176952065,7.29631185531616,65,1,0,0,1,0.269546508789062,31.7693061828613,2,1,1,215.033355712891,0,215.033355712891,,,,,,,,,,,,,,,,,,,,,,,,,,,,,,,,,
,3863753542.31135,230.012100219727,25.3218441009521,3.54194771438086E-5,5.95538053137041E-9,1,5,12.9061126708984,4.98274223357591,37.5000014901161,0.0460317674367451,0.00670747874557627,1,-4.150251562213E-8,,,,,,,,,,,,,,,,,,,,,230.012100219727,230.012100219727,25.3218441009521,25.3218441009521,50.1062962252938,5.39202885823483,7.39970397949219,64,1,64,0,0,0.27069091796875,32.2580642700195,2,1,1,230.012100219727,0,230.012100219727,,,,,,,,,,,,,,,,,,,,,,,,,,,,,,,,,
,3863753632.77105,245.0126953125,25.3218441009521,3.48509347376148E-5,7.85502975647652E-9,1,5,12.9061126708984,4.98234301790017,37.5699996948242,0.0452871250452822,0.00660352869442763,1,-3.74040342736275E-8,,,,,,,,,,,,,,,,,,,,,245.0126953125,245.0126953125,25.3218441009521,25.3218441009521,50.1438143942168,5.39491595136941,7.50296115875244,64,1,64,0,0,0.2703857421875,31.2805480957031,2,1,1,245.0126953125,0,245.0126953125,,,,,,,,,,,,,,,,,,,,,,,,,,,,,,,,,
,3863753722.89993,260.021667480469,25.3218441009521,3.43517051090065E-5,6.14606062272298E-9,1,5,12.9061126708984,4.98247934725104,37.6500003039837,0.0446410445361596,0.00650286864793527,1,-4.1729855386009E-8,,,,,,,,,,,,,,,,,,,,,260.021667480469,260.021667480469,25.3218441009521,25.3218441009521,50.1168482103034,5.39454483492702,7.70454120635986,64,1,64,0,0,0.270309448242187,30.3030319213867,2,1,1,260.021667480469,0,260.021667480469,,,,,,,,,,,,,,,,,,,,,,,,,,,,,,,,,
,3863753814.38381,275.2001953125,25.3218441009521,3.38491252505864E-5,7.58957852475894E-9,1,5,12.9061126708984,4.98247176323412,37.7399995923042,0.0439884593434564,0.00640345337698832,1,-4.43994694515974E-8,,,,,,,,,,,,,,,,,,,,,275.173980712891,275.226409912109,25.3218441009521,25.3218441009521,50.0722953847072,5.39467114332587,7.78219413757324,64,1,64,0,0,0.27130126953125,31.2805480957031,2,1,1,275.226409912109,0,275.2001953125,,,,,,,,,,,,,,,,,,,,,,,,,,,,,,,,,
,3863753904.56457,290.171875,25.3218441009521,3.33938905783799E-5,6.07421892504617E-9,1,5,12.9061126708984,4.98238504495809,37.8299988806248,0.0433950878022609,0.00632202669932816,1,-4.00714056101971E-8,,,,,,,,,,,,,,,,,,,,,290.171875,290.171875,25.3218441009521,25.3218441009521,50.1399062516207,5.39536773906391,7.68619441986084,63,1,64,0,0,0.271377563476562,32.2580642700195,2,1,1,290.171875,0,290.171875,,,,,,,,,,,,,,,,,,,,,,,,,,,,,,,,,
,3863754557.26591,300.001373291016,25.3719882965088,4.25877969498895E-5,6.34865611497784E-9,1,5,12.9061126708984,5.00274271561919,37.8700010478497,0.0556567149169572,0.00813071607804198,1,-3.43578409113102E-8,,,,,,,,,,,,,,,,,,,,,300.001373291016,300.001373291016,25.3719882965088,25.3719882965088,50.1199747243803,5.39240372223394,8.24951839447021,65,1,0,0,1,0.272369384765625,29.8142719268799,1,1,1,300.001373291016,0,300.001373291016,,,,,,,,,,,,,,,,,,,,,,,,,,,,,,,,,
,3863754652.82398,289.885162353516,25.3719882965088,4.27851896665476E-5,6.56723125225602E-9,1,5,12.9061126708984,5.0018291522854,37.8100015223026,0.0559021571267796,0.00815426313205409,1,-4.37412073674036E-8,,,,,,,,,,,,,,,,,,,,,289.885162353516,289.885162353516,25.3719882965088,25.3719882965088,50.056272000063,5.39633125316995,8.39721012115479,63,1,64,0,0,0.277023315429687,31.2805480957031,2,1,1,289.885162353516,0,289.885162353516,,,,,,,,,,,,,,,,,,,,,,,,,,,,,,,,,
,3863754731.788,274.954193115234,25.3719882965088,4.31010682850965E-5,6.36247856773553E-9,1,5,12.9061126708984,5.00228082288986,37.7399995923042,0.0563215464103679,0.00821857042226686,1,-4.17170068836762E-8,,,,,,,,,,,,,,,,,,,,,274.954193115234,274.954193115234,25.3719882965088,25.3719882965088,50.1469409082938,5.39366051652696,8.46085834503174,65,1,0,0,1,0.277023315429687,31.2805480957031,2,1,1,274.954193115234,0,274.954193115234,,,,,,,,,,,,,,,,,,,,,,,,,,,,,,,,,
,3863754824.43575,259.977661132813,25.3719882965088,4.32684407734186E-5,6.81256059088293E-9,1,5,12.9061126708984,5.00239079323707,37.6800000667572,0.0565434212567182,0.00824104854562502,1,-4.929575400974E-8,,,,,,,,,,,,,,,,,,,,,259.977661132813,259.977661132813,25.3719882965088,25.3719882965088,50.1473317225534,5.39270774790925,8.3433256149292,64,1,64,0,0,0.27374267578125,28.8367557525635,2,1,1,259.977661132813,0,259.977661132813,,,,,,,,,,,,,,,,,,,,,,,,,,,,,,,,,
,3863754914.69192,244.997100830078,25.3719882965088,4.34110409300312E-5,6.84152068238166E-9,1,5,12.9061126708984,5.00127776288509,37.5999994575977,0.056712629819977,0.00826202328654997,1,-5.22217388929815E-8,,,,,,,,,,,,,,,,,,,,,244.997100830078,244.997100830078,25.3719882965088,25.3719882965088,50.1793784918418,5.39509836751711,8.25887012481689,63,1,64,0,0,0.279541015625,31.2805480957031,2,1,1,244.997100830078,0,244.997100830078,,,,,,,,,,,,,,,,,,,,,,,,,,,,,,,,,
,3863755004.253,229.978897094727,25.3719882965088,4.34978137900259E-5,6.28586835059319E-9,1,5,12.9061126708984,5.00188476420619,37.5399999320507,0.0568361305903754,0.00827666125174659,1,-5.48396133787776E-8,,,,,,,,,,,,,,,,,,,,,229.978897094727,229.978897094727,25.3719882965088,25.3719882965088,50.1250553097553,5.3932004116654,8.18076133728027,63,1,64,0,0,0.274581909179687,31.2805480957031,2,1,1,229.978897094727,0,229.978897094727,,,,,,,,,,,,,,,,,,,,,,,,,,,,,,,,,
,3863755094.01299,214.918182373047,25.3719882965088,4.35481774344715E-5,6.21204323906016E-9,1,5,12.9061126708984,5.00268494158424,37.5000014901161,0.0569154214907816,0.00828307067000925,1,-5.8752195469677E-8,,,,,,,,,,,,,,,,,,,,,214.918182373047,214.918182373047,25.3719882965088,25.3719882965088,50.162964292938,5.39062374342593,8.10660648345947,65,1,0,0,1,0.277633666992187,30.7917900085449,2,1,1,214.918182373047,0,214.918182373047,,,,,,,,,,,,,,,,,,,,,,,,,,,,,,,,,
,3863755184.38427,199.920593261719,25.3719882965088,4.34953079233022E-5,5.35546069833318E-9,1,5,12.9061126708984,5.00281353371539,37.4299995601177,0.0568482315489105,0.00827424850704046,1,-5.79644490570464E-8,,,,,,,,,,,,,,,,,,,,,199.920593261719,199.920593261719,25.3719882965088,25.3719882965088,50.1445960227361,5.39018685047873,8.03312015533447,63,1,64,0,0,0.27435302734375,29.8142719268799,2,1,1,199.920593261719,0,199.920593261719,,,,,,,,,,,,,,,,,,,,,,,,,,,,,,,,,
,3863755274.56817,184.958114624023,25.3719882965088,4.3333302073492E-5,8.13226176935764E-9,1,5,12.9061126708984,5.00348228947904,37.3900011181831,0.0566486885936592,0.00823407991362076,1,-6.60824217454951E-8,,,,,,,,,,,,,,,,,,,,,184.958114624023,184.958114624023,25.3719882965088,25.3719882965088,50.1266185667938,5.38723787753806,7.98304271697998,64,1,64,0,0,0.271224975585938,31.7693061828613,2,1,1,184.958114624023,0,184.958114624023,,,,,,,,,,,,,,,,,,,,,,,,,,,,,,,,,
,3863755363.70028,169.987335205078,25.3719882965088,4.28503887507945E-5,6.3360815584522E-9,1,5,12.9061126708984,5.0037913980848,37.3499989509583,0.0560218756990061,0.00814543559091294,1,-6.34995104972731E-8,,,,,,,,,,,,,,,,,,,,,169.987335205078,169.987335205078,25.3719882965088,25.3719882965088,50.1492857938515,5.38726022991979,7.9110746383667,65,1,0,0,1,0.271072387695313,31.2805480957031,2,1,1,169.987335205078,0,169.987335205078,,,,,,,,,,,,,,,,,,,,,,,,,,,,,,,,,
,3863755453.55272,154.990447998047,25.3719882965088,4.23789096208402E-5,6.67077469287408E-9,1,5,12.9061126708984,5.0045531965099,37.3000018298626,0.0554156595710657,0.00806854010089427,1,-5.43782015811094E-8,,,,,,,,,,,,,,,,,,,,,154.990447998047,154.990447998047,25.3719882965088,25.3719882965088,50.0785484128611,5.38356960002056,7.86054563522339,65,1,0,0,1,0.270233154296875,31.2805480957031,2,1,1,154.990447998047,0,154.990447998047,,,,,,,,,,,,,,,,,,,,,,,,,,,,,,,,,
,3863755543.26092,139.906616210938,25.3719882965088,4.15874175676491E-5,7.56444703888578E-9,1,5,12.9061126708984,5.00496837830977,37.2399985790253,0.0543860280895434,0.00792537667961706,1,-4.83073371159511E-8,,,,,,,,,,,,,,,,,,,,,139.906616210938,139.906616210938,25.3719882965088,25.3719882965088,50.1621826644188,5.38135003071138,7.7931489944458,65,1,0,0,1,0.279998779296875,31.2805480957031,2,1,1,139.906616210938,0,139.906616210938,,,,,,,,,,,,,,,,,,,,,,,,,,,,,,,,,
,3863755633.32962,124.987014770508,25.3719882965088,4.04179427201135E-5,7.9636547298005E-9,1,5,12.9061126708984,5.00560535044684,37.2000001370907,0.0528665900982259,0.00770025559129419,1,-4.97201622210488E-8,,,,,,,,,,,,,,,,,,,,,124.987014770508,124.987014770508,25.3719882965088,25.3719882965088,50.1492857938515,5.37738762505152,7.72908067703247,63,1,64,0,0,0.269393920898438,30.7917900085449,2,1,1,124.987014770508,0,124.987014770508,,,,,,,,,,,,,,,,,,,,,,,,,,,,,,,,,
,3863755723.50702,109.86319732666,25.3719882965088,3.86419560762052E-5,9.37635233419439E-9,1,5,12.9061126708984,5.00596362523505,37.1600016951561,0.0505485357618933,0.00736351529555653,1,-4.68656856016842E-8,,,,,,,,,,,,,,,,,,,,,109.86319732666,109.86319732666,25.3719882965088,25.3719882965088,50.162964292938,5.37575967295557,7.65851402282715,64,1,64,0,0,0.267333984375,32.2580642700195,2,1,1,109.86319732666,0,109.86319732666,,,,,,,,,,,,,,,,,,,,,,,,,,,,,,,,,
,3863755813.95444,94.9384689331055,25.3719882965088,3.6632783775436E-5,6.26924309700494E-9,1,5,12.9061126708984,5.00623510136156,37.1199995279312,0.0479256231966587,0.00696959872526191,1,-5.32847068483102E-8,,,,,,,,,,,,,,,,,,,,,94.9384689331055,94.9384689331055,25.3719882965088,25.3719882965088,50.1176298388226,5.37534156923472,7.57719898223877,63,1,64,0,0,0.277328491210938,31.2805480957031,2,1,1,94.9384689331055,0,94.9384689331055,,,,,,,,,,,,,,,,,,,,,,,,,,,,,,,,,
,3863755902.99583,79.9868545532227,25.3719882965088,3.60120232612459E-5,5.89188780295621E-9,1,5,12.9061126708984,5.00625362950404,37.0800010859966,0.0471138011889773,0.00685114098633737,1,-5.26798900996491E-8,,,,,,,,,,,,,,,,,,,,,79.9868545532227,79.9868545532227,25.3719882965088,25.3719882965088,50.1082502965918,5.37771118246284,7.49457216262817,65,1,0,0,1,0.268096923828125,30.7917900085449,2,1,1,79.9868545532227,0,79.9868545532227,,,,,,,,,,,,,,,,,,,,,,,,,,,,,,,,,
,3863755991.84124,64.7748374938965,25.3719882965088,3.57569181822655E-5,6.19543245580334E-9,1,5,12.9061126708984,5.00624820411892,37.0500013232231,0.0467798242281619,0.00680366819206694,1,-5.14884964889752E-8,,,,,,,,,,,,,,,,,,,,,64.7644729614258,64.7852020263672,25.3719882965088,25.3719882965088,50.1215379814188,5.37536240319499,7.37648010253906,65,1,0,0,1,0.2679443359375,31.7693061828613,2,1,1,64.7644729614258,0,64.7748374938965,,,,,,,,,,,,,,,,,,,,,,,,,,,,,,,,,
,3863756079.51362,49.8178634643555,25.3719882965088,3.58030779737887E-5,5.21445645213583E-9,1,5,12.9061126708984,5.00633471525795,37.0099991559982,0.0468404370792848,0.00681880416361956,1,-4.6824025045156E-8,,,,,,,,,,,,,,,,,,,,,49.8178634643555,49.8178634643555,25.3719882965088,25.3719882965088,50.0949626117649,5.37551555948826,7.21805429458618,65,1,0,0,1,0.267181396484375,31.7693061828613,2,1,1,49.8178634643555,0,49.8178634643555,,,,,,,,,,,,,,,,,,,,,,,,,,,,,,,,,
,3863756165.72572,34.9845695495605,25.3719882965088,3.58572230283205E-5,6.16229671202404E-9,1,5,12.9061126708984,5.00650650736849,36.9900017976761,0.0469117018492204,0.00684185976876659,1,-3.74033761675518E-8,,,,,,,,,,,,,,,,,,,,,34.9845695495605,34.9845695495605,25.3719882965088,25.3719882965088,50.0848014410149,5.37514797127985,6.97864818572998,65,1,0,0,1,0.276412963867187,31.2805480957031,2,1,1,34.9845695495605,0,34.9845695495605,,,,,,,,,,,,,,,,,,,,,,,,,,,,,,,,,
,3863756253.88392,19.9899635314941,25.3719882965088,3.59131856641474E-5,7.03019247409525E-9,1,5,12.9061126708984,5.00647454817711,36.9700007140636,0.0469849113534801,0.0068496612366197,1,-3.96141305693505E-8,,,,,,,,,,,,,,,,,,,,,19.9899635314941,19.9899635314941,25.3719882965088,25.3719882965088,50.0910544691688,5.37557154939439,6.48682928085327,65,1,0,0,1,0.276718139648438,31.2805480957031,2,1,1,19.9899635314941,0,19.9899635314941,,,,,,,,,,,,,,,,,,,,,,,,,,,,,,,,,
,3863756481.88957,9.99887561798096,25.3719882965088,3.68631717589819E-5,9.9818832314199E-9,1,5,12.9061126708984,5.00654694498897,36.9499996304512,0.0482272516290043,0.00704116164589188,1,-3.28882241757362E-8,,,,,,,,,,,,,,,,,,,,,9.99887561798096,9.99887561798096,25.3719882965088,25.3719882965088,50.1563204505245,5.37639625862239,5.13668251037598,65,1,0,0,1,0.266876220703125,30.3030319213867,1,1,1,9.99887561798096,0,9.99887561798096,,,,,,,,,,,,,,,,,,,,,,,,,,,,,,,,,
,3863756549.68528,20.034158706665,25.3719882965088,3.59383664665666E-5,8.9031251191717E-9,1,5,12.9061126708984,5.00646706049545,36.9499996304512,0.0470154022157937,0.00687047695146691,1,-2.73892884266942E-8,,,,,,,,,,,,,,,,,,,,,20.034158706665,20.034158706665,25.3719882965088,25.3719882965088,50.1821141916592,5.3761753509409,5.82174301147461,65,1,0,0,1,0.266876220703125,31.2805480957031,2,1,1,20.034158706665,0,20.034158706665,,,,,,,,,,,,,,,,,,,,,,,,,,,,,,,,,
,3863756647.18792,35.103687286377,25.3719882965088,3.56756454186246E-5,8.35769696950555E-9,1,5,12.9061126708984,5.00648856324188,36.9499996304512,0.0466753958580272,0.00679707450970302,1,-4.49386944042847E-8,,,,,,,,,,,,,,,,,,,,,35.103687286377,35.103687286377,25.3719882965088,25.3719882965088,50.1367797375438,5.3764022713313,6.33162403106689,65,1,0,0,1,0.276107788085938,31.2805480957031,2,1,1,35.103687286377,0,35.103687286377,,,,,,,,,,,,,,,,,,,,,,,,,,,,,,,,,
,3863756742.5878,50.1262512207031,25.3719882965088,3.56377091140161E-5,7.74567629870994E-9,1,5,12.9061126708984,5.00635053444192,36.9599983096123,0.0466242257192919,0.00678780711508762,1,-4.6250003671798E-8,,,,,,,,,,,,,,,,,,,,,50.1262512207031,50.1262512207031,25.3719882965088,25.3719882965088,50.1656999927553,5.37609975707144,6.57968854904175,65,1,0,0,1,0.275497436523438,30.7917900085449,2,1,1,50.1262512207031,0,50.1262512207031,,,,,,,,,,,,,,,,,,,,,,,,,,,,,,,,,
,3863756836.79195,65.023796081543,25.3719882965088,3.55468571637667E-5,5.56904105834905E-9,1,5,12.9061126708984,5.00630374164753,36.9799993932247,0.0465044140753902,0.00677275223346195,1,-4.43447034927564E-8,,,,,,,,,,,,,,,,,,,,,65.023796081543,65.023796081543,25.3719882965088,25.3719882965088,50.1840682629572,5.37681614270596,6.73184537887573,64,1,64,0,0,0.267181396484375,31.7693061828613,2,1,1,65.023796081543,0,65.023796081543,,,,,,,,,,,,,,,,,,,,,,,,,,,,,,,,,
,3863756931.58805,80.1201858520508,25.3719882965088,3.57127764698866E-5,4.73868705404703E-9,1,5,12.9061126708984,5.00620366942219,37.0000004768372,0.0467202271299679,0.00680380353053175,1,-4.48353906332396E-8,,,,,,,,,,,,,,,,,,,,,80.1201858520508,80.1201858520508,25.3719882965088,25.3719882965088,50.0785484128611,5.37664472613835,6.88399839401245,65,1,0,0,1,0.26702880859375,31.7693061828613,2,1,1,80.1201858520508,0,80.1201858520508,,,,,,,,,,,,,,,,,,,,,,,,,,,,,,,,,
,3863757023.76619,95.130973815918,25.3719882965088,3.61194860541051E-5,5.76534599542891E-9,1,5,12.9061126708984,5.00596268375406,37.0300002396107,0.0472494850590441,0.00687828007779111,1,-4.72912124079583E-8,,,,,,,,,,,,,,,,,,,,,95.130973815918,95.130973815918,25.3719882965088,25.3719882965088,50.0769851558226,5.37733429481821,6.97853183746338,65,1,0,0,1,0.278167724609375,31.7693061828613,2,1,1,95.130973815918,0,95.130973815918,,,,,,,,,,,,,,,,,,,,,,,,,,,,,,,,,
,3863757114.46217,110.215782165527,25.3719882965088,3.72602893948442E-5,7.38297915383947E-9,1,5,12.9061126708984,5.00573392940681,37.0699986815453,0.0487381310676399,0.00709897003734336,1,-4.58035883006072E-8,,,,,,,,,,,,,,,,,,,,,110.215782165527,110.215782165527,25.3719882965088,25.3719882965088,50.1160665817842,5.37875390829646,7.03619956970215,65,1,0,0,1,0.277862548828125,32.2580642700195,2,1,1,110.215782165527,0,110.215782165527,,,,,,,,,,,,,,,,,,,,,,,,,,,,,,,,,
,3863757204.52894,125.109184265137,25.3719882965088,3.81117979675985E-5,6.56670410665527E-9,1,5,12.9061126708984,5.00522782974738,37.0999984443188,0.0498458302886197,0.00725377912313194,1,-5.17419361179493E-8,,,,,,,,,,,,,,,,,,,,,125.109184265137,125.109184265137,25.3719882965088,25.3719882965088,50.0949626117649,5.38063473513371,7.0782356262207,65,1,0,0,1,0.27984619140625,31.2805480957031,2,1,1,125.109184265137,0,125.109184265137,,,,,,,,,,,,,,,,,,,,,,,,,,,,,,,,,
,3863757295.36941,140.009185791016,25.3719882965088,3.83379779941803E-5,5.96063478493903E-9,1,5,12.9061126708984,5.00468941137226,37.1400006115437,0.0501350168047647,0.00728949082142008,1,-5.68206604244717E-8,,,,,,,,,,,,,,,,,,,,,140.009185791016,140.009185791016,25.3719882965088,25.3719882965088,50.0984799401015,5.38219645710764,7.1248288154602,65,1,0,0,1,0.2691650390625,31.2805480957031,2,1,1,140.009185791016,0,140.009185791016,,,,,,,,,,,,,,,,,,,,,,,,,,,,,,,,,
,3863757385.01935,155.026641845703,25.3719882965088,3.84121267396156E-5,6.68462432028076E-9,1,5,12.9061126708984,5.00417106993334,37.2000001370907,0.0502256743484612,0.00729590817086193,1,-6.19966159270269E-8,,,,,,,,,,,,,,,,,,,,,155.026641845703,155.026641845703,25.3719882965088,25.3719882965088,50.0414210581976,5.38450972734716,7.15528249740601,63,1,64,0,0,0.270233154296875,31.2805480957031,2,1,1,155.026641845703,0,155.026641845703,,,,,,,,,,,,,,,,,,,,,,,,,,,,,,,,,
,3863757476.34328,170.015151977539,25.3719882965088,3.8398009836605E-5,6.54227559301321E-9,1,5,12.9061126708984,5.00398956342862,37.2500009834766,0.0502033629819065,0.0073017342259617,1,-5.51823662321171E-8,,,,,,,,,,,,,,,,,,,,,170.015151977539,170.015151977539,25.3719882965088,25.3719882965088,50.1125492534476,5.38404616315888,7.18764209747314,64,1,64,0,0,0.269088745117187,31.2805480957031,2,1,1,170.015151977539,0,170.015151977539,,,,,,,,,,,,,,,,,,,,,,,,,,,,,,,,,
,3863757566.91162,185.040466308594,25.3719882965088,3.82905610480388E-5,5.61183368677116E-9,1,5,12.9061126708984,5.00417046935234,37.3000018298626,0.050065494901194,0.0072811087437628,1,-5.54574963185118E-8,,,,,,,,,,,,,,,,,,,,,185.040466308594,185.040466308594,25.3719882965088,25.3719882965088,50.1946202479669,5.38449495230959,7.22447443008423,63,1,64,0,0,0.269622802734375,31.2805480957031,2,1,1,185.040466308594,0,185.040466308594,,,,,,,,,,,,,,,,,,,,,,,,,,,,,,,,,
,3863757657.14275,200.036483764648,25.3719882965088,3.81014072341598E-5,5.8634645414706E-9,1,5,12.9061126708984,5.00374946858049,37.3600013554096,0.0498123409792478,0.00724406022816118,1,-5.53572577993386E-8,,,,,,,,,,,,,,,,,,,,,200.036483764648,200.036483764648,25.3719882965088,25.3719882965088,50.1707805781303,5.3862398429749,7.27214622497559,64,1,64,0,0,0.270614624023438,31.2805480957031,2,1,1,200.036483764648,0,200.036483764648,,,,,,,,,,,,,,,,,,,,,,,,,,,,,,,,,
,3863757747.3664,215.01872253418,25.3719882965088,3.7852970699583E-5,6.22373817237199E-9,1,5,12.9061126708984,5.00333617955154,37.4200008809567,0.0494824223837962,0.00719191671181093,1,-5.81160758949914E-8,,,,,,,,,,,,,,,,,,,,,215.01872253418,215.01872253418,25.3719882965088,25.3719882965088,50.1207563528995,5.38828110633119,7.33118152618408,65,1,0,0,1,0.270919799804687,31.7693061828613,2,1,1,215.01872253418,0,215.01872253418,,,,,,,,,,,,,,,,,,,,,,,,,,,,,,,,,
,3863757838.07233,230.005264282227,25.3719882965088,3.75619296524395E-5,6.9419570471597E-9,1,5,12.9061126708984,5.00303663866071,37.5000014901161,0.0490982931685346,0.00713301143993243,1,-5.99729556333334E-8,,,,,,,,,,,,,,,,,,,,,230.005264282227,230.005264282227,25.3719882965088,25.3719882965088,50.1043421539957,5.39058306831959,7.4268798828125,65,1,0,0,1,0.270614624023438,31.2805480957031,2,1,1,230.005264282227,0,230.005264282227,,,,,,,,,,,,,,,,,,,,,,,,,,,,,,,,,
,3863757928.34717,245.013809204102,25.3719882965088,3.72389399358383E-5,6.49025088864087E-9,1,5,12.9061126708984,5.00267198976453,37.5699996948242,0.0486720723508985,0.00706459104114462,1,-6.43269143231223E-8,,,,,,,,,,,,,,,,,,,,,245.013809204102,245.013809204102,25.3719882965088,25.3719882965088,50.1008248256591,5.39271366092788,7.51282072067261,64,1,64,0,0,0.273590087890625,31.2805480957031,2,1,1,245.013809204102,0,245.013809204102,,,,,,,,,,,,,,,,,,,,,,,,,,,,,,,,,
,3863758018.88139,260.018432617187,25.3719882965088,3.6890534630683E-5,6.41582547488698E-9,1,5,12.9061126708984,5.00265735862616,37.6500003039837,0.0482147939701437,0.00701009228469024,1,-5.48279043333724E-8,,,,,,,,,,,,,,,,,,,,,260.018432617187,260.018432617187,25.3719882965088,25.3719882965088,50.1543663792265,5.39233315029886,7.71662044525146,64,1,64,0,0,0.272674560546875,31.2805480957031,2,1,1,260.018432617187,0,260.018432617187,,,,,,,,,,,,,,,,,,,,,,,,,,,,,,,,,
,3863758110.2437,275.230010986328,25.3719882965088,3.6546326968291E-5,7.22479100728166E-9,1,5,12.9061126708984,5.00231292962378,37.7399995923042,0.0477593325968028,0.00695074510530404,1,-4.916542866572E-8,,,,,,,,,,,,,,,,,,,,,275.230010986328,275.230010986328,25.3719882965088,25.3719882965088,50.1195839101207,5.39267467573319,7.78645086288452,64,1,64,0,0,0.272979736328125,31.7693061828613,2,1,1,275.230010986328,0,275.230010986328,,,,,,,,,,,,,,,,,,,,,,,,,,,,,,,,,
,3863758200.38107,290.121795654297,25.3719882965088,3.6251523518515E-5,6.90722375094949E-9,1,5,12.9061126708984,5.00267359488926,37.8299988806248,0.0473800276423786,0.0068874281276007,1,-5.48485117730831E-8,,,,,,,,,,,,,,,,,,,,,290.121795654297,290.121795654297,25.3719882965088,25.3719882965088,50.1606194073803,5.3931408240244,7.73729038238525,64,1,64,0,0,0.272140502929687,31.7693061828613,2,1,1,290.121795654297,0,290.121795654297,,,,,,,,,,,,,,,,,,,,,,,,,,,,,,,,,
,3863758340.47876,299.945953369141,25.3719882965088,3.58419980065045E-5,6.83030806115971E-9,1,5,12.9061126708984,5.0013753146448,37.8700010478497,0.0468267305451353,0.00681419472773216,1,-4.88343032321281E-8,,,,,,,,,,,,,,,,,,,,,299.945953369141,299.945953369141,25.3719882965088,25.3719882965088,50.101997268438,5.39868041196096,7.65713357925415,65,1,0,0,1,0.277252197265625,31.2805480957031,1,1,1,299.945953369141,0,299.945953369141,,,,,,,,,,,,,,,,,,,,,,,,,,,,,,,,,