File: data/Rock_mag_data/MPMS3/DX1-5r-FC-ZFC-RT-SIRM-VSM-SWEEP_AC-3freq.dat
[Header]
; MPMS3 Data File (default extension .dat)
; Copyright (c) 2007, Quantum Design, Inc. All rights reserved.
TITLE,
FILEOPENTIME,3864030622.93639,06/10/2022,2:48 pm
BYAPP,MPMS3 w/ AC,1.0,1.1
INFO,MPMS3 Measurement Release 1.1.16 Build 424, MultiVu Release 2.3.4.19,APPNAME
INFO,Linear Motor Servo Controller,MOTOR_MODULE_NAME
INFO,3101-100 N2,MOTOR_HW_VERSION
INFO,,MOTOR_SERIAL_NUMBER
INFO,01.04.28,MOTOR_SOFTWARE_VERSION
INFO,Quantum Design Squid Module,SQUID_MODULE_NAME
INFO,3101-501 B0,SQUID_HW_VERSION
INFO,SQM327,SQUID_SERIAL_NUMBER
INFO,01.03.04,SQUID_SOFTWARE_VERSION
INFO,Quantum Design VSM Oven,OVEN_MODULE_NAME
INFO,3101-201 A3,OVEN_HW_VERSION
INFO,OVB365,OVEN_SERIAL_NUMBER
INFO,01.07.07,OVEN_SOFTWARE_VERSION
INFO,SQUID AC,AC_MODULE_NAME
INFO,3101-401 G0,AC_HW_VERSION
INFO,SAC220,AC_SERIAL_NUMBER
INFO,SQUID AC 00.95.07,AC_SOFTWARE_VERSION
INFO,TCI344,COIL_SERIAL_NUMBER
INFO,0,MOMENT_UNITS
INFO,DX1-5r,SAMPLE_MATERIAL
INFO,SSRM2022C,SAMPLE_COMMENT
INFO,,SAMPLE_MASS
INFO,,SAMPLE_VOLUME
INFO,,SAMPLE_MOLECULAR_WEIGHT
INFO,,SAMPLE_SIZE
INFO,,SAMPLE_SHAPE
INFO,Straw,SAMPLE_HOLDER
INFO,Standard,SAMPLE_HOLDER_DETAIL
INFO,64.24,SAMPLE_OFFSET
DATATYPE,COMMENT,1
DATATYPE,TIME,2
STARTUPAXIS,X,2
STARTUPAXIS,Y1,5
FIELDGROUP, VSM,2,3,4,5,6,8,9,10,11,14,15
FIELDGROUP, DC, 2,3,4,14,56,57,58,59,60,61,62,63,64,65,66,67,68,69
FIELDGROUP, AC, 2,3,4,11,16,17,18,19,20,21,22,23,24,25,26,27,28,29,30
STARTUPGROUP, All
[Data]
Comment,Time Stamp (sec),Temperature (K),Magnetic Field (Oe),Moment (emu),M. Std. Err. (emu),Transport Action,Averaging Time (sec),Frequency (Hz),Peak Amplitude (mm),Center Position (mm),Lockin Signal' (V),Lockin Signal (V),Range,M. Quad. Signal (emu),AC Moment (emu),AC M. Std Err. (emu),AC Phase (deg),AC Phase Std. Err. (deg),AC Susceptibility (emu/Oe),AC Suscept. Std Err. (emu/Oe),AC X' (emu/Oe),AC X' Std Err. (emu/Oe),AC X'' (emu/Oe),AC X'' Std Err. (emu/Oe),AC Drive (Oe),AC Frequency (Hz),AC Averaging Time (sec),AC Cycles,AC Range,AC Measure Type,AC Signal' (V),AC Signal'' (V),AC Trim Coil Ratio,AC Trim Coil Phase,Min. Temperature (K),Max. Temperature (K),Min. Field (Oe),Max. Field (Oe),Mass (grams),Motor Lag (deg),Pressure (Torr),Measure Count,Measurement Number,SQUID Status (code),Motor Status (code),Measure Status (code),Motor Current (amps),Motor Temp. (C),Temp. Status (code),Field Status (code),Chamber Status (code),Chamber Temp (K),Redirection State,Average Temp (K),Rotation Angle (deg),Rotator state,DC Moment Fixed Ctr (emu),DC Moment Err Fixed Ctr (emu),DC Moment Free Ctr (emu),DC Moment Err Free Ctr (emu),DC Fixed Fit,DC Free Fit,DC Calculated Center (mm),DC Calculated Center Err (mm),DC Scan Length (mm),DC Scan Time (s),DC Number of Points,DC Squid Drift,DC Min V (V),DC Max V (V),DC Scans per Measure,Map 01,Map 02,Map 03,Map 04,Map 05,Map 06,Map 07,Map 08,Map 09,Map 10,Map 11,Map 12,Map 13,Map 14,Map 15,Map 16
,3864040551.55251,9.99999046325684,25.4346656799316,3.58700624768735E-5,4.71187009810409E-8,1,5,14.0008964538574,5.0001126265888,35.9500013291836,0.0468212717555564,0.00699920143207927,10,-5.46771226344594E-8,,,,,,,,,,,,,,,,,,,,,9.99999046325684,9.99999046325684,25.4346656799316,25.4346656799316,49.6580322695149,5.76068476713765,5.16144943237305,70,1,0,0,1,0.317840576171875,31.2805480957031,1,1,1,9.99999046325684,0,9.99999046325684,,,,,,,,,,,,,,,,,,,,,,,,,,,,,,,,,
,3864040652.2124,25.0326309204102,25.4346656799316,2.76979182845419E-5,5.97929102830661E-8,1,5,14.0008964538574,4.99941764566471,35.9500013291836,0.0361573598956263,0.00533572361458276,1,-9.42022201557083E-8,,,,,,,,,,,,,,,,,,,,,25.0326309204102,25.0326309204102,25.4346656799316,25.4346656799316,49.667020997486,5.76378073450139,6.07294750213623,70,1,0,0,1,0.318145751953125,31.2805480957031,2,1,1,25.0326309204102,0,25.0326309204102,,,,,,,,,,,,,,,,,,,,,,,,,,,,,,,,,
,3864040780.87819,45.0233573913574,25.4346656799316,2.18219462756851E-5,3.4437986649331E-8,1,5,14.0008964538574,5.00040602995972,35.9600000083447,0.028489869752311,0.00423658216829776,1,-4.99737571153344E-8,,,,,,,,,,,,,,,,,,,,,45.0233573913574,45.0233573913574,25.4346656799316,25.4346656799316,49.6662393689668,5.75993375258174,6.54756593704224,70,1,0,0,1,0.327911376953125,32.7468223571777,2,1,1,45.0233573913574,0,45.0233573913574,,,,,,,,,,,,,,,,,,,,,,,,,,,,,,,,,
,3864040907.39948,65.0324859619141,25.4346656799316,2.058700988751E-5,4.31573431458209E-8,1,5,14.0008964538574,5.00015501181462,35.9899997711182,0.0268763208865929,0.00399240968430058,1,-5.03157402360943E-8,,,,,,,,,,,,,,,,,,,,,65.0324859619141,65.0324859619141,25.4346656799316,25.4346656799316,49.7420573353322,5.76103529230779,6.82724046707153,70,1,0,0,1,0.317230224609375,32.7468223571777,2,1,1,65.0324859619141,0,65.0324859619141,,,,,,,,,,,,,,,,,,,,,,,,,,,,,,,,,
,3864041032.29591,85.0351791381836,25.4346656799316,1.8905086603581E-5,7.8782655489203E-9,1,5,14.0008964538574,4.9996944055286,36.0199995338917,0.02467541129529,0.00367884626056712,1,-3.61788860565758E-8,,,,,,,,,,,,,,,,,,,,,85.0351791381836,85.0351791381836,25.4346656799316,25.4346656799316,49.8112314592841,5.76342558474114,6.97769594192505,70,1,0,0,1,0.313644409179687,32.2580642700195,2,1,1,85.0351791381836,0,85.0351791381836,,,,,,,,,,,,,,,,,,,,,,,,,,,,,,,,,
,3864041153.39815,105.001091003418,25.4346656799316,1.44129414474421E-5,8.53896008733424E-9,1,5,14.0008964538574,4.99877130058331,36.0600017011166,0.0188055645394095,0.0028153338929948,1,-1.88704554845552E-8,,,,,,,,,,,,,,,,,,,,,105.001091003418,105.001091003418,25.4346656799316,25.4346656799316,49.7733224761014,5.76624929109111,7.06653118133545,70,1,0,0,1,0.316696166992188,32.7468223571777,2,1,1,105.001091003418,0,105.001091003418,,,,,,,,,,,,,,,,,,,,,,,,,,,,,,,,,
,3864041274.94928,125.057518005371,25.4346656799316,1.2774026536021E-5,6.89349254949897E-9,1,5,14.0008964538574,4.99851301147062,36.1099988222122,0.0166665892686218,0.00249079914231244,1,-1.99588599571175E-8,,,,,,,,,,,,,,,,,,,,,125.057518005371,125.057518005371,25.4346656799316,25.4346656799316,49.7315053503226,5.76723221244611,7.14519309997559,69,1,64,0,0,0.316925048828125,32.7468223571777,2,1,1,125.057518005371,0,125.057518005371,,,,,,,,,,,,,,,,,,,,,,,,,,,,,,,,,
,3864041395.7902,145.026489257813,25.4346656799316,1.24493924117469E-5,6.06689131967868E-9,1,5,14.0008964538574,4.99829149765701,36.1599996685982,0.0162425482951047,0.00242386768255642,1,-2.21200740105471E-8,,,,,,,,,,,,,,,,,,,,,145.026489257813,145.026489257813,25.4346656799316,25.4346656799316,49.8385884574572,5.76830931224638,7.20411968231201,70,1,0,0,1,0.320358276367188,33.2355842590332,2,1,1,145.026489257813,0,145.026489257813,,,,,,,,,,,,,,,,,,,,,,,,,,,,,,,,,
,3864041516.55537,165.002792358398,25.4346656799316,1.23268786940551E-5,5.99158880050255E-9,1,5,14.0008964538574,4.99836727703413,36.2300015985966,0.0160831900417505,0.00239912504358253,1,-2.26234208946312E-8,,,,,,,,,,,,,,,,,,,,,165.002792358398,165.002792358398,25.4346656799316,25.4346656799316,49.7326777931014,5.76804370302018,7.2570481300354,69,1,64,0,0,0.318832397460937,32.7468223571777,2,1,1,165.002792358398,0,165.002792358398,,,,,,,,,,,,,,,,,,,,,,,,,,,,,,,,,
,3864041637.01921,185.01286315918,25.4346656799316,1.22078622178212E-5,5.87628738497117E-9,1,5,14.0008964538574,4.99847613796661,36.3099984824657,0.0159279013342603,0.00237928407645378,1,-1.99132961860035E-8,,,,,,,,,,,,,,,,,,,,,185.01286315918,185.01286315918,25.4346656799316,25.4346656799316,49.7627704910918,5.76810581260018,7.30971431732178,70,1,0,0,1,0.3173828125,32.7468223571777,2,1,1,185.01286315918,0,185.01286315918,,,,,,,,,,,,,,,,,,,,,,,,,,,,,,,,,
,3864041758.22558,205.057052612305,25.4346656799316,1.20910740627932E-5,7.71146511829632E-9,1,5,14.0008964538574,4.99854443688947,36.3899990916252,0.0157744530754528,0.00236566299146616,1,-1.27499736969899E-8,,,,,,,,,,,,,,,,,,,,,205.057052612305,205.057052612305,25.4346656799316,25.4346656799316,49.7596439770149,5.76775274016509,7.36767101287842,69,1,64,0,0,0.319747924804687,32.7468223571777,2,1,1,205.057052612305,0,205.057052612305,,,,,,,,,,,,,,,,,,,,,,,,,,,,,,,,,
,3864041877.94703,225.005859375,25.4346656799316,1.19843767767121E-5,6.10430829914036E-9,1,5,14.0008964538574,4.9985632459887,36.4799983799458,0.015636809703313,0.00233503214785761,1,-2.01253684141041E-8,,,,,,,,,,,,,,,,,,,,,225.005859375,225.005859375,25.4346656799316,25.4346656799316,49.8010702885341,5.76667826576555,7.47160053253174,69,1,64,0,0,0.315017700195313,32.7468223571777,2,1,1,225.005859375,0,225.005859375,,,,,,,,,,,,,,,,,,,,,,,,,,,,,,,,,
,3864041998.55381,245.006225585938,25.4346656799316,1.18299810038122E-5,6.55688792373295E-9,1,5,14.0008964538574,4.99856585217356,36.5800000727177,0.0154365124403211,0.00229739182688754,1,-2.56613777133419E-8,,,,,,,,,,,,,,,,,,,,,245.006225585938,245.006225585938,25.4346656799316,25.4346656799316,49.7033667236303,5.76719164002095,7.59034442901611,68,1,64,0,0,0.317153930664063,33.2355842590332,2,1,1,245.006225585938,0,245.006225585938,,,,,,,,,,,,,,,,,,,,,,,,,,,,,,,,,
,3864042119.14598,265.016479492187,25.4346656799316,1.16833192891963E-5,6.76888218049757E-9,1,5,14.0008964538574,4.99906416882584,36.6900004446506,0.0152471684608798,0.00226988662230975,1,-2.48375530974013E-8,,,,,,,,,,,,,,,,,,,,,265.016479492187,265.016479492187,25.4346656799316,25.4346656799316,49.8264732154091,5.76647130189055,7.85744571685791,69,1,64,0,0,0.31646728515625,32.2580642700195,2,1,1,265.016479492187,0,265.016479492187,,,,,,,,,,,,,,,,,,,,,,,,,,,,,,,,,
,3864042239.47441,285.062957763672,25.4346656799316,1.14874516347952E-5,6.70372860234578E-9,1,5,14.0008964538574,4.99975482337306,36.8000008165836,0.0149939267986383,0.00223576279260388,1,-2.17402285384447E-8,,,,,,,,,,,,,,,,,,,,,285.062957763672,285.062957763672,25.4346656799316,25.4346656799316,49.6724923971206,5.76473492847774,7.74672317504883,69,1,64,0,0,0.319900512695313,32.7468223571777,2,1,1,285.062957763672,0,285.062957763672,,,,,,,,,,,,,,,,,,,,,,,,,,,,,,,,,
,3864044103.66698,10.0001459121704,25.4346656799316,1.61307505558865E-5,9.26354928721213E-9,1,5,14.0008964538574,4.9787324261162,35.9500013291836,0.0209259099875306,0.00315081818095791,1,-7.51036947489905E-9,,,,,,,,,,,,,,,,,,,,,10.0001459121704,10.0001459121704,25.4346656799316,25.4346656799316,49.6509976128418,5.7639043847681,5.14446353912354,70,1,0,0,1,0.31341552734375,29.8142719268799,1,1,1,10.0001459121704,0,10.0001459121704,,,,,,,,,,,,,,,,,,,,,,,,,,,,,,,,,
,3864044204.13987,25.0226879119873,25.4346656799316,1.54436270587685E-5,1.14741888273018E-8,1,5,14.0008964538574,4.97831985781615,35.9500013291836,0.0200362706861691,0.00298924603138686,1,-2.80110224007184E-8,,,,,,,,,,,,,,,,,,,,,25.0226879119873,25.0226879119873,25.4346656799316,25.4346656799316,49.6896882245437,5.7629292190151,6.06203985214233,70,1,0,0,1,0.314102172851562,32.2580642700195,2,1,1,25.0226879119873,0,25.0226879119873,,,,,,,,,,,,,,,,,,,,,,,,,,,,,,,,,
,3864044332.80467,45.048469543457,25.4346656799316,1.47769406726817E-5,1.2932218366826E-8,1,5,14.0008964538574,4.97897164888657,35.9600000083447,0.0191769207726801,0.00284704940042167,1,-3.73474165205227E-8,,,,,,,,,,,,,,,,,,,,,45.048469543457,45.048469543457,25.4346656799316,25.4346656799316,49.6693658830437,5.76085207266809,6.5903491973877,69,1,64,0,0,0.3131103515625,32.2580642700195,2,1,1,45.048469543457,0,45.048469543457,,,,,,,,,,,,,,,,,,,,,,,,,,,,,,,,,
,3864044459.41273,65.0113296508789,25.4346656799316,1.42976244445746E-5,2.0085604910862E-8,1,5,14.0008964538574,4.97854530028932,35.9899997711182,0.0185511577123821,0.00276424170155705,1,-2.85243557265549E-8,,,,,,,,,,,,,,,,,,,,,65.0113296508789,65.0113296508789,25.4346656799316,25.4346656799316,49.6697566973033,5.76278699288961,6.83623790740967,68,1,64,0,0,0.314483642578125,31.7693061828613,2,1,1,65.0113296508789,0,65.0113296508789,,,,,,,,,,,,,,,,,,,,,,,,,,,,,,,,,
,3864044584.66883,85.012565612793,25.4346656799316,1.38534405326383E-5,6.82276288938066E-8,1,5,14.0008964538574,4.97755956095977,36.0199995338917,0.017960182526666,0.00274144970946009,1,2.15853454635744E-8,,,,,,,,,,,,,,,,,,,,,85.012565612793,85.012565612793,25.4346656799316,25.4346656799316,49.6881249675053,5.76624083527242,6.99306774139404,70,1,0,0,1,0.315093994140625,32.2580642700195,2,1,1,85.012565612793,0,85.012565612793,,,,,,,,,,,,,,,,,,,,,,,,,,,,,,,,,
,3864044705.68834,105.023918151855,25.4346656799316,1.2697558667004E-5,1.26522118641254E-8,1,5,14.0008964538574,4.97751314655309,36.0600017011166,0.0164690317609591,0.00246237098435001,1,-1.90124278017508E-8,,,,,,,,,,,,,,,,,,,,,105.023918151855,105.023918151855,25.4346656799316,25.4346656799316,49.6775729824956,5.7662492734961,7.0792350769043,70,1,0,0,1,0.31524658203125,32.7468223571777,2,1,1,105.023918151855,0,105.023918151855,,,,,,,,,,,,,,,,,,,,,,,,,,,,,,,,,
,3864044826.72243,125.028747558594,25.4346656799316,1.25276941023131E-5,6.70563274061733E-8,1,5,14.0008964538574,4.97769868441146,36.1099988222122,0.0162504827341577,0.00242348418354555,1,-2.34413403254015E-8,,,,,,,,,,,,,,,,,,,,,125.028747558594,125.028747558594,25.4346656799316,25.4346656799316,49.7299420932841,5.76620186939488,7.15461921691895,68,1,64,0,0,0.31494140625,32.2580642700195,2,1,1,125.028747558594,0,125.028747558594,,,,,,,,,,,,,,,,,,,,,,,,,,,,,,,,,
,3864044948.01754,145.032836914062,25.4346656799316,1.23573128452202E-5,1.28165763234192E-8,1,5,14.0008964538574,4.9876618773339,36.1599996685982,0.0160738818008951,0.00240184205735011,1,-1.95918339499693E-8,,,,,,,,,,,,,,,,,,,,,145.032836914062,145.032836914062,25.4346656799316,25.4346656799316,49.6408364420918,5.76830640978619,7.21402597427368,70,1,0,0,1,0.317306518554687,32.2580642700195,2,1,1,145.032836914062,0,145.032836914062,,,,,,,,,,,,,,,,,,,,,,,,,,,,,,,,,
,3864045068.29625,165.040252685547,25.4346656799316,1.22834828941308E-5,1.12730035547515E-8,1,5,14.0008964538574,4.98809118188071,36.2300015985966,0.0159795838253823,0.0023890634228214,1,-1.84883941714695E-8,,,,,,,,,,,,,,,,,,,,,165.040252685547,165.040252685547,25.4346656799316,25.4346656799316,49.8081049452072,5.76578585100434,7.25383615493774,70,1,0,0,1,0.313796997070313,32.7468223571777,2,1,1,165.040252685547,0,165.040252685547,,,,,,,,,,,,,,,,,,,,,,,,,,,,,,,,,
,3864045188.94083,185.026611328125,25.4346656799316,1.2195131997239E-5,1.17834513343398E-8,1,5,14.0008964538574,4.98823427572404,36.3099984824657,0.0158662063174164,0.00236588909262632,1,-2.30346895044406E-8,,,,,,,,,,,,,,,,,,,,,185.026611328125,185.026611328125,25.4346656799316,25.4346656799316,49.8510945137649,5.76434482331004,7.30929088592529,69,1,64,0,0,0.313644409179687,32.7468223571777,2,1,1,185.026611328125,0,185.026611328125,,,,,,,,,,,,,,,,,,,,,,,,,,,,,,,,,
,3864045309.11975,205.019638061523,25.4346656799316,1.21002266567487E-5,4.13621420820081E-8,1,5,14.0008964538574,4.98787606150745,36.3899990916252,0.0157386240895064,0.00236392880410827,1,-1.00234943974439E-8,,,,,,,,,,,,,,,,,,,,,205.019638061523,205.019638061523,25.4346656799316,25.4346656799316,49.7944264461207,5.76563003782779,7.36317491531372,69,1,64,0,0,0.314788818359375,32.7468223571777,2,1,1,205.019638061523,0,205.019638061523,,,,,,,,,,,,,,,,,,,,,,,,,,,,,,,,,
,3864045430.15237,225.039703369141,25.4346656799316,1.19676903618252E-5,9.3432231155811E-9,1,5,14.0008964538574,4.98789997811087,36.4799983799458,0.0155693552543334,0.00231809252355668,1,-2.52607931942315E-8,,,,,,,,,,,,,,,,,,,,,225.039703369141,225.039703369141,25.4346656799316,25.4346656799316,49.7772306186976,5.76595188227978,7.47235250473022,69,1,64,0,0,0.315704345703125,32.7468223571777,2,1,1,225.039703369141,0,225.039703369141,,,,,,,,,,,,,,,,,,,,,,,,,,,,,,,,,
,3864045550.472,245.029037475586,25.4346656799316,1.18055152296686E-5,5.7901419925659E-8,1,5,14.0008964538574,4.98799535133405,36.5800000727177,0.0153662458699692,0.00223735291882537,1,-6.28928743706001E-8,,,,,,,,,,,,,,,,,,,,,245.029037475586,245.029037475586,25.4346656799316,25.4346656799316,49.7393216355149,5.76649706223853,7.58502578735352,68,1,64,0,0,0.320968627929687,32.2580642700195,2,1,1,245.029037475586,0,245.029037475586,,,,,,,,,,,,,,,,,,,,,,,,,,,,,,,,,
,3864045671.02656,265.051696777344,25.4346656799316,1.16668124309401E-5,3.15296057822268E-8,1,5,14.0008964538574,4.98799904743861,36.6900004446506,0.015186868579892,0.00220349029076284,1,-6.7980855776012E-8,,,,,,,,,,,,,,,,,,,,,265.051696777344,265.051696777344,25.4346656799316,25.4346656799316,49.6857800819476,5.76713550210591,7.86552667617798,68,1,64,0,0,0.314865112304687,31.7693061828613,2,1,1,265.051696777344,0,265.051696777344,,,,,,,,,,,,,,,,,,,,,,,,,,,,,,,,,
,3864045792.11331,285.016723632813,25.4346656799316,1.15081753939984E-5,1.00154732195394E-8,1,5,14.0008964538574,4.98873869388238,36.8000008165836,0.014974366577063,0.0022343606225611,1,-2.06408627142597E-8,,,,,,,,,,,,,,,,,,,,,285.016723632813,285.016723632813,25.4346656799316,25.4346656799316,49.819438558736,5.76415356695029,7.73865222930908,67,1,64,0,0,0.31494140625,32.7468223571777,2,1,1,285.016723632813,0,285.016723632813,,,,,,,,,,,,,,,,,,,,,,,,,,,,,,,,,
,3864046477.28848,300.001739501953,25.3093090057373,1.78781426316966E-5,1.96673581752826E-8,1,5,14.0008964538574,5.01026288551941,36.8800014257431,0.023402758364595,0.003497963541281,1,-2.75952643762224E-8,,,,,,,,,,,,,,,,,,,,,300.001739501953,300.001739501953,25.3093090057373,25.3093090057373,49.731114536063,5.76188713029717,8.31996250152588,70,1,0,0,1,0.324478149414063,29.8142719268799,1,1,1,300.001739501953,0,300.001739501953,,,,,,,,,,,,,,,,,,,,,,,,,,,,,,,,,
,3864046601.70267,284.826019287109,25.3093090057373,1.80410921958586E-5,5.03295021322099E-8,1,5,14.0008964538574,5.01027689779572,36.8000008165836,0.0236182646143021,0.00351588691370451,1,-3.85232564459393E-8,,,,,,,,,,,,,,,,,,,,,284.826019287109,284.826019287109,25.3093090057373,25.3093090057373,49.707665680486,5.7616284434841,8.32792568206787,69,1,64,0,0,0.32958984375,31.2805480957031,2,1,1,284.826019287109,0,284.826019287109,,,,,,,,,,,,,,,,,,,,,,,,,,,,,,,,,
,3864046714.37337,264.985443115234,25.3093090057373,1.82464409783939E-5,9.44599211395904E-8,1,5,14.0008964538574,5.01012528010213,36.7100015282631,0.0238732064948566,0.0036410100494094,1,2.6184865854365E-8,,,,,,,,,,,,,,,,,,,,,264.985443115234,264.985443115234,25.3093090057373,25.3093090057373,49.6400548135726,5.76215210938914,8.19982624053955,69,1,64,0,0,0.327987670898438,34.7018585205078,2,1,1,264.985443115234,0,264.985443115234,,,,,,,,,,,,,,,,,,,,,,,,,,,,,,,,,
,3864046834.07637,244.954467773438,25.3093090057373,1.83544898085172E-5,9.11410296373668E-8,1,5,14.0008964538574,5.0100690390584,36.6099998354912,0.0240248322657753,0.00359211045782398,1,-2.74586075460696E-8,,,,,,,,,,,,,,,,,,,,,244.954467773438,244.954467773438,25.3093090057373,25.3093090057373,49.7189992940149,5.76262191093465,8.10219573974609,69,1,64,0,0,0.32745361328125,32.7468223571777,2,1,1,244.954467773438,0,244.954467773438,,,,,,,,,,,,,,,,,,,,,,,,,,,,,,,,,
,3864046954.48525,224.960494995117,25.3093090057373,1.83107056170966E-5,9.59023595354283E-8,1,5,14.0008964538574,5.01038499335577,36.5400016307831,0.0239686510070762,0.00359036822292553,1,-2.24183336282465E-8,,,,,,,,,,,,,,,,,,,,,224.960494995117,224.960494995117,25.3093090057373,25.3093090057373,49.7287696505053,5.76046310856659,8.03354644775391,68,1,64,0,0,0.32867431640625,33.2355842590332,2,1,1,224.960494995117,0,224.960494995117,,,,,,,,,,,,,,,,,,,,,,,,,,,,,,,,,
,3864047074.95495,204.945220947266,25.3093090057373,1.80737129266667E-5,8.64422933325158E-8,1,5,14.0008964538574,5.01068855584658,36.4699997007847,0.0236885768596267,0.00335786561269879,1,-1.64490514019503E-7,,,,,,,,,,,,,,,,,,,,,204.945220947266,204.945220947266,25.3093090057373,25.3093090057373,49.6826535678706,5.75858329273813,7.96178150177002,68,1,64,0,0,0.32562255859375,32.7468223571777,2,1,1,204.945220947266,0,204.945220947266,,,,,,,,,,,,,,,,,,,,,,,,,,,,,,,,,
,3864047195.32347,184.963104248047,25.3093090057373,1.79004515254739E-5,2.61088661629082E-8,1,5,14.0008964538574,5.01083910219084,36.3899990916252,0.0234300811124276,0.00354027538113553,1,9.31214770663252E-10,,,,,,,,,,,,,,,,,,,,,184.963104248047,184.963104248047,25.3093090057373,25.3093090057373,49.717826851236,5.75886179508888,7.8902006149292,70,1,0,0,1,0.329208374023438,32.2580642700195,2,1,1,184.963104248047,0,184.963104248047,,,,,,,,,,,,,,,,,,,,,,,,,,,,,,,,,
,3864047314.78975,164.918319702148,25.3093090057373,1.74469556377674E-5,1.89318218308186E-8,1,5,14.0008964538574,5.01080705789439,36.3299995660782,0.022841008222685,0.00341932817486543,1,-2.29487946836484E-8,,,,,,,,,,,,,,,,,,,,,164.918319702148,164.918319702148,25.3093090057373,25.3093090057373,49.7373675642168,5.75838020066348,7.83817577362061,70,1,0,0,1,0.328521728515625,32.2580642700195,2,1,1,164.918319702148,0,164.918319702148,,,,,,,,,,,,,,,,,,,,,,,,,,,,,,,,,
,3864047433.7011,144.970504760742,25.3093090057373,1.67549043199823E-5,1.67044146067567E-8,1,5,14.0008964538574,5.01083395095505,36.2700000405312,0.0219368045476602,0.00327283952224781,1,-3.03523480218773E-8,,,,,,,,,,,,,,,,,,,,,144.970504760742,144.970504760742,25.3093090057373,25.3093090057373,49.7588623484957,5.75816903642209,7.76628541946411,70,1,0,0,1,0.328292846679687,32.2580642700195,2,1,1,144.970504760742,0,144.970504760742,,,,,,,,,,,,,,,,,,,,,,,,,,,,,,,,,
,3864047553.26398,124.994163513184,25.3093090057373,1.55162309577984E-5,1.60937053562532E-8,1,5,14.0008964538574,5.01065451266744,36.2100005149841,0.0203120973839503,0.00304346986397643,1,-1.83748673960075E-8,,,,,,,,,,,,,,,,,,,,,124.994163513184,124.994163513184,25.3093090057373,25.3093090057373,49.6685842545245,5.75890751962184,7.70230913162231,70,1,0,0,1,0.328903198242188,32.2580642700195,2,1,1,124.994163513184,0,124.994163513184,,,,,,,,,,,,,,,,,,,,,,,,,,,,,,,,,
,3864047673.99198,104.98802947998,25.3093090057373,1.22995482831275E-5,1.47783834697188E-8,1,5,14.0008964538574,5.0107125225304,36.1599996685982,0.0161034778085669,0.00239907480970316,1,-2.4872002448291E-8,,,,,,,,,,,,,,,,,,,,,104.98802947998,104.98802947998,25.3093090057373,25.3093090057373,49.7123554516014,5.75809464050761,7.61737632751465,70,1,0,0,1,0.328903198242188,32.2580642700195,2,1,1,104.98802947998,0,104.98802947998,,,,,,,,,,,,,,,,,,,,,,,,,,,,,,,,,
,3864047793.76803,84.98095703125,25.3093090057373,1.08903740029722E-5,1.24470294375771E-8,1,5,14.0008964538574,5.01049118774362,36.0900014638901,0.014256799307219,0.00212939526314095,1,-1.79602205320679E-8,,,,,,,,,,,,,,,,,,,,,84.98095703125,84.98095703125,25.3093090057373,25.3093090057373,49.7647245623899,5.76033170032362,7.52483224868774,70,1,0,0,1,0.326461791992188,32.7468223571777,2,1,1,84.98095703125,0,84.98095703125,,,,,,,,,,,,,,,,,,,,,,,,,,,,,,,,,
,3864047911.3199,64.9794158935547,25.3093090057373,1.07202743099276E-5,2.63023670733349E-8,1,5,14.0008964538574,5.01035552609009,36.0499992966652,0.0140337839948818,0.00209475466750858,1,-1.86742876863439E-8,,,,,,,,,,,,,,,,,,,,,64.9794158935547,64.9794158935547,25.3093090057373,25.3093090057373,49.690469853063,5.75940442166108,7.39881610870361,70,1,0,0,1,0.327224731445313,32.2580642700195,2,1,1,64.9794158935547,0,64.9794158935547,,,,,,,,,,,,,,,,,,,,,,,,,,,,,,,,,
,3864048027.31997,44.9895553588867,25.3093090057373,1.06173573070954E-5,4.3557700486009E-8,1,5,14.0008964538574,5.00998772065361,36.0100008547306,0.013900582869715,0.00205488452576739,1,-3.34323531559321E-8,,,,,,,,,,,,,,,,,,,,,44.9895553588867,44.9895553588867,25.3093090057373,25.3093090057373,49.6955504384379,5.76133593282984,7.19351625442505,70,1,0,0,1,0.3271484375,32.7468223571777,2,1,1,44.9895553588867,0,44.9895553588867,,,,,,,,,,,,,,,,,,,,,,,,,,,,,,,,,
,3864048144.4618,24.9587059020996,25.3093090057373,1.06338652796831E-5,7.50512921142532E-8,1,5,14.0008964538574,5.0098613948227,35.9899997711182,0.0139181963774492,0.00208123509285575,1,-1.57334512026407E-8,,,,,,,,,,,,,,,,,,,,,24.9587059020996,24.9587059020996,25.3093090057373,25.3093090057373,49.6775729824956,5.76097812470146,6.74397945404053,68,1,64,0,0,0.326995849609375,32.2580642700195,2,1,1,24.9587059020996,0,24.9587059020996,,,,,,,,,,,,,,,,,,,,,,,,,,,,,,,,,
,3864048401.02431,9.99878120422363,25.3093090057373,1.04042156374494E-5,1.48572703182794E-8,1,5,14.0008964538574,5.00875905267319,35.9500013291836,0.0136129091856119,0.002039104704233,1,-1.27621236893963E-8,,,,,,,,,,,,,,,,,,,,,9.99878120422363,9.99878120422363,25.3093090057373,25.3093090057373,49.7018034665918,5.76634971173154,5.1812858581543,70,1,0,0,1,0.320968627929687,32.7468223571777,1,1,1,9.99878120422363,0,9.99878120422363,,,,,,,,,,,,,,,,,,,,,,,,,,,,,,,,,
,3864048500.93665,25.0025024414062,25.3093090057373,1.05588739371567E-5,1.69710325268443E-8,1,5,14.0008964538574,5.00864775623247,35.9500013291836,0.0138150500118467,0.00206793059615317,1,-1.40381485202616E-8,,,,,,,,,,,,,,,,,,,,,25.0025024414062,25.0025024414062,25.3093090057373,25.3093090057373,49.590812216861,5.76693469434034,6.11037158966065,70,1,0,0,1,0.321578979492188,31.7693061828613,2,1,1,25.0025024414062,0,25.0025024414062,,,,,,,,,,,,,,,,,,,,,,,,,,,,,,,,,
,3864048629.6846,45.0155906677246,25.3093090057373,1.06290060860144E-5,1.18316910389094E-8,1,5,14.0008964538574,5.0092482559752,35.9600000083447,0.0139099868645358,0.00207641466497406,1,-1.84117073768803E-8,,,,,,,,,,,,,,,,,,,,,45.0155906677246,45.0155906677246,25.3093090057373,25.3093090057373,49.7213441795726,5.76421823999054,6.60651063919067,70,1,0,0,1,0.320053100585937,31.7693061828613,2,1,1,45.0155906677246,0,45.0155906677246,,,,,,,,,,,,,,,,,,,,,,,,,,,,,,,,,
,3864048756.52871,65.0615463256836,25.3093090057373,1.06548719688989E-5,1.45357298661974E-8,1,5,14.0008964538574,5.00827542915408,35.9800010919571,0.0139397621687459,0.0020828136299745,1,-1.69953622067075E-8,,,,,,,,,,,,,,,,,,,,,65.0615463256836,65.0615463256836,25.3093090057373,25.3093090057373,49.6611587835918,5.76905840175683,6.84001779556274,70,1,0,0,1,0.32806396484375,32.2580642700195,2,1,1,65.0615463256836,0,65.0615463256836,,,,,,,,,,,,,,,,,,,,,,,,,,,,,,,,,
,3864048881.25426,85.0263366699219,25.3093090057373,1.07303043114103E-5,1.46666498517714E-8,1,5,14.0008964538574,5.00812246265742,36.0199995338917,0.0140407995563988,0.00207794648787217,1,-3.20423901133071E-8,,,,,,,,,,,,,,,,,,,,,85.0263366699219,85.0263366699219,25.3093090057373,25.3093090057373,49.7670694479476,5.76915775972988,7.03176307678223,68,1,64,0,0,0.320663452148438,32.7468223571777,2,1,1,85.0263366699219,0,85.0263366699219,,,,,,,,,,,,,,,,,,,,,,,,,,,,,,,,,
,3864049002.58405,105.012893676758,25.3093090057373,1.17551363803757E-5,4.71954684740598E-8,1,5,14.0008964538574,5.00795579324223,36.0600017011166,0.0153924460573158,0.0022011534270527,1,-9.25611606030573E-8,,,,,,,,,,,,,,,,,,,,,105.012893676758,105.012893676758,25.3093090057373,25.3093090057373,49.6291120143033,5.76982197352043,7.12443351745606,68,1,64,0,0,0.325241088867188,32.2580642700195,2,1,1,105.012893676758,0,105.012893676758,,,,,,,,,,,,,,,,,,,,,,,,,,,,,,,,,
,3864049123.95723,125.033256530762,25.3093090057373,1.35292024463901E-5,7.9033803995746E-8,1,5,14.0008964538574,5.00798323160919,36.1099988222122,0.0177083408799403,0.00258132506457027,1,-6.98619744553522E-8,,,,,,,,,,,,,,,,,,,,,125.033256530762,125.033256530762,25.3093090057373,25.3093090057373,49.6849984534283,5.77010690982848,7.19552421569824,68,1,64,0,0,0.324020385742188,32.7468223571777,2,1,1,125.033256530762,0,125.033256530762,,,,,,,,,,,,,,,,,,,,,,,,,,,,,,,,,
,3864049244.39105,145.024078369141,25.3093090057373,1.3769079627772E-5,4.36073350717774E-8,1,5,14.0008964538574,5.0080482173797,36.1599996685982,0.018015280044092,0.0026758841417726,1,-3.38320359079023E-8,,,,,,,,,,,,,,,,,,,,,145.024078369141,145.024078369141,25.3093090057373,25.3093090057373,49.6560781982168,5.76992211822246,7.25328302383423,68,1,64,0,0,0.32318115234375,32.2580642700195,2,1,1,145.024078369141,0,145.024078369141,,,,,,,,,,,,,,,,,,,,,,,,,,,,,,,,,
,3864049365.39403,165.013702392578,25.3093090057373,1.39352168050808E-5,1.35257897208648E-8,1,5,14.0008964538574,5.00765511351665,36.2300015985966,0.0182283746130224,0.00272294006687292,1,-2.27196997959933E-8,,,,,,,,,,,,,,,,,,,,,165.013702392578,165.013702392578,25.3093090057373,25.3093090057373,49.707665680486,5.77110385893931,7.29936456680298,69,1,64,0,0,0.321273803710937,32.7468223571777,2,1,1,165.013702392578,0,165.013702392578,,,,,,,,,,,,,,,,,,,,,,,,,,,,,,,,,
,3864049487.66434,185.315032958984,25.3093090057373,1.40152406191249E-5,3.38212955351769E-8,1,5,14.0008964538574,5.00866517932271,36.3099984824657,0.0183327522736945,0.00277557078486646,1,4.83950018635739E-9,,,,,,,,,,,,,,,,,,,,,185.315032958984,185.315032958984,25.3093090057373,25.3093090057373,49.7201717367937,5.76586810472842,7.35067510604858,68,1,64,0,0,0.326614379882812,32.2580642700195,2,1,1,185.315032958984,0,185.315032958984,,,,,,,,,,,,,,,,,,,,,,,,,,,,,,,,,
,3864049606.99345,205.148895263672,25.3093090057373,1.39999243980822E-5,5.37162806843784E-8,1,5,14.0008964538574,5.00880049357158,36.3899990916252,0.018311741887907,0.00278368287858252,1,1.32738842755853E-8,,,,,,,,,,,,,,,,,,,,,205.148895263672,205.148895263672,25.3093090057373,25.3093090057373,49.6572506409956,5.76740652421039,7.40150499343872,68,1,64,0,0,0.32745361328125,32.2580642700195,2,1,1,205.148895263672,0,205.148895263672,,,,,,,,,,,,,,,,,,,,,,,,,,,,,,,,,
,3864049726.53766,225.026702880859,25.3093090057373,1.39286226561443E-5,1.22256749687296E-8,1,5,14.0008964538574,5.00850000807513,36.4799983799458,0.0182256661319417,0.00271158017544318,1,-3.08993356039529E-8,,,,,,,,,,,,,,,,,,,,,225.026702880859,225.026702880859,25.3093090057373,25.3093090057373,49.7131370801206,5.76702795066689,7.49946594238281,70,1,0,0,1,0.326156616210937,33.7243423461914,2,1,1,225.026702880859,0,225.026702880859,,,,,,,,,,,,,,,,,,,,,,,,,,,,,,,,,
,3864049847.50648,245.017196655273,25.3093090057373,1.3826880986009E-5,1.26925137370521E-8,1,5,14.0008964538574,5.00858372643332,36.5800000727177,0.0180915675904449,0.0027010519076501,1,-2.36286144610699E-8,,,,,,,,,,,,,,,,,,,,,245.017196655273,245.017196655273,25.3093090057373,25.3093090057373,49.6685842545245,5.76809626789857,7.61092329025269,69,1,64,0,0,0.328903198242188,32.2580642700195,2,1,1,245.017196655273,0,245.017196655273,,,,,,,,,,,,,,,,,,,,,,,,,,,,,,,,,
,3864049968.45357,265.037170410156,25.3093090057373,1.3689157832645E-5,1.10801594933585E-8,1,5,14.0008964538574,5.00919096126345,36.6900004446506,0.0179143519332469,0.00267493409579151,1,-2.31388934596889E-8,,,,,,,,,,,,,,,,,,,,,265.037170410156,265.037170410156,25.3093090057373,25.3093090057373,49.799116217236,5.76462289798296,7.8823127746582,70,1,0,0,1,0.3253173828125,32.2580642700195,2,1,1,265.037170410156,0,265.037170410156,,,,,,,,,,,,,,,,,,,,,,,,,,,,,,,,,
,3864050088.43479,285.030395507813,25.3093090057373,1.35411914116481E-5,1.23291374419357E-8,1,5,14.0008964538574,5.00927997994187,36.8000008165836,0.0177238292538702,0.00262838538889761,1,-3.64180474597712E-8,,,,,,,,,,,,,,,,,,,,,285.030395507813,285.030395507813,25.3093090057373,25.3093090057373,49.7643337481303,5.76634621992695,7.75689029693603,68,1,64,0,0,0.327987670898438,32.2580642700195,2,1,1,285.030395507813,0,285.030395507813,,,,,,,,,,,,,,,,,,,,,,,,,,,,,,,,,
,3864051360.58485,9.99812459945679,25.3093090057373,,,5,,,,35.9600000083447,,,,,7.12987952001677E-6,3.6446306826568E-8,0.266324689550022,0.00448324913430315,2.37662651539865E-6,1.21487689867966E-8,2.37660084055813E-6,5.83546782984619E-9,1.10470970983547E-8,1.06555104571007E-8,2.99999998898473,1.00057637691498,19.98847910208,20,1,3,0.0250907396914407,0.000421683676720194,0.000312793185003102,277.75284576416,9.99442481994629,10.0004930496216,25.3093090057373,25.3093090057373,,,5.23217296600342,,1,,,,,,1,1,1,9.99703979492188,0,9.99848503362937,,,,,,,,,,,,,,,,,,,,,,,,,,,,,,,,,
,3864051842.2797,20.0000352859497,25.3093090057373,,,5,,,,35.9600000083447,,,,,3.84219940813686E-6,1.05078717616822E-8,-0.177902574581431,0.00222022773470522,1.28073371646881E-6,3.50262550793604E-9,1.28072754273785E-6,2.04609438539856E-9,-3.97665345234303E-9,2.84286531775333E-9,2.99999864041248,10.005763053894,10,100,1,3,0.0134534256554824,0.00127947605927722,0.00394931668415666,254.585304260254,19.9994678497314,20.000337600708,25.3093090057373,25.3093090057373,,,5.95777082443237,,1,,,,,,1,1,1,20.0000305175781,0,20.0000194081089,,,,,,,,,,,,,,,,,,,,,,,,,,,,,,,,,
,3864052283.48353,29.999942779541,25.3093090057373,,,5,,,,35.9600000083447,,,,,2.60406130612903E-6,6.22145327673854E-9,0.219158412752741,0.00208759976654451,8.68050472595491E-7,2.07388952187598E-9,8.68044122423608E-7,1.00793548261248E-9,3.32031611197064E-9,1.81248001694852E-9,2.99989619076276,100.057640075684,10,1000,1,3,0.00907034529982547,0.00111423406280363,0.012779762968421,197.885971069336,29.9996795654297,30.0005207061768,25.3093090057373,25.3093090057373,,,6.32043313980103,,1,,,,,,1,1,1,30.0000247955322,0,30.0000906343813,,,,,,,,,,,,,,,,,,,,,,,,,,,,,,,,,
,3864052900.3165,50.0001792907715,25.3093090057373,,,5,,,,35.9800010919571,,,,,1.62635938644116E-6,4.88017506828503E-8,0.187633354468488,0.017978923462845,5.42119808500156E-7,1.62672506182977E-8,5.42116901535755E-7,1.3024264385655E-8,1.77534152153239E-9,9.74638291321791E-9,2.99999992795078,1.00057637691498,19.98847910208,20,1,3,0.00572344477164834,8.82525978042367E-5,0.000394986680475995,259.23779296875,49.9981307983398,50.0006713867188,25.3093090057373,25.3093090057373,,,6.69066762924194,,1,,,,,,1,1,1,50.0004005432129,0,49.9998500859626,,,,,,,,,,,,,,,,,,,,,,,,,,,,,,,,,
,3864053394.28081,59.9999732971191,25.3093090057373,,,5,,,,35.9899997711182,,,,,1.31589488463142E-6,9.33870225546138E-9,0.00388670154504922,0.00402517268433176,4.38630172658639E-7,3.11289042199445E-9,4.38630171649419E-7,2.56425267834891E-9,2.97548018886935E-11,1.76484984656635E-9,3.00000995521005,10.005763053894,10,100,1,3,0.00460623684835623,0.000452241977469516,0.00392440194264054,254.60440826416,59.99951171875,60.0006408691406,25.3093090057373,25.3093090057373,,,6.82038831710815,,1,,,,,,1,1,1,60.000057220459,0,60.0000559050461,,,,,,,,,,,,,,,,,,,,,,,,,,,,,,,,,
,3864053857.47537,69.9999847412109,25.3093090057373,,,5,,,,35.9999984502792,,,,,1.11762175421617E-6,3.97502336062262E-9,0.573733163532933,0.00313880174057528,3.72557698180705E-7,1.32506865391747E-9,3.72539020000523E-7,6.21527681579096E-10,3.7305563600524E-9,1.17026077377034E-9,2.99986219496685,100.057640075684,10,1000,1,3,0.0038902883612189,0.000498658677211018,0.0127266403287649,197.625427246094,69.9991836547852,70.000602722168,25.3093090057373,25.3093090057373,,,6.8950629234314,,1,,,,,,1,1,1,70,0,69.9999792310927,,,,,,,,,,,,,,,,,,,,,,,,,,,,,,,,,
,3864054514.04326,89.9970626831055,25.3093090057373,,,5,,,,36.0299982130527,,,,,8.61091019747224E-7,4.00032230390024E-8,-1.30957013465998,0.0290110938617134,2.87030332779405E-7,1.33344073481387E-8,2.86955362150894E-7,1.04146606689005E-8,-6.55988325390848E-9,8.32714011397383E-9,3.00000007458797,1.00057637691498,19.98847910208,20,1,3,0.00303051700086722,-3.24751466665546E-5,0.00039717135950923,250.390472412109,89.9663772583008,90.000358581543,25.3093090057373,25.3093090057373,,,6.99763488769531,,1,,,,,,1,1,1,89.9986343383789,0,89.9936270462839,,,,,,,,,,,,,,,,,,,,,,,,,,,,,,,,,
,3864055017.75092,99.9996871948242,25.3093090057373,,,5,,,,36.0499992966652,,,,,7.81577780904821E-7,1.20287929935523E-8,0.56975728828736,0.00858836097966473,2.60525104107351E-7,4.00958500036047E-9,2.60512223079551E-7,3.33004445817473E-9,2.59065557266525E-9,2.23328810987194E-9,3.00000947541228,10.005763053894,10,100,1,3,0.00273310067354697,0.000295566900988063,0.0039225579239428,254.62572479248,99.9988555908203,100.001281738281,25.3093090057373,25.3093090057373,,,7.04583311080933,,1,,,,,,1,1,1,99.9998550415039,0,100.000014870854,,,,,,,,,,,,,,,,,,,,,,,,,,,,,,,,,
,3864055478.32503,110.000205993652,25.3093090057373,,,5,,,,36.0799990594387,,,,,7.05358103425121E-7,4.02932319705151E-9,0.70207079955626,0.00486209786029013,2.35141477745159E-7,1.34323403426827E-9,2.35123825076512E-7,7.03735400865047E-10,2.88122154075854E-9,1.14413030568459E-9,2.99971791531212,100.057640075684,10,1000,1,3,0.00245459925922174,0.000319884052867105,0.0127255050465465,197.636703491211,109.998229980469,110.00170135498,25.3093090057373,25.3093090057373,,,7.08239507675171,,1,,,,,,1,1,1,110.000228881836,0,110.000297828957,,,,,,,,,,,,,,,,,,,,,,,,,,,,,,,,,
,3864056140.35964,129.990379333496,25.3093090057373,,,5,,,,36.1299999058247,,,,,6.32197749395443E-7,3.3955270806974E-8,-0.63832068987707,0.0395643713839982,2.10732586182108E-7,1.13184237661556E-8,2.10719508529778E-7,7.65469597222144E-9,-2.34768055071894E-9,8.33740643864341E-9,2.99999995657586,1.00057637691498,19.98847910208,20,1,3,0.00222507845217533,2.22276505730016E-6,0.000250289333052933,280.358947753906,129.941177368164,129.999328613281,25.3093090057373,25.3093090057373,,,7.14237070083618,,1,,,,,,1,1,1,129.994750976562,0,129.985505649022,,,,,,,,,,,,,,,,,,,,,,,,,,,,,,,,,
,3864056645.88815,139.999984741211,25.3093090057373,,,5,,,,36.1500009894371,,,,,5.57480385771099E-7,8.22569315808354E-9,-0.308409359184227,0.00941096484051815,1.85826281670614E-7,2.74189014132902E-9,1.85823589603234E-7,2.11175641181054E-9,-1.00025321556789E-9,1.74884144629933E-9,3.00000829139583,10.005763053894,10,100,1,3,0.00195245783141328,0.000180902148567347,0.00395815586671233,254.628631591797,139.998016357422,140.001708984375,25.3093090057373,25.3093090057373,,,7.18022441864014,,1,,,,,,1,1,1,139.999908447266,0,140.000069716881,,,,,,,,,,,,,,,,,,,,,,,,,,,,,,,,,
,3864057108.58863,150.000144958496,25.3093090057373,,,5,,,,36.1800007522106,,,,,5.15061448388831E-7,6.05048287861016E-9,0.965244977922597,0.0113595258141441,1.71705059873557E-7,2.01703802174572E-9,1.71680694523081E-7,4.98920891703974E-10,2.89252731266386E-9,1.95435931317381E-9,2.99968707251911,100.057640075684,10,1000,1,3,0.00179131789942179,0.000241683707243882,0.0127708846703172,197.641815185547,149.998199462891,150.002655029297,25.3093090057373,25.3093090057373,,,7.20843935012817,,1,,,,,,1,1,1,149.999786376953,0,150.000304328071,,,,,,,,,,,,,,,,,,,,,,,,,,,,,,,,,
,3864057778.86802,169.98974609375,25.3093090057373,,,5,,,,36.2499989569187,,,,,4.35000208492219E-7,3.76919217048885E-8,2.90763504092117,0.0618000521499623,1.45000065357415E-7,1.25639735429073E-8,1.44813393211947E-7,8.80614004358398E-9,7.35527702378537E-9,8.96132404947296E-9,3.00000008565495,1.00057637691498,19.98847910208,20,1,3,0.00152799780982623,9.62179562255612E-5,8.54209938552231E-5,261.433395385742,169.931777954102,169.999877929687,25.3093090057373,25.3093090057373,,,7.26239633560181,,1,,,,,,1,1,1,169.995330810547,0,169.98295004326,,,,,,,,,,,,,,,,,,,,,,,,,,,,,,,,,
,3864058288.02482,180.000175476074,25.3093090057373,,,5,,,,36.2900011241436,,,,,4.14668516487048E-7,1.2248153728846E-8,-0.10156680274484,0.0181519167306402,1.38223022940608E-7,4.08272334775931E-9,1.38222805766236E-7,3.2211274785483E-9,-2.45024385260856E-10,2.50857882102198E-9,2.99999600403199,10.005763053894,10,100,1,3,0.00145179503148043,0.000139792970774338,0.00395305268466473,254.647789001465,179.997116088867,180.002731323242,25.3093090057373,25.3093090057373,,,7.28597450256348,,1,,,,,,1,1,1,180.000137329102,0,180.000237300478,,,,,,,,,,,,,,,,,,,,,,,,,,,,,,,,,
,3864058756.86852,190.000610351562,25.3093090057373,,,5,,,,36.3299995660782,,,,,4.07990204814928E-7,3.28096437608552E-9,0.111155264080199,0.00714522961076412,1.36006227884785E-7,1.09373113214365E-9,1.3600597194166E-7,5.01734540742298E-10,2.63855362862985E-10,9.71859166775896E-10,2.99979060635773,100.057640075684,10,1000,1,3,0.00142165787831044,0.000170189379905706,0.0127297760918736,197.65983581543,189.99658203125,190.003509521484,25.3093090057373,25.3093090057373,,,7.31272745132446,,1,,,,,,1,1,1,190.000259399414,0,190.000431852521,,,,,,,,,,,,,,,,,,,,,,,,,,,,,,,,,
,3864059416.27516,209.98365020752,25.3093090057373,,,5,,,,36.4100001752377,,,,,2.89865333133187E-7,6.72605814976092E-8,-2.74707602834263,0.134770225370249,9.66217718356664E-8,2.24201924692048E-8,9.65107373466864E-8,1.82561643728402E-8,-4.63080656716425E-9,1.30145108531988E-8,3.0000001824246,1.00057637691498,19.98847910208,20,1,3,0.00101955440753619,-3.65227398683819E-5,0.000456362031400204,255.743492126465,209.923965454102,210.00146484375,25.3093090057373,25.3093090057373,,,7.37699222564697,,1,,,,,,1,1,1,209.991363525391,0,209.979851259004,,,,,,,,,,,,,,,,,,,,,,,,,,,,,,,,,
,3864059929.45004,220.001190185547,25.3093090057373,,,5,,,,36.4600010216236,,,,,3.31364017997067E-7,1.2203597354358E-8,-1.42798963342855,0.0166538483899759,1.10454549537603E-7,4.06786125017901E-9,1.1042024623164E-7,3.62262732699675E-9,-2.75258709196047E-9,1.85042330303214E-9,3.00000334421951,10.005763053894,10,100,1,3,0.0011624134654558,8.48179768127185E-5,0.00395315559580922,254.636932373047,219.996292114258,220.005813598633,25.3093090057373,25.3093090057373,,,7.43187522888184,,1,,,,,,1,1,1,220.00048828125,0,220.001768985037,,,,,,,,,,,,,,,,,,,,,,,,,,,,,,,,,
,3864060402.41557,230.000961303711,25.3093090057373,,,5,,,,36.5099981427193,,,,,3.34535642129352E-7,4.28803314922393E-9,0.134543473965783,0.0110728881212727,1.11508618960661E-7,1.42930257441032E-9,1.11508311522161E-7,7.19874164070235E-10,2.61847265394444E-10,1.23478218205485E-9,3.00008775328277,100.057640075684,10,1000,1,3,0.0011656708913215,0.000139965966909946,0.0127328112721443,197.677322387695,229.994918823242,230.004943847656,25.3093090057373,25.3093090057373,,,7.49321222305298,,1,,,,,,1,1,1,230.000381469727,0,230.000973454228,,,,,,,,,,,,,,,,,,,,,,,,,,,,,,,,,
,3864061069.79452,249.982437133789,25.3093090057373,,,5,,,,36.6000011563301,,,,,2.66236936464441E-7,4.91694077630776E-8,-1.20805786461926,0.137980926663846,8.87456441814029E-8,1.63898023463593E-8,8.87259185383297E-8,1.08941568117744E-8,-1.87102664381139E-9,1.22451201836974E-8,3.0000000441738,1.00057637691498,19.98847910208,20,1,3,0.000937008493631957,-8.38318252831344E-6,0.000303445820463821,250.168190002441,249.916198730469,250.001983642578,25.3093090057373,25.3093090057373,,,7.68222427368164,,1,,,,,,1,1,1,249.990676879883,0,249.978152002607,,,,,,,,,,,,,,,,,,,,,,,,,,,,,,,,,
,3864061577.38642,260.000732421875,25.3093090057373,,,5,,,,36.6600006818771,,,,,2.60807192775605E-7,2.02871817859299E-8,-3.64600155101944,0.0185467724433415,8.69355758187626E-8,6.7623818635139E-9,8.67596176571746E-8,6.54145097530545E-9,-5.52838917956276E-9,1.71441757038858E-9,3.00000535246144,10.005763053894,10,100,1,3,0.00091680115398555,3.12947677938814E-5,0.00396045856177807,254.633758544922,259.996459960938,260.006072998047,25.3093090057373,25.3093090057373,,,7.87331104278564,,1,,,,,,1,1,1,259.999969482422,0,260.001172295932,,,,,,,,,,,,,,,,,,,,,,,,,,,,,,,,,
,3864062058.34876,270.000793457031,25.3093090057373,,,5,,,,36.7100015282631,,,,,2.7375204502172E-7,3.7304036245477E-9,0.660316646702911,0.0109377523879316,9.12445185598517E-8,1.24338389044281E-9,9.12384591377207E-8,7.4114994458196E-10,1.05154238792348E-9,9.98348766042635E-10,3.00020263510024,100.057640075684,10,1000,1,3,0.000952814844545263,0.000123239877283869,0.0127303553745151,197.684509277344,269.995452880859,270.005615234375,25.3093090057373,25.3093090057373,,,8.09807777404785,,1,,,,,,1,1,1,270.000122070313,0,270.000807328658,,,,,,,,,,,,,,,,,,,,,,,,,,,,,,,,,
,3864062724.49311,289.977203369141,25.3093090057373,,,5,,,,36.8300005793571,,,,,2.46149566752001E-7,5.10010366279387E-8,-0.755314493690304,0.157520006146939,8.20498523650738E-8,1.70003448756997E-8,8.20427229829826E-8,1.1044265066755E-8,-1.08160929544093E-9,1.29242382765091E-8,3.00000011769406,1.00057637691498,19.98847910208,20,1,3,0.000866346133077164,-9.05444157819857E-7,7.81474518589675E-5,267.865562438965,289.916229248047,289.998870849609,25.3093090057373,25.3093090057373,,,8.57609367370605,,1,,,,,,1,1,1,289.984436035156,0,289.975931408336,,,,,,,,,,,,,,,,,,,,,,,,,,,,,,,,,
,3864063229.02722,299.997344970703,25.3093090057373,,,5,,,,36.8900001049042,,,,,2.3545095568163E-7,1.07061556508842E-8,-0.0553454127337831,0.0223167332035626,7.84833571725502E-8,3.56870514906482E-9,7.84833205570022E-8,3.10968658388342E-9,-7.58117466392969E-11,1.75085858680169E-9,3.00001126562383,10.005763053894,10,100,1,3,0.000824274428753801,8.00278666866038E-5,0.00395670020952821,254.619827270508,299.992706298828,300.004302978516,25.3093090057373,25.3093090057373,,,8.76091480255127,,1,,,,,,1,1,1,299.997253417969,0,299.998149135657,,,,,,,,,,,,,,,,,,,,,,,,,,,,,,,,,
,3864063285.16143,299.998764038086,25.3093090057373,,,5,,,,36.8900001049042,,,,,2.41397972023994E-7,4.69864952971345E-9,1.57759773884872,0.016142175325635,8.04582550539754E-8,1.56606594123893E-9,8.04277578193269E-8,8.71946326091321E-10,2.21507979229864E-9,1.30087360520707E-9,3.00028843357406,100.057640075684,10,1000,1,3,0.000838394471523475,0.00012208643134081,0.0127427754923701,197.692260742187,299.992614746094,300.006378173828,25.3093090057373,25.3093090057373,,,8.74298667907715,,1,,,,,,1,1,1,299.998199462891,0,299.999638671875,,,,,,,,,,,,,,,,,,,,,,,,,,,,,,,,,